Workbook

Sheet LƯƠNG THÁNG 2
A12: BẢNG LƯƠNG THÁNG 2-A ĐIỆP
A13: TÊN | B13: MỨC LƯƠNG | C13: HỆ SỐ | D13: TỔNG | I13: BẢNG LƯƠNG THÁNG 2-A ƯỚC
A14: LƯƠNG CỨNG | B14: 7000000 | C14: 1 | D14: =B14*C14 -> 7000000 | I14: TÊN | J14: MỨC LƯƠNG | K14: HỆ SỐ | L14: TỔNG
A15: LƯƠNG THÂM NIÊN | B15: 2000000 | C15: 1 | D15: =B15*C15 -> 2000000 | I15: LƯƠNG CỨNG | J15: 7000000 | K15: 1 | L15: =J15*K15 -> 7000000
A16: TIỀN CÔNG ( THEO BẢNG KÊ) | B16: ='a Điệp T2.26'!E3 -> 2900000 | C16: 1 | D16: =B16*C16 -> 2900000 | I16: LƯƠNG THÂM NIÊN | J16: 2000000 | K16: 1 | L16: =J16*K16 -> 2000000
A17: HỖ TRỢ ĂN TRƯA | B17: 700000 | C17: 1 | D17: =B17*C17 -> 700000 | I17: TIỀN CÔNG ( THEO BẢNG KÊ) | J17: ='A Ước T2.26'!E3 -> 3600000 | K17: 1 | L17: =J17*K17 -> 3600000
D18: =B18*C18 -> 0 | I18: HỖ TRỢ ĂN TRƯA | J18: 700000 | K18: 1 | L18: =J18*K18 -> 700000
D19: =B19*C19 -> 0
D20: =B20*C20 -> 0
A21: TỔNG | D21: =SUM(D14:D20) -> 12600000
L22: =J22*K22 -> 0
I23: TỔNG | L23: =SUM(L15:L22) -> 13300000
A24: BẢNG ỨNG CHI THÁNG 2- A ĐIỆP
A25: Ứng chi | B25: 3000000
A26: Chi thực tế | B26: 3920000 | I26: BẢNG ỨNG CHI THÁNG 2- A ƯỚC
A27: Tổng HT back lại | B27: =B26-B25 -> 920000 | I27: Ứng chi | J27: 6000000
I28: Chi thực tế | J28: 2210000
I29: Tổng HT back lại | J29: =J28-J27 -> -3790000
A34: BẢNG LƯƠNG THÁNG 2-TRƯỜNG
A35: TÊN | B35: MỨC LƯƠNG | C35: HỆ SỐ | D35: TỔNG
A36: LƯƠNG CỨNG | B36: 4000000 | C36: 1 | D36: =B36*C36 -> 4000000
A37: TIỀN CÔNG ( THEO BẢNG KÊ) | B37: 140000 | C37: 1 | D37: =B37*C37 -> 140000
D39: =B39*C39 -> 0
A41: TỔNG | D41: =SUM(D36:D40) -> 4140000
A44: BẢNG ỨNG CHI THÁNG 2- TRƯỜNG
A45: Ứng chi | B45: 0
A46: Chi thực tế | B46: 325000
A47: Tổng HT back lại | B47: =B46-B45 -> 325000

Sheet A Điệp T1.26
A1: TIMEHOUSE SỬA CHỮA THÁNG 1.26
A2: NGÀY | B2: TÒA | C2: MÃ PHÒNG | D2: NỘI DUNG SỬA CHỮA | E2: TIỀN CÔNG | F2: MUA VẬT TƯ | G2: GHI CHÚ
E3: =SUBTOTAL(109,E4:E77) -> 4750000 | F3: =SUBTOTAL(109,F4:F77) -> 11315000
A4: 26/12 | B4: T21 | D4: Sơn chống thấm mặt ngoài trục 3+4. Làm đường ống thoát nước điều hoà 3+4 . Bịt keo lỗ ống dẫn điều hoà . Làm lại mái tôn sân thượng | E4: 1000000 | F4: 479000
A5: 27/12 | B5: G1 | D5: Lắp máy giặt sân thượng | F5: 356000
B6: T7 | C6: 101 | D6: Sửa cửa chính khó đóng mở | F6: 70000
A7: 28/12 | B7: T31 | C7: 304 | D7: Sơn chống thấm nvs | E7: 200000
B8: T31 | C8: 303 | D8: Sơn phòng | E8: 200000
B9: S2 | C9: Tầng 2 | D9: Đi dây làm ổ cắm điện cho máy giặt | F9: 107000 | G9: Dây điện + ổ + đế
A10: 29/12 | B10: T24 | D10: Thay át tổng 3p 501 + 502 +601 | F10: 60000
B11: T18 | C11: 303 | D11: Sơn chống thấm gác xép, tít keo bọt vào khe hở | E11: 50000 | F11: 50000
A12: 30/12 | B12: T26 | C12: 403 | D12: Thay 2 bóng âm trần | F12: 70000
A13: 31/12 | B13: T35 | C13: 302 | D13: Dọn phòng | E13: 100000
B14: T28 | C14: 302 | D14: Dọn phòng | E14: 100000
B15: T28 | C15: 302 | D15: Sơn phòng | E15: 200000
A16: 3/1 | B16: T36 | C16: 203 | D16: Dọn phòng | E16: 100000
B17: T2 | C17: 201 | D17: Dọn phòng | E17: 200000 | G17: Bẩn + nhiều đồ
A18: 4/1 | B18: S12 | C18: 101 | D18: Dọn phòng | E18: 100000
B19: S12 | C19: 101 | D19: Sơn phòng | E19: 100000
B20: S12 | C20: 504 | D20: Lắp kệ gương | F20: 80000
B21: T21 | C21: 101 | D21: Thay dây vòi xịt bệt | F21: 80000
B22: T13 | C22: 601 | D22: Dọn phòng | E22: 100000
B23: T13 | C23: 601 | D23: Sơn phòng | E23: 200000
B24: T13 | C24: 301 | D24: Dọn phòng | E24: 200000 | G24: Quá bẩn + Nhiều đồ
B25: T13 | C25: 301 | D25: Sơn phòng | E25: 100000
A26: 5/1 | B26: T11 | C26: 202 | D26: Thay 4 bóng đèn ốp trần | F26: 140000
B27: S41 | C27: 401 | D27: Dọn phòng | E27: 100000
B28: S12 | C28: 408 | D28: Xử lý trần thủng + cố định bồn cầu + Tít keo silicon cửa sổ | F28: =65000+10000+55000 -> 130000
B29: T33 | C29: 404 | D29: Lắp móc khoá cửa | F29: 15000
B30: T33 | C30: 404 | D30: Lắp giá cài vòi xịt | F30: 10000
A31: 6/1 | B31: T25 | C31: 302 | D31: Dọn phòng | E31: 100000
B32: T25 | C32: 302 | D32: Sơn phòng vá tỉa | E32: 50000
B33: T20 | C33: 301 | D33: Sơn phòng | E33: 200000
B34: T20 | D34: Dọn phòng | E34: 100000
B35: T20 | D35: Bắn tấm alu sau tủ | F35: 215000
B36: T20 | D36: Lắp thêm bóng trong 40W + thay công tắc | F36: =60000+10000 -> 70000
A37: 7/1 | B37: S45 | C37: 501 | D37: Thay vòi nước chậu rửa bát | F37: 60000 | G37: Khách đã chi 1 nửa
B38: S5 | C38: 501 | D38: Hỏng van 1 chiều BNL | F38: 50000
A39: 8/1 | B39: G1 | D39: Lắp bơm tăng áp sân thượng | F39: 1175000 | G39: Bơm + dây + giá + zen trong 26 + nơ + tê 40-225 + mang sông 25
A40: 9/1 | B40: S45 | C40: 403 | D40: Lắp ổ điện cắm tủ lạnh | F40: 35000
...

Sheet A Ước T1.26
A1: TIMEHOUSE SỬA CHỮA THÁNG 1.26
A2: NGÀY | B2: TÒA | C2: MÃ PHÒNG | D2: NỘI DUNG SỬA CHỮA | E2: TIỀN CÔNG | F2: MUA VẬT TƯ | G2: GHI CHÚ
B3: G1 | D3: lắp át nhà vệ sinh chung tầng 6 | F3: 60000
B4: S13 | C4: 501 | D4: Sơn phòng | E4: 150000 | G4: 501+401 = 1 thùng lấy T20
B5: S13 | C5: 501 | D5: Dọn vệ sinh phòng | E5: 150000
B6: S13 | C6: 401 | D6: Sơn phòng | E6: 150000
A7: 14/1 | B7: S13 | D7: Thay van cấp nước máy giặt | F7: 60000
B8: S13 | C8: 401 | D8: Thay vòi xịt | F8: 40000
B9: S15 | D9: Thay bơm | F9: 1300000
B10: S15 | C10: 101 | D10: Dọn vệ sinh phòng | E10: 100000
A11: 46023 | B11: S18 | C11: 304 | D11: Sơn phòng | E11: 150000
B12: S19A | C12: 502 | D12: dọn vệ sinh phòng | E12: 100000
A13: 29/12 | B13: S19C | C13: 202 | D13: Dọn vệ sinh phòng | E13: 200000 | G13: Bẩn
B14: S19C | C14: 202 | D14: Sơn phòng | E14: 100000 | G14: 202+302+402
B15: S19C | C15: 302 | D15: Dọn vệ sinh phòng | E15: 150000 | G15: 1 thùng sơn lấy ở T20
B16: S19C | C16: 302 | D16: Sơn phòng | E16: 100000
B17: S19C | C17: 301 | D17: Thay bóng típ | F17: 40000
B18: S19C | C18: 202 | D18: Thay bóng tròn | F18: 20000
B19: S19C | C19: 302 | D19: Thay 2 bóng tròn | F19: 40000
B20: S19C | C20: 402 | D20: sơn phòng | E20: 200000
B21: S19C | C21: 402 | D21: dọn phòng | E21: 100000
B22: S2 | C22: 304 | D22: Thay bình nóng lạnh | F22: 1200000
B23: S2 | D23: Sửa bơm | F23: 200000
B24: S25A | C24: 402 | D24: dọn vệ sinh phòng | E24: 100000
A25: 46082 | B25: S25B | C25: 102 | D25: dọn vệ sinh phòng + sửa điện+ thay vòi xịt | E25: 200000
A26: 46327 | B26: S26 | C26: 601 | D26: Sơn phòng | E26: 150000
B27: S29 | C27: 201 | D27: lát lại nền gạch | E27: 300000 | F27: 500000
B28: S3 | D28: Thay rơle bơm áp | F28: 115000
B29: S30 | C29: 203 | D29: Dọn vệ sinh phòng | E29: 100000
B30: S30 | D30: Dọn vệ sinh phòng | E30: 100000
A31: 30/12 | B31: S42 | C31: 301 | D31: Thay át nóng lạnh | F31: 60000
A32: 31/12 | B32: S45 | D32: Sửa bơm | F32: 400000
B33: S4B | D33: Tháo 3 tủ + 1 giường + 1 điều hoà | E33: 500000
B34: T15 | C34: 603 | D34: Bắn dây phơi | F34: 80000 | G34: Nở sắt + tăng móc + dây thép
B35: T15 | C35: 603 | D35: dọn phòng | E35: 200000
B36: T15 | C36: 502 | D36: dọn phòng | E36: 100000
B37: T17 | C37: 401 | D37: sơn và dọn phòng | E37: 300000
B38: T17 | C38: 401 | D38: thay vòi chậu, dây cấp, làm khung bắn lưới 4 phòng | E38: 100000 | F38: 85000
B39: T21 | C39: 503 | D39: Sơn phòng | E39: 200000 | G39: 1 Thùng sơn lấy ở T20
B40: T21 | C40: 503 | D40: Dọn vệ sinh phòng | E40: 200000 | G40: Bẩn
...

Sheet Trường
A1: Ngày | B1: Lỗi sửa chữa + mua đồ | C1: Toà nhà | D1: Phòng | E1: Chi phí vật liệu | F1: Chi phí công | G1: Bên chi | H1: Ghi chú chi tiết
A2: Tháng 1 | B2: Sơn, dọn phòng | C2: S20 | D2: 201 | F2: 300 | G2: Cty | H2: PHĐ
B3: Dọn phòng | C3: S28 | D3: 401 | F3: 100 | G3: Cty | H3: PHĐ
B4: Thay khoá phòng | C4: T26 | D4: 602 | G4: Khách
B5: Mất nước | C5: S47 | G5: Cty
B6: Dọn phòng | C6: S21 | D6: 501 | F6: 100 | G6: Cty | H6: PHĐ
B7: Dọn phòng | C7: S47 | D7: 301 | F7: 200 | G7: Cty | H7: PHĐ, bẩn
B8: Thay dây, vòi xịt | C8: S47 | D8: 402 | E8: 60 | G8: Cty
B9: Lắp tăng atp tầng 7 | C9: S21 | E9: 250 | G9: Cty
B10: Dây, vòi sen | C10: S25B | D10: 102 | E10: 80 | G10: Cty | H10: Khách mới
B11: Thay dây, đầu xịt | C11: S20 | D11: 201 | E11: 80 | G11: Cty | H11: PHĐ
B12: Thay atp ngoài cột | C12: S36
B13: Sửa cửa kéo phòng, thay máng bóng tuýp | C13: S28 | D13: 401 | E13: 50 | G13: Cty | H13: Khách mới
B14: Mua vòi gạt, van hỗ trợ lắp máy giặt, thay dây thoát chậu rửa | C14: T45 | D14: 101 | E14: 150 | G14: Cty | H14: Khách mới
B15: Xử lý vỡ ống nước | C15: S47 | E15: 25 | G15: Cty
B16: Thay 4 bóng âm trần nhà xe | C16: T26 | E16: 132 | G16: Cty
B17: Thay 3 bóng thang máy, 2 bóng tuýp p302, p401 | C17: T13 | E17: 170 | G17: Cty
B18: Thay dây sen | C18: T26 | D18: 403 | E18: 30 | G18: Cty
B19: Thay công tắc nóng, lạnh; sửa cụm ổ điện bị cháy xén theo | C19: S28 | D19: 401 | E19: 140 | G19: Cty | M19: Try
B20: Ngăn mùi thoát sàn | C20: S28 | D20: 102 | E20: 35 | G20: Cty
B21: Thay vòi rửa mặt, dây cấp | C21: T45 | D21: 101 | E21: 230 | G21: Cty | H21: Khách mới
B22: Tổng | E22: =SUM(E2:E21) -> 1432 | F22: =SUM(F2:F21) -> 700

Sheet a Điệp T2.26
A1: TIMEHOUSE SỬA CHỮA THÁNG 2.26
A2: NGÀY | B2: TÒA | C2: MÃ PHÒNG | D2: NỘI DUNG SỬA CHỮA | E2: TIỀN CÔNG | F2: MUA VẬT TƯ | G2: GHI CHÚ
E3: =SUBTOTAL(109,E4:E47) -> 2900000 | F3: =SUBTOTAL(109,F4:F47) -> 3920000
A4: 46048 | B4: T25 | C4: 304 | D4: thay bóng tuýp | F4: 50000
A5: 46050 | B5: S45 | D5: Nâng chõ bơm bể ngầm | F5: 80000
A6: 29/2 | B6: S48B | C6: 101 | D6: Chống thấm nvs xuống phòng | E6: 500000 | F6: 350000 | G6: sơn chống thấm
C7: 201 | D7: xử lý nứt vỡ ống nhiệt | F7: 165000 | G7: ống, cút,tê,xi măng
A8: 46052 | B8: T28 | C8: 201 | D8: Sửa cửa nvs | F8: 85000 | G8: vít, keo silicon,đinh
B9: S49 | C9: 301 | D9: Dọn phòng | E9: 100000
B10: S33 | C10: 101 | D10: Sửa cửa nhôm kính thay 2 bánh xe ray cửa | F10: 175000
A11: 45688 | B11: S45 | C11: 503 | D11: Cửa chính ra vào bị xệ | F11: 15000
B12: S48A | C12: 201 | D12: Thay cần gạt củ sen | F12: 50000
B13: S33 | C13: 404 | D13: Sơn phòng | E13: 200000
D14: Dọn phòng | E14: 100000
B15: S33 | D15: Xử lý đọng nước sân thượng | F15: 135000
B16: T25 | D16: xử lý ổ điện cắm bơm k có điện | F16: 110000
B17: S45 | C17: 401 | D17: Dọn phòng | E17: 100000
A18: 46061 | B18: S40 | C18: 301 | D18: Lắp ngăn thoát sàn, sửa rò bệt | F18: 95000
A19: 46062 | B19: T7 | D19: Lắp cam ở cổng | E19: 100000 | F19: 25000
A20: 46063 | B20: S5 | C20: 303 | D20: Sơn phòng | E20: 200000
D21: dọn phòng | E21: 100000
B22: T42 | C22: 303 | D22: dọn phòng | E22: 150000 | G22: bẩn nhiều đồ
A23: 46076 | B23: T24 | D23: sửa chập điện âm tường, thay át và hạt công tắc | F23: 385000
B24: T22 | D24: thay dây điện từ téc xuống, thay phao điện | F24: 460000 | G24: dây điện , phao điện
A25: 46077 | B25: T20 | C25: 201+202 | D25: dọn vệ sinh | E25: 100000 | G25: rất bẩn
D26: lắp chốt khoá ngoài | F26: 30000
A27: 46078 | B27: S1 | D27: Sửa mất nước | F27: 95000
B28: S43 | C28: 401 | D28: Sơn phòng | E28: 100000 | G28: khách đã chi 1 nửa
A29: 46054 | B29: T41 | D29: Dọn nvs gầm cầu thang | E29: 50000 | F29: 50000
D30: Thay bóng tuýp | F30: 80000
A31: 46055 | B31: S45 | C31: 601 | D31: dọn phòng | E31: 100000
B32: T2 | C32: 501 | D32: Sửa chập điện nhảy át | F32: 65000
B33: T21 | C33: 503 | D33: Lắp tủ quần áo | E33: 100000 | F33: 38000
A34: 46056 | B34: T28 | C34: 202 | D34: Dọn phòng | E34: 100000
A35: 46057 | B35: S5 | C35: 502 | D35: Sơn phòng | E35: 200000 | G35: thùng sơn lấy ở T18
B36: S5 | C36: 303 | D36: Thay vòi củ chậu rửa mặt | F36: 180000
B37: T7 | C37: 201 | D37: Thay dây bát sen, sơn sàn gỗ nền nhà | F37: =80000+112000 -> 192000
A38: 46058 | B38: T11 | D38: Sửa bơm thay bi, tháy cánh quạt | F38: 350000
D39: thay chõ bơm lắp sắc co bể ngầm | F39: 160000
A40: 6 | B40: S45 | D40: Sửa mất nước | F40: 230000
...

Sheet A Ước T2.26
A1: TIMEHOUSE SỬA CHỮA THÁNG 2.26
A2: NGÀY | B2: TÒA | C2: MÃ PHÒNG | D2: NỘI DUNG SỬA CHỮA | E2: TIỀN CÔNG | F2: MUA VẬT TƯ | G2: GHI CHÚ
E3: =SUBTOTAL(109,E4:E32) -> 3600000 | F3: =SUBTOTAL(109,F4:F32) -> 2210000
A4: 46055 | B4: S39 | C4: 601 | D4: Dọn phòng | E4: 100000
A5: 46056 | B5: T38 | C5: 101 | D5: Dọn phòng + sơn phòng | E5: 200000
A6: 46057 | B6: S35 | C6: 201 | D6: Dọn vs phòng | E6: 100000
A7: 46057 | B7: S15 | C7: 402 | D7: Dọn và sơn phòng | E7: 200000
A8: 46057 | B8: S19B | C8: 203 | D8: Dọn phòng | E8: 100000
A9: 46057 | B9: S19A | C9: 402 | D9: Dọn phòng | E9: 100000
A10: 46058 | B10: T15 | C10: 202 | D10: Dọn phòng | E10: 100000
A11: 46058 | B11: S50 | C11: 302 | D11: Dọn phòng | E11: 100000
A12: 46059 | B12: T37 | C12: 702 | D12: Dọn phòng | E12: 200000 | G12: bẩn
A13: 46059 | B13: T37 | C13: 702 | D13: Sơn phòng | E13: 200000 | G13: 1 thùng sơn lấy T42
A14: 46060 | B14: S42 | C14: 302 | D14: Dọn phòng | E14: 100000
A15: 46060 | B15: S42 | C15: 402 | D15: Dọn phòng | E15: 150000
A16: 46060 | B16: S44 | C16: 303 | D16: Dọn phòng | E16: 100000
A17: 46061 | B17: S50 | C17: 502 | D17: Dọn phòng | E17: 150000 | G17: bẩn
B18: S50 | C18: 203 | D18: Dọn phòng | E18: 150000
B19: S9B | C19: 402 | D19: Thay bình nóng lạnh | F19: 1350000
B20: S9B | D20: dây cấp | F20: 50000
A21: 46062 | B21: S50 | D21: Lắp cam | E21: 100000
B22: S50 | D22: dây điện phích cắm điện | F22: 110000
B23: T17 | C23: 202 | D23: sơn chống thấm , bột bả | E23: 150000 | F23: 700000
A24: 46063 | B24: S10 | C24: 402 | D24: Dọn phòng | E24: 400000 | G24: bẩn nhiều
B25: S10 | C25: 402 | D25: sơn phòng | E25: 300000 | G25: 1 thùng sơn lấy ở S3
B26: S7 | C26: 103 | D26: dọn phòng | E26: 100000
B27: S7 | C27: 103 | D27: sơn phòng | E27: 150000 | G27: thùng sơn lấy ở T42
B28: T42 | C28: 303 | D28: Dọn phòng | E28: 150000
B29: S8 | C29: 105 | D29: Dọn và sơn phòng | E29: 200000 | G29: 1/2 thùng sơn/ khách chi

Sheet trường.2.26
A1: Ngày | B1: Lỗi sửa chữa + mua đồ | C1: Toà nhà | D1: Phòng | E1: Chi phí vật liệu | F1: Chi phí công | G1: Bên chi | H1: Ghi chú chi tiết
A2: Tháng 2 | B2: Thay khoá phòng | C2: S28 | D2: 101 | G2: Khách
B3: Thay hạt công tắc | C3: T44 | D3: 201 | G3: Khách
B4: Dọn phòng | C4: S27 | D4: 601 | F4: 100 | G4: Cty | H4: phđ
B5: Vệ sinh máy giặt | C5: S20,S36 | G5: Cty
B6: Rò nước máy bơm | C6: G1 | E6: 10 | G6: Cty
B7: Thay bóng âm trần | C7: T26 | D7: 203 | F7: 40 | G7: Cty | H7: phđ
B8: Thay vòi xịt | C8: S25B | D8: 101 | G8: Khách
B9: Thay cục chống giật bnl | C9: S33 | D9: 101 | G9: Khách
B10: Thay công tắc bnl | C10: T44 | D10: 201 | G10: Khách
B11: Sửa ổ điện máy giặt | C11: T45 | G11: Cty
B12: Thay dây cấp | C12: S28 | D12: MB | G12: Khách
B13: Lắp Giường | C13: S36 | D13: 602 | G13: Cty
B14: Lắp chốt cửa trong, nối thêm ổ điện, thay ổ, xly cửa nvs lệch bản lề, thay dây thoát chậu, thay vòi xịt, thoát sàn | C14: S28 | D14: 401 | E14: 315 | G14: Cty | H14: Khách mới
G15: Cty
G16: Cty
G17: Cty
G18: Cty
G19: Cty
G20: Cty
G21: Cty
B22: Tổng | E22: =SUM(E2:E21) -> 325 | F22: =SUM(F2:F21) -> 140

Sheet trường tháng 3
A1: Ngày | B1: Lỗi sửa chữa + mua đồ | C1: Toà nhà | D1: Phòng | E1: Chi phí vật liệu | F1: Chi phí công | G1: Bên chi | H1: Ghi chú chi tiết
A2: Tháng 3 | B2: Thay van điện máy giặt | C2: S27 | E2: 95 | G2: cty
B3: kẻ vạch nhà xe | C3: G4 | E3: 375 | F3: 300 | G3: cty
B4: Thông tắc nvs, bệt | C4: G1 | D4: 404 | E4: 40 | G4: cty
B5: Căng dây phơi | C5: G6 | E5: 170 | G5: Cty
B6: Thay bộ dây bát sen | C6: G5 | D6: 401 | E6: 80 | G6: Cty
B7: Thay đồng hồ điện | C7: S28 | D7: 302 | E7: 145 | G7: Cty
B8: Dọn vsinh, thay vòi đồng, vòi chậu rửa | C8: s25A | D8: 601 | E8: 180 | F8: 100 | G8: Cty
B9: Thay đồng hồ nước | C9: G2 | D9: 401 | E9: 440 | G9: cty
B10: Thay phao điện | C10: G1 | E10: 145 | G10: cty
B11: Sơn, dọn phòng, thay bát sen | C11: S36 | D11: 501 | E11: 30 | F11: 300 | G11: cty | H11: trừ cọc
B12: Dọn phòng | C12: G3 | D12: 301 | F12: 100 | G12: Cty
B13: Dọn, sơn phòng | C13: S25B | D13: 202 | E13: 40 | F13: 200 | G13: cty
B14: Dọn phòng | C14: S21 | D14: 401701 | F14: 250 | G14: Cty
B15: Thay ổ điện sân phơi | C15: T26 | E15: 45 | G15: Cty
B16: Dọn phòng | C16: G3 | D16: 601 | F16: 100 | G16: Cty
B17: Lắp 3c cam nhà xe | C17: G5 | E17: 30 | F17: 300 | G17: Cty
B18: Căng dây phơi | C18: G5 | E18: 55 | G18: Cty
B19: Sơn phòng | C19: S25A | D19: 601 | F19: 100 | G19: Cty
B20: Sơn phòng | C20: S25B | D20: 101 | F20: 100 | G20: Cty
B21: Thay bóng tuýp | C21: S20 | D21: 201 | E21: 40 | G21: cty
B22: Vật tư xly vỡ ống nước trên téc | C22: S20 | E22: 50 | G22: cty
B23: Lắp 1c cam ban công | C23: G5 | E23: 30 | F23: 100 | G23: cty
B24: Đồ đi đường điện nước, vật tư lắp giặt sấy | C24: G5 | E24: 789 | G24: Cty
B25: Thay bóng hành lang | C25: S25A | E25: 90 | G25: cty
B26: Đi ống thoát chậu rửa | C26: G1 | D26: 601 | E26: 30 | G26: cty
B27: Thay bóng tuýp p201, 1 lọ thông tắc + 2 ngăn mùi thoát sànp404,601 | C27: G1 | D27: 201404601 | E27: 200 | G27: cty
B28: Dọn + sơn p302,601 | C28: T26 | D28: 302601 | F28: 400 | G28: cty
B29: Sơn phòng | C29: T26 | D29: 202301402 | F29: 200 | G29: cty
B30: Thay dây cấp | C30: S13 | D30: 504 | E30: 30 | G30: cty
B31: Dọn phòng | C31: T44 | D31: 101 | F31: 100 | G31: cty
B32: Lắp 5c cam hành lang | C32: G5 | E32: 275 | F32: 500 | G32: cty
B33: Đồ lắp máy giặt | C33: G4 | E33: 165 | G33: cty
B34: Lắp 5c cam ( 2c nxe, 3c hành lang tầng) | C34: G4 | E34: 330 | F34: 500 | G34: cty
B35: Dây sen | C35: S28 | D35: 401 | E35: 70 | G35: cty | H35: khách mới
B36: Thay bóng hành lang | C36: S20 | E36: 65 | G36: Cty
B37: Tổng | E37: =SUM(E2:E36) -> 4034 | F37: =SUM(F2:F36) -> 3650

Sheet A Điệp T3.26
A1: TIMEHOUSE SỬA CHỮA THÁNG 3.26
A2: NGÀY | B2: TÒA | C2: MÃ PHÒNG | D2: NỘI DUNG SỬA CHỮA | E2: TIỀN CÔNG | F2: MUA VẬT TƯ | G2: GHI CHÚ
E3: =SUBTOTAL(109,E4:E127) -> 8535000 | F3: =SUBTOTAL(109,F4:F127) -> 6966000
A4: 46079 | B4: S33 | C4: 104 | D4: Thay bóng đèn âm trần WC | F4: 35000
B5: S33 | D5: Thay bóng sân phơi | F5: 25000
B6: T13 | C6: 202 | D6: Xử lý ngấm sàn WC ngấm xuống trần tầng 1 | E6: 200000 | F6: 195000 | G6: Ống cút + keo + xi măng + dây vòi xịt..
A7: 46080 | B7: T21 | C7: 402 | D7: Dọn vs phòng | E7: 100000
B8: T25 | C8: 408 | D8: Sơn phòng | E8: 200000 | G8: 1 thùng sơn còn thừa sơn hành lang + cầu thang
B9: T25 | C9: 208 | D9: Sơn phòng | E9: 200000
B10: T25 | C10: 208 | D10: Dọn vs phòng | E10: 100000
A11: 46081 | B11: T25 | C11: 309 | D11: Sơn phòng | E11: 300000 | G11: Phòng đôi to, 1 thùng sơn lấy ở T18
B12: T25 | C12: 104 | D12: Sơn phòng | E12: 100000
B13: S40 | C13: 303 | D13: Dọn vs phòng | E13: 250000 | G13: trừ vào hoàn cọc
B14: S40 | C14: 506 | D14: Dọn vs phòng | E14: 100000
A15: 46082 | B15: S40 | C15: 103 | D15: Dọn vs phòng | E15: 100000
B16: S45 | C16: 303 | D16: Dọn vs phòng | E16: 200000 | G16: Khách chi
B17: S45 | C17: 303 | D17: Thông tắc thoát chậu rửa bát | E17: 150000
B18: T21 | D18: Xử lý tắc cống | E18: 150000
A19: 46083 | B19: T41 | C19: 401 | D19: Sơn phòng | E19: 200000 | G19: 1/2 thùng ở T42
B20: T41 | C20: 401 | D20: Dọn vs phòng | E20: 400000 | G20: Quá bẩn - Khách hết hđ
B21: T41 | C21: 401 | D21: Thay dây bát sen | E21: 150000
B22: T41 | C22: 401 | D22: Thông tắc chậu rửa bát | E22: 150000
B23: T41 | C23: 401 | D23: Thay bóng típ chỗ bếp | E23: 35000
B24: T18 | C24: 302 | D24: Sơn phòng | E24: 200000 | G24: 1/2 ở T42
B25: T21 | C25: 402 | D25: Lắp tủ quần áo | E25: 100000 | F25: 215000 | G25: Alu + vít + ke góc
B26: T20 | C26: 301 | D26: Lắp át điều hòa | F26: 50000
B27: T20 | C27: 301 | D27: Thay điều khiển điều hòa | F27: 100000
A28: 46084 | B28: T7 | C28: 401 | D28: Dọn vs phòng | E28: 300000 | G28: Quá bẩn - Nhiều đồ khách hết hđ
B29: S45 | C29: 401 | D29: Lắp ngăn mùi thoát sàn | F29: 35000
B30: S45 | C30: 503 | D30: Dọn vs phòng | E30: 200000 | G30: Quá bẩn - Nhiều đồ đạc
B31: T35 | C31: 304 | D31: Chống thấm ngấm nước từ nvs 404 | E31: 150000 | F31: 85000 | G31: Vòi + xi măng+…
B32: S22 | D32: Lắp máy giặt sân thượng | F32: 65000 | G32: Keo + cút + tế+ dây điện..
B33: S41 | D33: Tháo bộ cửa vân tay | F33: 170000
A34: 46085 | B34: T3 | C34: 401 | D34: Dọn vs phòng | E34: 150000
B35: T3 | C35: 401 | D35: Sơn phòng | E35: 200000
B36: T41 | C36: 301 | D36: Xử lý rò nước bồn rửa | F36: 55000
B37: T3 | C37: 401 | D37: Thay dây sen | F37: 40000
B38: T3 | C38: 401 | D38: Thay vòi xịt | F38: 40000
A39: 46086 | B39: S37A | C39: 501 | D39: Thông tắc cống nvs thông tắc bồn cầu | F39: 50000
B40: S37A | C40: 501 | D40: Bắn keo silicon bồn rửa | F40: 55000
...

Sheet A Ước T3.26
A1: TIMEHOUSE SỬA CHỮA THÁNG 3.26
A2: NGÀY | B2: TÒA | C2: MÃ PHÒNG | D2: NỘI DUNG SỬA CHỮA | E2: TIỀN CÔNG | F2: MUA VẬT TƯ | G2: GHI CHÚ
E3: =SUBTOTAL(109,E4:E88) -> 7550000 | F3: =SUBTOTAL(109,F4:F88) -> 6200000
A4: 46082 | B4: T42 | C4: 205 | D4: Sơn phòng | E4: 150000
B5: T42 | C5: 205 | D5: Dọn vs phòng | E5: 200000 | G5: Sơn lấy 1/2 T42
B6: T42 | C6: 205 | D6: Sửa cửa nvs | F6: 20000
B7: T42 | C7: 205 | D7: Chốt cửa | F7: 10000
B8: T42 | C8: 205 | D8: Bát sen | F8: 40000
B9: T42 | C9: 205 | D9: Vòi chậu | F9: 120000
B10: T42 | C10: 205 | D10: Dây cấp | E10: 200000 | F10: 40000
B11: T42 | C11: 205 | D11: Xi pông chậu rửa mặt | F11: 30000
B12: T42 | C12: 205 | D12: Đui chích | F12: 10000
B13: S29 | C13: 402 | D13: Dọn vs phòng | E13: 100000
B14: S15 | C14: 302 | D14: Dọn vs phòng | E14: 300000
A15: 46084 | B15: S2 | C15: 206 | D15: Dọn vs phòng | E15: 150000
B16: S2 | C16: 206 | D16: Thay ổ điện | F16: 40000
B17: S2 | C17: 206 | D17: Thay dây sen | F17: 40000
A18: 46085 | B18: T42 | C18: 102 | D18: Sơn phòng | E18: 150000
B19: T42 | C19: 102 | D19: Dọn vs phòng | E19: 200000 | G19: Khách
B20: S35 | C20: 402 | D20: Dọn vs phòng | E20: 200000 | G20: Bẩn
B21: T42 | C21: 203 | D21: Dọn vs phòng | E21: 100000 | G21: Khách
B22: T42 | C22: 203 | D22: Thay xi pông chậu | F22: 30000
A23: 46086 | B23: S30 | C23: 201 | D23: Dọn vs phòng | E23: 150000
A24: 46087 | B24: S30 | D24: Lắp cam hành lang 4 cái | E24: 400000
B25: t38 | C25: 101 | D25: Thay sen tường | F25: 250000
A26: 46089 | B26: S39 | C26: 405 | D26: Dọn vs phòng | E26: 200000 | G26: Bẩn
A27: 46087 | B27: S30 | D27: Lắp cam dây điện + phích cắm | F27: 90000
A28: 46089 | B28: S44 | C28: 303 | D28: Sơn phòng | E28: 150000 | G28: Sơn lấy 1/2 S3
A29: 46090 | B29: T42 | C29: 205 | D29: Lắp chốt thang | F29: 20000
A30: 46091 | B30: S35 | C30: 402 | D30: Chũi keo sơn lại | E30: 100000
B31: S4a | C31: 103 | D31: Sơn phòng | E31: 150000 | G31: Sơn lấy 1/2 S3
B32: S4A | D32: Dọn vs phòng | E32: 150000
A33: 46092 | B33: T22 | D33: Thay phao téc | F33: 80000
B34: T26 | D34: Trường lấy sơn T42
A35: 46094 | B35: S18 | C35: 203 | D35: Sơn phòng | E35: 150000
B36: S18 | C36: 203 | D36: Dọn vs phòng | E36: 150000
B37: S13 | C37: 102 | D37: Thay tấm alu | F37: 220000
B38: S13 | D38: Vít | F38: 20000
B39: T42 | D39: Thay van cấp máy giặt | F39: 30000
B40: S13 | D40: Thay van cấp máy giặt | F40: 30000
...

Sheet LƯƠNG THÁNG 3 
A12: BẢNG LƯƠNG THÁNG 3-A ĐIỆP
A13: TÊN | B13: MỨC LƯƠNG | C13: HỆ SỐ | D13: TỔNG | I13: BẢNG LƯƠNG THÁNG 3-A ƯỚC
A14: LƯƠNG CỨNG | B14: 7000000 | C14: 1 | D14: =B14*C14 -> 7000000 | I14: TÊN | J14: MỨC LƯƠNG | K14: HỆ SỐ | L14: TỔNG
A15: LƯƠNG THÂM NIÊN | B15: 2000000 | C15: 1 | D15: =B15*C15 -> 2000000 | I15: LƯƠNG CỨNG | J15: 7000000 | K15: 1 | L15: =J15*K15 -> 7000000
A16: TIỀN CÔNG ( THEO BẢNG KÊ) | B16: ='A Điệp T3.26'!E3 -> 8535000 | C16: 1 | D16: =B16*C16 -> 8535000 | I16: LƯƠNG THÂM NIÊN | J16: 2000000 | K16: 1 | L16: =J16*K16 -> 2000000
A17: HỖ TRỢ ĂN TRƯA | B17: 700000 | C17: 1 | D17: =B17*C17 -> 700000 | I17: TIỀN CÔNG ( THEO BẢNG KÊ) | J17: ='A Ước T3.26'!E3 -> 7550000 | K17: 1 | L17: =J17*K17 -> 7550000
D18: =B18*C18 -> 0 | I18: HỖ TRỢ ĂN TRƯA | J18: 700000 | K18: 1 | L18: =J18*K18 -> 700000
D19: =B19*C19 -> 0
D20: =B20*C20 -> 0
A21: TỔNG | D21: =SUM(D14:D20) -> 18235000
L22: =J22*K22 -> 0
I23: TỔNG | L23: =SUM(L15:L22) -> 17250000
A24: BẢNG ỨNG CHI THÁNG 3- A ĐIỆP
A25: Ứng chi | B25: 9000000
A26: Chi thực tế | B26: 6966000 | I26: BẢNG ỨNG CHI THÁNG 3- A ƯỚC
A27: Tổng HT back lại | B27: =B26-B25 -> -2034000 | I27: Ứng chi | J27: 6000000
I28: Chi thực tế | J28: 6200000
I29: Tổng HT back lại | J29: =J28-J27 -> 200000
A34: BẢNG LƯƠNG THÁNG 3-TRƯỜNG
A35: TÊN | B35: MỨC LƯƠNG | C35: HỆ SỐ | D35: TỔNG
A36: LƯƠNG CỨNG | B36: 4000000 | C36: 1 | D36: =B36*C36 -> 4000000
A37: TIỀN CÔNG ( THEO BẢNG KÊ) | B37: 3650000 | C37: 1 | D37: =B37*C37 -> 3650000
D39: =B39*C39 -> 0
A41: TỔNG | D41: =SUM(D36:D40) -> 7650000
A44: BẢNG ỨNG CHI THÁNG 3- TRƯỜNG
A45: Ứng chi | B45: 0
A46: Chi thực tế | B46: 4034000
A47: Tổng HT back lại | B47: =B46-B45 -> 4034000

Sheet Trường T4.26
A1: Ngày | B1: Lỗi sửa chữa + mua đồ | C1: Toà nhà | D1: Phòng | E1: Chi phí vật liệu | F1: Chi phí công | G1: Bên chi | H1: Ghi chú chi tiết
A2: Tháng 4 | G2: cty
A3: 46117 | B3: Thay cấp bệt | C3: S21 | D3: 801 | E3: 71 | G3: cty
A4: 46118 | B4: Dọn phòng | C4: G1 | D4: 302 | F4: 100 | G4: cty
B5: Sơn phòng | C5: S20 | D5: 101 | F5: 150 | G5: Cty
A6: 46119 | B6: Thay đèn hành lang | C6: T44- 45 | E6: 88 | G6: Cty
B7: Dọn phòng | C7: S27 | D7: 302 | F7: 150 | G7: Cty
B8: mua lăn chũi | C8: s20-T26 | E8: 35 | G8: Cty
A9: 46121 | B9: Vòi rửa bát, bát sen | C9: S25A | D9: 402 | E9: 170 | G9: cty
B10: Mua kìm mỏ quạ | E10: 80 | G10: cty
B11: Xi măng trắng bịt hở sàn | C11: G5 | E11: 10 | G11: cty
A12: 46123 | B12: Bộ sen, 2 dây cấp, giá đỡ bình nl | C12: G7 | D12: 101 | E12: 430 | G12: Cty
B13: Băng dính dán tiêu lệnh, bảng biển | C13: S36 | E13: 50 | G13: cty
B14: Vật tư đi lại đường điện nước máy giặt | C14: G1 | E14: 680 | G14: Cty
B15: Daay cấp máy giặt hỗ trợ chủ nhà | C15: G1 | E15: 80 | G15: Cty
A16: 46124 | B16: Lắp 4c cam G6 | C16: G6 | E16: 132 | F16: 400 | G16: Cty
B17: Thay lõi khóa phòng | C17: G5 | D17: 501 | E17: 110 | G17: Cty
B18: Dọn phòng | C18: G6 | D18: 402 | F18: 100 | G18: Cty
A19: 46127 | B19: Thay vòi rửa | C19: S25A | D19: 202 | E19: 120 | G19: Cty
B20: Thay vòi gạt | C20: S25A | D20: 402 | E20: 75 | G20: Cty
B21: Đi thêm đường điện, thêm ổ | C21: G7 | D21: 101 | E21: 81 | G21: cty
B22: Dọn phòng | C22: G7 | D22: 101 | F22: 100 | G22: cty
A23: 46129 | B23: Thay ổ điện | C23: G5 | D23: 404 | E23: 40 | G23: cty
A24: 46132 | B24: Sơn phòng | C24: S28 | D24: 301 | F24: 200 | G24: Cty
B25: Kẻ vạch nhà xe G5 | C25: G5 | E25: 283 | F25: 300 | G25: cty
A26: 46134 | B26: Thuê đổ trạc | C26: S28 | E26: 100 | G26: cty
B27: Thuê đổ trạc | C27: T45 | E27: 100 | G27: cty
A28: 46136 | B28: Thay bát sen | C28: T26 | D28: 501 | F28: 50 | G28: cty
B29: Dọn, sơn phòng | C29: T26 | D29: 501 | F29: 250 | G29: cty
B30: Đánh thêm khóa cổng | C30: S20 | E30: 30
B31: Sơn vá, dọn | C31: T26 | D31: 301 | F31: 200 | G31: cty
A32: 46139 | B32: Thay xịt bệt, vòi gạt | C32: S20 | D32: 101 | E32: 130 | G32: cty
B33: Kẻ vạch nhà xe G1 | C33: G1 | E33: 315 | F33: 100 | G33: cty
A34: 46140 | B34: Mua khoan pin | E34: 650 | G34: cty
B35: Lắp then cửa nvs | C35: S20 | D35: 201 | E35: 20 | G35: cty
A36: 46141 | B36: Lắp 6c cam G6 | C36: G6 | E36: 90 | F36: 600 | G36: cty
A37: 46145 | B37: Xịt bệt | C37: S25A | D37: 102 | E37: 80 | G37: cty
B38: Mua đồ lắp đồ trên VP mới | E38: 40 | G38: cty
A39: 46146 | B39: Thay kệ dưới gương | C39: S28 | D39: 401 | E39: 80 | G39: cty | H39: Khách đã báo từ lúc mới vào
B40: Thay vòi gạt,bát sen | C40: T27 | E40: 160 | G40: cty
...

Sheet A Điệp T4.26
A1: TIMEHOUSE SỬA CHỮA A ĐIỆP THÁNG 4.26
A2: NGÀY | B2: TÒA | C2: MÃ PHÒNG | D2: NỘI DUNG SỬA CHỮA | E2: TIỀN CÔNG | F2: MUA VẬT TƯ | G2: GHI CHÚ | H2: QUẢN LÝ | I2: LOẠI PHÒNG
E3: =SUBTOTAL(109,E4:E118) -> 10490000 | F3: =SUBTOTAL(109,F4:F158) -> 7456000 | H3: 1 | I3: 1
A4: 46107 | B4: T21 | C4: 202 | D4: Thay khóa đấm | F4: 65000 | H4: Đỗ Thùy Linh
B5: T21 | D5: Thay pin điều khiển đh | F5: 10000 | H5: Đỗ Thùy Linh
B6: T13 | C6: 601 | D6: Thay dây vòi xịt | F6: 80000 | H6: Đỗ Thùy Linh
B7: T18 | D7: Rửa cọ téc sân thượng | E7: 500000 | H7: Nguyễn Ngọc Văn Khải
B8: S40 | C8: 605 | D8: Dọn phòng | E8: 300000 | G8: Khách hết hd | H8: Đặng Trung Kiên
B9: T18 | D9: Thay rửa bể ngầm + lao vét + vận chuyển bùn đất cát | E9: 1000000 | H9: Nguyễn Ngọc Văn Khải
B10: T18 | D10: Đấu nối hút nước trực tiếp lên téc để rửa bể ngầm | F10: 175000 | H10: Nguyễn Ngọc Văn Khải
A11: 46108 | B11: S23 | D11: Thay rơ le bơm áp | F11: 80000 | H11: Nguyễn Công Lâm
A12: 46111 | B12: S12 | C12: 101 | D12: Dọn phòng | E12: 100000 | H12: Đỗ Thanh Hương
A13: 46112 | B13: S33 | C13: 401 | D13: Thay củ sen cắm tường | F13: 250000 | H13: Đặng Trung Kiên
B14: S33 | C14: 401 | D14: Thay dây bát sen | F14: 80000 | H14: Đặng Trung Kiên
B15: S33 | C15: 401 | D15: Xử lý gẫy ống nước | F15: 20000 | H15: Đặng Trung Kiên
A16: 46114 | B16: T7 | C16: 201 | D16: Dọn phòng | E16: 100000 | H16: Đặng Trung Kiên
B17: T7 | C17: 301 | D17: Dọn phòng | E17: 100000 | H17: Đặng Trung Kiên
B18: T7 | C18: 301 | D18: Sơn phòng | E18: 100000 | H18: Đặng Trung Kiên
B19: T7 | C19: 301 | D19: Thay dây bát sen | F19: 80000 | H19: Đặng Trung Kiên
B20: T7 | C20: 302 | D20: Dọn phòng | E20: 250000 | H20: Đặng Trung Kiên
B21: T7 | C21: 302 | D21: Sơn phòng | E21: 200000 | H21: Đặng Trung Kiên
B22: T7 | C22: 302 | D22: Thay giá cài vòi xịt | F22: 10000 | H22: Đặng Trung Kiên
A23: 46115 | B23: T35 | C23: 101 | D23: Thay bát sen | F23: 40000 | H23: Nguyễn Công Lâm
B24: T35 | C24: 101 | D24: Thay 3 bóng típ + 1 bóng tròn | F24: 220000 | H24: Nguyễn Công Lâm
B25: T35 | C25: 101 | D25: Sơn phòng | E25: 300000 | H25: Nguyễn Công Lâm
B26: T35 | C26: 101 | D26: Tổng vệ sinh phòng | E26: 300000 | H26: Nguyễn Công Lâm
B27: S48A | C27: 301 | D27: Thay át phòng | F27: 55000 | H27: Đỗ Thanh Hương
B28: T2 | C28: 201 | D28: Sửa BNL ko nóng | F28: 50000 | H28: Vũ Đắc Hào
B29: T21 | C29: 202 | D29: Thay dây bát sen | F29: 80000 | H29: Đỗ Thùy Linh
B30: T21 | C30: 202 | D30: Thông tắc ống thoát nước bàn bếp | F30: 50000 | H30: Đỗ Thùy Linh
A31: 46116 | B31: T25 | C31: 209 | D31: Sơn phòng | E31: 300000 | G31: Phòng đôi | H31: Nguyễn Công Lâm
B32: T33 | C32: 502 | D32: Sửa chập điện | F32: 255000 | H32: Nguyễn Công Lâm
B33: S33 | C33: 203 | D33: Đi lại đường điện | F33: 65000 | H33: Đặng Trung Kiên
B34: S33 | C34: 203 | D34: Dọn phòng | E34: 100000 | G34: Khách hết hd | H34: Đặng Trung Kiên
B35: S33 | C35: 203 | D35: Sơn phòng + Dán phòng | E35: 200000 | H35: Đặng Trung Kiên
A36: 46117 | B36: T11 | C36: 402 | D36: Dọn phòng | E36: 100000 | H36: Đỗ Thanh Hương | I36: kh phá hd thu được điện nước
B37: T11 | C37: 402 | D37: Sửa cánh tủ bếp | F37: 35000 | H37: Đỗ Thanh Hương | I37: kh phá hd thu được điện nước
A38: 46118 | B38: T30 | C38: 502 | D38: Chống thấm dột mái WC | F38: 80000 | H38: Đặng Trung Kiên
B39: T13 | C39: 602 | D39: Sơn phòng + Dọn phòng | E39: 400000 | G39: Khách chi | H39: Đỗ Thùy Linh
B40: S22 | D40: Sửa mất nước | F40: 65000 | H40: Nguyễn Công Lâm
...

Sheet A Ước T4.26
A1: TIMEHOUSE SỬA CHỮA A ƯỚC THÁNG 4.26
A2: NGÀY | B2: TÒA | C2: MÃ PHÒNG | D2: NỘI DUNG SỬA CHỮA | E2: TIỀN CÔNG | F2: MUA VẬT TƯ | G2: GHI CHÚ | H2: QUẢN LÝ | I2: LOẠI PHÒNG
E3: =SUBTOTAL(109,E4:E100) -> 9300000 | F3: =SUBTOTAL(109,F4:F119) -> 12823000 | H3: 1 | I3: l
A4: 46113 | B4: S19C | C4: 302 | D4: Thay vòi chậu | F4: 120000 | H4: Vũ Đắc Hào
B5: S19C | C5: 302 | D5: Thay bóng đèn | F5: 20000 | H5: Vũ Đắc Hào
A6: 46113 | B6: S38 | C6: 301 | D6: Dọn vệ sinh + Sơn chỗ bẩn | E6: 200000 | G6: Khách HHĐ | H6: Đặng Trung Kiên
A7: 46113 | B7: S44 | C7: 301 | D7: Dọn vệ sinh + Sửa chậu | E7: 200000 | G7: Khách HHĐ | H7: Vũ Đắc Hào
A8: 46113 | B8: S18 | C8: 604 | D8: Dọn vệ sinh + Sửa vòi nước | E8: 200000 | G8: Khách HHĐ | H8: Vũ Đắc Hào
A9: 46113 | B9: S18 | C9: 703 | D9: Dọn máy hút mùi | E9: 100000 | G9: Khách HHĐ | H9: Vũ Đắc Hào
A10: 46114 | B10: T42 | C10: 608 | D10: Sơn phòng | E10: 200000 | H10: Trần Quang Huy | I10: kh phá hd thu điện nước
B11: T42 | C11: 608 | D11: Dọn vệ sinh phòng | E11: 150000 | H11: Trần Quang Huy | I11: kh phá hd thu điện nước
A12: 46114 | B12: T42 | C12: 506 | D12: Sơn phòng | E12: 200000 | H12: Trần Quang Huy
B13: T42 | C13: 506 | D13: Dọn vệ sinh phòng | E13: 150000 | H13: Trần Quang Huy
A14: 46114 | B14: T42 | C14: 103 | D14: Sơn phòng | E14: 200000 | H14: Trần Quang Huy
B15: T42 | C15: 103 | D15: Dọn vệ sinh phòng | E15: 200000 | G15: Khách | H15: Trần Quang Huy
A16: 46115 | B16: T14 | C16: 503 | D16: Sơn phòng | E16: 200000 | H16: Nguyễn Ngọc Văn Khải
A17: 46116 | B17: S7 | C17: 201 | D17: Sơn phòng + Vệ sinh | E17: 300000 | G17: Khách | H17: Đỗ Thùy Linh
A18: 46116 | B18: S18 | C18: 201 | D18: Dọn vệ sinh phòng | E18: 150000 | G18: (Khách HHĐ) | H18: Vũ Đắc Hào
A19: 46116 | B19: T14 | C19: 401 | D19: Sơn phòng | E19: 200000 | H19: Nguyễn Ngọc Văn Khải | I19: kh phá hd thu điện nước
B20: T14 | C20: 401 | D20: Dọn vệ sinh phòng | E20: 150000 | H20: Nguyễn Ngọc Văn Khải | I20: kh phá hd thu điện nước
A21: 46116 | B21: S39 | C21: 302 | D21: Dọn vệ sinh + Sơn tỉa | E21: 150000 | H21: Nguyễn Ngọc Văn Khải | I21: kh phá hd thu điện nước
A22: 46117 | B22: T42 | D22: vệ sinh téc nước | E22: 400000 | H22: Trần Quang Huy
A23: 46117 | B23: S18 | C23: 304 | D23: dọn vệ sinh phòng | E23: 150000 | H23: Vũ Đắc Hào
A24: 46117 | B24: S2 | C24: 308 | D24: Sơn phòng | E24: 200000 | H24: Đặng Trung Kiên
B25: S2 | C25: 308 | D25: dọn vệ sinh phòng | E25: 150000 | H25: Đặng Trung Kiên
A26: 46117 | B26: S2 | C26: 402 | D26: Sơn phòng | E26: 200000 | H26: Đặng Trung Kiên | I26: kh phá hd thu điện nước
B27: S2 | C27: 402 | D27: dọn vệ sinh phòng | E27: 150000 | H27: Đặng Trung Kiên | I27: kh phá hd thu điện nước
A28: 46117 | B28: T42 | C28: 506 | D28: Thay 1 bộ bát sen | F28: 80000 | H28: Trần Quang Huy
A29: 46118 | B29: T43 | D29: Thay van cấp máy giặt | F29: 30000 | H29: Đỗ Thanh Hương
A30: 46118 | B30: S3 | C30: 303 | D30: dọn vệ sinh và sơn phòng | E30: 800000 | G30: khách | H30: Đỗ Thùy Linh
A31: 46118 | B31: S3 | C31: 403 | D31: dọn vệ sinh phòng | E31: 200000 | G31: khách | H31: Đỗ Thùy Linh
A32: 46119 | B32: S4a | C32: 204 | D32: Sơn phòng | E32: 200000 | H32: Nguyễn Ngọc Văn Khải
A33: 46119 | B33: VP | D33: chạy thêm đường điện ở văn phòng mới | F33: 420000
A34: 46120 | B34: T42 | D34: lắp đặt máy bơm áp | F34: 1800000 | H34: Trần Quang Huy
B35: T42 | D35: dây điện | F35: 150000 | H35: Trần Quang Huy
B36: T42 | D36: ống + cút + keo | F36: 70000 | H36: Trần Quang Huy
A37: 46120 | B37: S7 | C37: 201 | D37: Thay van cấp | F37: 40000 | H37: Đỗ Thùy Linh
A38: 46120 | B38: S19c | C38: 201 | D38: Thay tụ quạt trần | F38: 10000 | H38: Vũ Đắc Hào
A39: 46121 | B39: T17 | D39: Sơn cổng và sơn nhà xe | F39: 475000 | H39: Nguyễn Thị Thương Huyền
B40: T17 | D40: Sơn đen 5kg | E40: 400000 | F40: 20000 | H40: Nguyễn Thị Thương Huyền
...

Sheet A Điệp 5.26
A1: TIMEHOUSE SỬA CHỮA THÁNG 5.26
A2: NGÀY | B2: TÒA | C2: MÃ PHÒNG | D2: NỘI DUNG SỬA CHỮA | E2: TIỀN CÔNG | F2: MUA VẬT TƯ | G2: GHI CHÚ
E3: =SUBTOTAL(109,E4:E85) -> 7150000 | F3: =SUBTOTAL(109,F4:F85) -> 8003000
A4: 26/4 | B4: S33 | C4: 302 | D4: Thay chống giật BNL | F4: 120000
B5: S33 | C5: 302 | D5: Đi lại đường nước nóng | F5: 56000
B6: S45 | C6: 303 | D6: Sơn phòng | E6: 150000
B7: S45 | C7: 303 | D7: Dọn phòng | E7: 150000
B8: S45 | C8: 303 | D8: Thay dây sen | F8: 50000
B9: S45 | C9: 303 | D9: Thay vòi gạt | F9: 50000
B10: S45 | C10: 303 | D10: Thông tắc chậu rửa mặt | E10: 150000
B11: S33 | C11: 203 | D11: Thay cần gạt bồn cầu | F11: 50000
A12: 27/4 | B12: S23 | D12: Thay bơm áp trên sân thượng | F12: 1050000
A13: 28/4 | B13: T33 | C13: 501 | D13: Sơn phòng | E13: 300000
B14: T33 | C14: 501 | D14: Dọn phòng | E14: 100000
B15: T33 | C15: 501 | D15: Sơn cửa sổ + song săt cửa | E15: 100000 | F15: 98000
B16: T33 | C16: 501 | D16: Lắp chốt + Tay nắm cửa nhà vệ sinh | F16: 40000
B17: S16 | C17: 404 | D17: Thay đồng hồ điện | F17: 150000
A18: 29/4 | B18: T2 | C18: 601 | D18: Thay bóng âm trần | F18: 315000
B19: T2 | C19: 601 | D19: Bắt giá cài bát sen | F19: 10000
B20: T2 | C20: 601 | D20: Dọn phòng | E20: 150000
B21: T2 | C21: 502 | D21: Dọn phòng | E21: 150000 | G21: Khách hết hđ
B22: T2 | C22: 502 | D22: Thay 11 bóng âm trần | F22: 385000
B23: T2 | C23: 502 | D23: Thay hút mùi nvs | E23: 50000 | F23: 150000 | G23: Khách chi
A24: 3/5 | B24: T34 | C24: 101 | D24: Tháo lắp điều hòa mới | E24: 600000
B25: S12 | C25: 408 | D25: Sửa giường sập | F25: 45000
B26: S33 | C26: 203 | D26: Sửa vòi chậu rửa bát | F26: 165000
A27: 4/5 | B27: T12 | C27: 402 | D27: Dọn phòng | E27: 150000
B28: S45 | C28: 102 | D28: Dọn phòng + Sơn trả | E28: 150000
B29: S45 | D29: Hàn lại cánh cổng bị rơi ra | F29: 86000
B30: T33 | C30: 501 | D30: Tháo điều hòa ở vp cũ đưa về lắp 501T33 | E30: 600000
A31: 5/5 | B31: T41 | C31: 403 | D31: Sửa hút mùi nhà WC | F31: 50000
B32: T33 | C32: 402 | D32: Sơn phòng + Dọn phòng | E32: 300000
B33: T13 | C33: 201 | D33: Sơn phòng + Dọn phòng | E33: 300000 | G33: Kh chi
B34: T13 | C34: 201 | D34: Bắn alu gác xép | E34: 150000 | F34: 295000
B35: T34 | C35: 401 | D35: Sơn phòng | E35: 300000
B36: T34 | C36: 401 | D36: Dọn phòng | E36: 200000
A37: 6/5 | B37: T25 | C37: 104 | D37: Thay tấm alu sau tủ quần áo | F37: 250000
B38: T25 | C38: 104 | D38: Thay vòi liền sen | F38: 200000
A39: 7/5 | B39: T36 | C39: 302 | D39: Thay tấm trần nhà | F39: 35000
B40: S49 | C40: 202 | D40: Dọn phòng | E40: 100000
...

Sheet A Ước 5.26 
A1: TIMEHOUSE SỬA CHỮA THÁNG 5.26
A2: NGÀY | B2: TÒA | C2: MÃ PHÒNG | D2: NỘI DUNG SỬA CHỮA | E2: TIỀN CÔNG | F2: MUA VẬT TƯ | G2: GHI CHÚ
E3: =SUBTOTAL(109,E4:E79) -> 7400000 | F3: =SUBTOTAL(109,F4:F79) -> 3248000
A4: 46058 | B4: T14 | C4: 303 | D4: Dọn vệ sinh + Sơn điểm | E4: 200000
B5: T14 | C5: 304 | D5: Thay đồng hồ điện | F5: 160000
B6: S42 | C6: 101 | D6: Dọn vệ sinh phòng | E6: 150000
B7: S42 | C7: 301 | D7: Dọn vệ sinh phòng | E7: 150000
A8: 46086 | B8: S2 | C8: 404 | D8: Dọn vệ sinh phòng | E8: 200000
B9: S2 | C9: 404 | D9: Sơn phòng | E9: 200000
A10: 46117 | B10: S13 | C10: 502 | D10: Sơn phòng | E10: 200000
B11: s13 | C11: 301 | D11: Sơn phòng | E11: 200000
A12: 46147 | B12: T37 | C12: 402 | D12: Lắp thêm bóng típ | F12: 80000
B13: S50 | C13: 703 | D13: Dọn vệ sinh phòng | E13: 150000
B14: S50 | C14: 703 | D14: Thay bóng âm trần | F14: 80000
B15: S50 | C15: 201 | D15: Dọn vệ sinh phòng | E15: 400000
A16: 46178 | B16: S39 | C16: 405 | D16: Dọn vệ sinh phòng | E16: 150000
B17: T42 | C17: 109 | D17: Dọn vệ sin phòng + Thay bóng đèn | E17: 300000
B18: T42 | C18: 109 | D18: Sơn phòng | E18: 200000
B19: T42 | C19: 307 | D19: Dọn vệ sinh phòng | E19: 200000
A20: 46208 | B20: S19B | C20: 203 | D20: Thay quạt trần | F20: 750000
B21: S13 | C21: 504 | D21: Sơn phòng | E21: 200000
B22: S13 | C22: 504 | D22: Dọn vệ sinh phòng | E22: 250000
B23: S13 | C23: 504 | D23: Thay 1 bộ bát sen | F23: 80000
A24: 46208 | B24: S13 | C24: 203 | D24: Sơn phòng | E24: 200000 | G24: 1/2 lấy sơn thùng T42
B25: S13 | C25: 203 | D25: Dọn vệ sinh phòng | E25: 200000
A26: 46239 | B26: T17 | C26: 301 | D26: Sơn phòng | E26: 200000 | G26: 1/2 lấy sơn thùng T42
B27: T17 | C27: 301 | D27: Dọn vệ sinh phòng | E27: 300000 | G27: Kh chi
A28: 46300 | B28: T37 | C28: 102 | D28: Lắp 1 bộ bóng típ | F28: 75000
A29: 46331 | B29: T42 | C29: 108 | D29: Thay dây cấp nước | F29: 25000
A30: 13/5 | B30: S7 | C30: 103 | D30: Thay vòi chậu | F30: 120000
A31: 14/5 | B31: S8 | D31: Thay van máy giặt | F31: 35000
B32: T22 | D32: Sơn nhà xe | E32: 400000
A33: 19/5 | B33: T37 | C33: 301 | D33: Thay dây cấp nước | F33: 25000
B34: T42 | C34: 103 | D34: Thay 1 bộ bát sen | F34: 80000
B35: S25A | C35: 202 | D35: Dọn vệ sinh phòng | E35: 200000
B36: S25A | C36: 202 | D36: Thay 1 bộ bát sen | F36: 80000
A37: 21/5 | B37: S25A | C37: 601 | D37: Dọn vệ sinh phòng | E37: 200000
B38: S25A | C38: 601 | D38: Thay bóng tròn | F38: 22000
B39: S25A | D39: Thay bóng sân phơi | F39: 22000
B40: T14 | C40: 503 | D40: Thay quạt húi mùi | F40: 180000
...

Sheet trường t5.2026
A1: Ngày | B1: Lỗi sửa chữa + mua đồ | C1: Toà nhà | D1: Phòng | E1: Chi phí vật liệu | F1: Chi phí công | G1: Bên chi | H1: Ghi chú chi tiết
A2: Tháng 5 | G2: cty
A3: 46149 | B3: Đi đường điện lắp bóng từ cổng ra ngõ | C3: S12 | E3: 775 | G3: cty
A4: 46150 | B4: Dơn dọn, thay bát sen | C4: S10 | D4: 303 | E4: 70 | F4: 200 | G4: cty
B5: Thay cấp xả bệt, bộ dây vòi sen | C5: S25A | D5: 302 | E5: 180 | G5: Cty
A6: 46151 | B6: Thay lavabo, 2 dây cấp, bóng tuýp | C6: S12 | D6: 101 | E6: 275 | G6: Cty
B7: Dọn phòng | C7: G5 | D7: 203 | F7: 200 | G7: Cty
A8: 46152 | B8: Thay máng đèn,dây bát sen, giá đỡ dây xịt | C8: S12 | D8: 204 | E8: 125 | G8: Cty
B9: Thay bộ gương + kệ | C9: S12 | D9: 304504 | E9: 400 | G9: cty
B10: Lăn sơn, nối dây sen | C10: S12 | E10: 45 | G10: cty
B11: Thay bộ ngăn mùi thoát sàn | C11: G6 | D11: 206 | E11: 70 | G11: cty
A12: 46153 | B12: mua bóng tuýp,dây điện,máng bóng lắp vp | C12: VP | E12: 119 | G12: Cty
A13: 46154 | B13: Thay dây cấp bình, thay dây sen | C13: S25A | D13: 101301 | E13: 70 | G13: cty
B14: Dọn phòng | C14: S25A | D14: 301 | F14: 150 | G14: Cty
B15: Thay vòi rửa | C15: G1 | D15: 302 | E15: 120 | G15: Cty
A16: 46155 | B16: Thay đui cẩm ứng + bóng | C16: G3 | D16: 101 | E16: 85 | G16: Cty
B17: Thay bóng đèn | C17: T41 | D17: 503 | E17: 35 | G17: Cty
B18: Vít,nở lắp bảng biển các nhà | E18: 15 | G18: Cty
A19: 46158 | B19: Điều khuyển diều hòa | C19: S28 | D19: 101 | E19: 65 | G19: Cty
B20: Bột bả, giấy giáp, xăng tẩy phòng | C20: G5 | D20: 203 | E20: 40 | G20: Cty
B21: Dây thoát lavabo vp | C21: VP | E21: 30 | G21: cty
A22: 46159 | B22: Thay atp | C22: T45 | D22: 101 | E22: 55 | G22: cty
B23: Thay 2 bánh xe cửa lùa | C23: T5 | D23: 701 | E23: 70 | G23: cty
B24: Thay dây cấp | C24: S21 | D24: 202 | E24: 25 | G24: Cty
B25: Thay 2 đầu xịt bệt | C25: T41 | D25: 501503 | E25: 80 | G25: cty
A26: 46161 | B26: Phao cơ | C26: S47 | E26: 140 | G26: cty
B27: Thay vòi chậu rửa | C27: S25A | E27: 80 | G27: cty
B28: Thay van cấp máy giặt | C28: S21 | E28: 30 | G28: cty
A29: 46162 | B29: Dọn phòng | C29: G5 | D29: 503 | F29: 200 | G29: cty
A30: 46164 | B30: Thay bóng nhà xe | C30: T41 | E30: 45 | G30: cty
B31: Thay 3 bóng hành lang | C31: T5 | E31: 100 | G31: cty
A32: 46165 | B32: Giá đỡ, vít lavabo | C32: T5 | D32: 202 | E32: 15 | G32: cty
B33: Thay phao điện | C33: G3,S25A | E33: 300 | G33: cty
B34: Vật tư đi lại đường điện sân phơi, bếp | C34: S28 | E34: 362 | G34: cty
A35: 46168 | B35: lắp thoát sàn 1 chiều | C35: G6 | D35: 506 | E35: 60 | G35: cty
B36: Vật tư lắp cam | C36: G5 | E36: 62 | F36: 100 | G36: cty
B37: ngăn mùi thoát sàn | C37: T41 | D37: 401 | E37: 30 | G37: cty
A38: 46169 | B38: Thay atp tổng | C38: T45 | E38: 150 | G38: cty
B39: Thay phao điện | C39: G1,S28 | E39: 240 | G39: cty
A40: 46170 | B40: Sơn dọn phòng | C40: T5 | D40: 101 | F40: 500 | G40: cty | H40: trừ cọc
...

Sheet Sheet4
A1: Danh sách sử dụng sơn tháng 5 ( 17 thùng ngày 4/5)
A2: Mã phòng | B2: Số lượng | C2: Ghi chú
A3: 101T25 | B3: 1 | C3: lấy 1 thùng ở điểm T20 | I3: S3 | J3: 3 thùng
A4: 203S13 | B4: 1 | C4: lấy 1 thùng ở điểm T42( lấy 1 thùng nguyên dùng hết 1/2 đang ở 203S13 | I4: T33 | J4: 3 thùng
A5: 301T17 | B5: 1 | C5: lấy 1 thùng ở điểm T42 (lấy 1 thùng nguyên dùng hết 1/3 đang ở 301T17) | I5: T28 | J5: 3 thùng
A6: 501T33, 402T33 | B6: 1 | C6: lấy từ vp | I6: T20 | J6: 3 thùng
A7: 401T34 | B7: 1 | C7: lấy từ vp
A8: 101, 501T5 | B8: 1 | C8: lấy từ điểm T20
A9: T28 | B9: 1 | C9: lấy về các điểm( chuyển về 2 thùng 1 thùng sang T35)
A10: T24 ( sơn nhà xe) | B10: 1 | C10: lấy từ vp đi ( đãng nhẽ là chuyển về kho t33)
A11: T22 ( Nhà xe) | B11: 2 | C11: lấy từ vp
A12: T42 | B12: 1 | C12: lấy từ vp điều chuyển về điểm chứa sơn ( chuyển 4 1 thùng sang G9, 1 thùng sang 203S13, 1 thùng sang 301T17)
A13: S10,S3 | B13: 1/3 và 2/3 | C13: lấy từ điểm S3 ( S3 dùng 1/3 và S10 dùng 2/3)
A14: G9 | B14: 1 | C14: lấy từ điểm T42
A15: T17( nhà xe) | B15: 1 | C15: sơn đặt riêng nhà huyền
A16: T13 | B16: 1 | C16: sơn đặt riêng nhà huyển
A17: T26 | B17: 1 | C17: sơn đặt riêng nhà huyền | D17: d
A18: 101T38 | B18: 1 | C18: sơn đặt riêng cho nhà huyền
A19: T35 | B19: 1 | C19: chuyển từ t28 sang
A20: S48 | B20: 1 | C20: chuyển từ điểm T20
A21: T32 | B21: 1
A22: T36 | B22: 1
C23: còn thiếu 4 thùng

Sheet A Điệp 6.26
A1: TIMEHOUSE SỬA CHỮA THÁNG 6.26
A2: NGÀY | B2: TÒA | C2: MÃ PHÒNG | D2: NỘI DUNG SỬA CHỮA | E2: TIỀN CÔNG | F2: MUA VẬT TƯ | G2: GHI CHÚ
E3: =SUBTOTAL(109,E4:E105) -> 10300000 | F3: =SUBTOTAL(109,F4:F105) -> 9186000
A4: 2/6 | B4: T21 | C4: 201 | D4: Sơn phòng | E4: 300000 | G4: Nửa thùng sơn S48
B5: T21 | D5: Dọn phòng | E5: 100000
B6: T21 | D6: Sửa cánh tủ bếp | F6: 65000
B7: S48B | C7: 101 | D7: Sơn phòng | E7: 150000 | G7: Nửa thùng sơn S48
B8: S48B | C8: 101 | D8: Dọn phòng | E8: 100000
B9: T36 | C9: 302 | D9: Sơn phòng | E9: 200000
B10: T36 | D10: Dọn phòng | E10: 100000
A11: 3/6 | B11: T36 | D11: Thay vòi rửa bát | F11: 120000
B12: T21 | C12: Tầng 3 | D12: Thay bóng điện hành lang | F12: 25000
B13: T35 | C13: 303 | D13: Sơn phòng | E13: 200000 | G13: Nửa thùng sơn T28
B14: T35 | D14: Dọn phòng | E14: 100000
B15: T35 | D15: Sơn lan can + Cầu thang + Cửa sổ + Cửa ra vào | E15: 150000 | F15: 202000
A16: 4/6 | B16: T21 | C16: 403 | D16: Sơn phòng | E16: 250000 | G16: Nửa thùng sơn T21
B17: T21 | D17: Dọn phòng | E17: 150000
B18: T21 | C18: 404 | D18: Sơn phòng | E18: 300000 | G18: Nửa thùng sơn T21
B19: T21 | D19: Dọn phòng | E19: 300000
A20: 5/6 | B20: T18 | C20: 202 | D20: Sơn phòng | E20: 150000
B21: T18 | D21: Dọn phòng | E21: 100000
B22: T18 | C22: 601 | D22: Sơn phòng | E22: 200000
B23: T18 | D23: Dọn phòng | E23: 100000
B24: S45 | C24: 504 | D24: Chống thấm dột góc trần | F24: 55000
A25: 6/6 | B25: T20 | C25: 302 | D25: Sơn + bóc xốp dán tường + Cạo chũi | E25: 300000
B26: T20 | D26: Dọn phòng | E26: 100000
B27: T20 | D27: Sửa cửa chính xệ | F27: 10000
B28: T20 | D28: Thay bóng típ | F28: 45000
B29: T20 | D29: Thay bóng trần | F29: 60000
B30: S24 | D30: Thay 2 bóng đèn thang máy
A31: 7/6 | B31: S22 | C31: 104 | D31: Dọn phòng | E31: 100000
A32: 8/6 | B32: S45 | D32: Thay phao téc + Phao bể ngầm | F32: =80000+140000 -> 220000
A33: 10/6 | B33: T20 | D33: Lắp máng nước mái tôn trước cổng | E33: 200000 | F33: 295000
A34: 11/6 | B34: T20 | C34: 504 | D34: Cạo chũi , tháo dỡ tủ + Sơn phòng | E34: 200000
B35: T20 | C35: 504 | D35: Dọn phòng | E35: 100000
B36: S40 | D36: Xử lý tràn nước bể ngầm | F36: 150000
A37: 13/6 | B37: T38 | C37: 101 | D37: Dọn phòng | E37: 100000
A38: 14/6 | B38: T8 | D38: Chạy lại ống thoát máy giặt vào đường thoát khác | E38: 150000 | F38: 48000
A39: 19/6 | B39: S33 | C39: 202 | D39: Xử lý nước thải điều hòa nhỏ giọt xuống t1 | F39: 23000
B40: T8 | C40: 402 | D40: Xử lý rò nước đầy nhỏ xuống kv bếp | E40: 200000 | F40: 95000
...

Sheet A Ước 6.26
A1: TIMEHOUSE SỬA CHỮA THÁNG 6.26
A2: NGÀY | B2: TÒA | C2: MÃ PHÒNG | D2: NỘI DUNG SỬA CHỮA | E2: TIỀN CÔNG | F2: MUA VẬT TƯ | G2: GHI CHÚ
E3: =SUBTOTAL(109,E4:E87) -> 7450000 | F3: =SUBTOTAL(109,F4:F87) -> 4265000
A4: 46174 | B4: T42 | C4: 306 | D4: Dọn vệ sinh phòng | E4: 200000
B5: T42 | D5: Thay bóng đèn | F5: 25000
B6: T42 | C6: 308 | D6: Dọn vệ sinh phòng | E6: 150000
B7: T42 | C7: 103 | D7: Thay gạt nước bồn cầu | F7: 20000
B8: S25A | C8: 502 | D8: Dọn vệ sinh phòng | E8: 200000
B9: S25A | C9: 501 | D9: Dọn vệ sinh phòng | E9: 300000 | G9: Khách hết hd
A10: 46175 | B10: S4 | D10: Thay phao trên téc | F10: 80000
B11: S29 | C11: 402 | D11: Dọn vệ sinh phòng | E11: 150000
B12: S18 | C12: 502 | D12: Sơn phòng | E12: 200000
B13: S18 | D13: Dọn vệ sinh phòng | E13: 150000
B14: S18 | D14: Sửa BNL | F14: 120000
B15: T10 | C15: 301 | D15: Sơn phòng | E15: 200000
B16: T10 | D16: Dọn vệ sinh phòng | E16: 150000
B17: T10 | D17: Thay 1 bộ vòi xịt | F17: 80000
B18: T22 | C18: 401 | D18: Sơn phòng | E18: 200000
B19: T22 | D19: Dọn vệ sinh phòng | E19: 150000
B20: T22 | D20: Thay 1 bộ bát sen tăng áp | F20: 100000
B21: T22 | D21: Thay vòi chậu rửa | F21: 120000
B22: T22 | D22: Thay 1 dây cấp nước | F22: 25000
B23: T22 | D23: Thay 1 bộ nắp bệt | F23: 80000
A24: 46176 | B24: S7 | C24: 302 | D24: Sơn tường + dọn vệ sinh | E24: 300000
B25: S7 | D25: Thay 1 bộ bát sen | F25: 80000
B26: S7 | D26: Thay vòi rửa bát | F26: 120000
B27: S7 | D27: Lắp thêm bóng đèn | F27: 40000
B28: S14 | C28: 202 | D28: Thay 1 bộ vòi xịt | F28: 80000
B29: T42 | D29: Thay phao bể ngầm | F29: 85000
B30: G5 | C30: 201 | D30: Dọn vệ sinh phòng | E30: 150000
B31: G5 | C31: 303 | D31: Dọn vệ sinh phòng | E31: 150000
B32: G5 | C32: 601 | D32: Dọn vệ sinh phòng | E32: 150000
A33: 46177 | B33: G1 | C33: 601 | D33: Dọn vệ sinh phòng | E33: 150000
B34: G6 | C34: 102 | D34: Dọn vệ sinh phòng | E34: 150000
B35: G8 | D35: Chậu rửa bát | F35: 300000
B36: G8 | D36: Vòi chậu | F36: 120000
A37: 46178 | B37: S10 | C37: 401 | D37: Thay vòi gạt | F37: 40000
B38: S10 | D38: Thay bóng đèn | F38: 20000
A39: 46179 | B39: S8 | C39: 104 | D39: Sơn phòng | E39: 200000
B40: S8 | D40: Dọn vệ sinh phòng | E40: 150000
...

Sheet Trường 6.2026
A1: Ngày | B1: Lỗi sửa chữa + mua đồ | C1: Toà nhà | D1: Phòng | E1: Chi phí vật liệu | F1: Chi phí công | G1: Bên chi | H1: Ghi chú chi tiết
A2: Tháng 6 | G2: cty
A3: 46181 | B3: điều khuyển đh | C3: S28 | D3: 204 | E3: 65 | G3: cty | H3: đk đa năng k dò đc
B4: bát sen,vòi gạt | C4: s10 | D4: 102 | E4: 90 | G4: cty
B5: thay phao cơ | C5: g5 | E5: 150 | G5: Cty
A6: 46182 | B6: Dây xịt,bát sen | C6: t5 | D6: 101 | E6: 80 | G6: Cty
A7: 46186 | B7: 2 bóng tròn hành lang, vít nở | C7: T5 | E7: 65 | G7: Cty
B8: 1 bóng tròn thây nvs | C8: s10 | D8: 501 | E8: 30 | G8: Cty
B9: bản lề cửa | C9: T5 | D9: 701 | E9: 50 | G9: cty
A10: 46188 | B10: vòi rửa,dây cấp | C10: S47 | D10: 201 | E10: 150 | G10: cty
B11: vòi chậu dây cấp | C11: T44 | D11: 201 | E11: 150 | G11: cty
B12: Dây thoát máy giặt | C12: T45 | E12: 20 | G12: Cty
B13: dây- bát sen | C13: T44 | D13: 101 | E13: 80 | G13: cty
A14: 46190 | B14: bát sen | C14: G9 | D14: 302 | E14: 40 | G14: Cty
B15: Chốt cửa gạt | C15: S25a | D15: 202 | E15: 40 | G15: Cty
A16: 46191 | B16: Dây đầu xịt | C16: G2 | D16: tầng 1 | E16: 80 | G16: Cty
B17: 2 khóa gạt S25A phòng trống | C17: S25A | E17: 70 | G17: Cty
B18: Khóa cửa lùa | C18: S27 | D18: 202 | E18: 70 | G18: Cty
A19: 46192 | B19: Thay đồng hồ điện | C19: S10 | D19: 402 | E19: 175 | G19: Cty
B20: đèn | C20: T43 | D20: 402 | E20: 85 | G20: Cty
B21: Sửa tăng atp | C21: G2 | E21: 350 | G21: cty
B22: Thay rắc co nhiệt bị rò | C22: G2 | E22: 67 | G22: cty
A23: 46198 | B23: Sơn hành lang,nxe G10 | C23: G10 | F23: 500 | G23: cty
B24: Sơn phòng 302,401 | C24: G10 | D24: 302401 | F24: 400 | G24: Cty
A25: 46199 | B25: vật tư lắp máy giăt | C25: G4 | E25: 120 | G25: cty
B26: sửa điều hòa | C26: G10 | D26: 401 | E26: 400 | G26: cty | H26: kê cho nguồn sau thu qly cũ
A27: 46205 | B27: Chổi lăn sơn, móc dán deco, nước ae hỗ trợ | C27: G13 | E27: 165 | G27: cty
B28: Vòi chậu rửa | C28: G10 | D28: 401 | E28: 120 | G28: cty
B29: Sơn nhà xe, hành lang lên t2, phòng lửng | C29: G13 | F29: 400 | G29: cty
B30: Thây vòi gạt | C30: T44 | D30: 201 | E30: 70 | G30: cty
G31: cty
G32: cty
G33: cty
G34: cty
G35: cty
G36: cty
G37: cty
G38: cty
G39: cty
G40: cty
...

Sheet A Điệp 7.26
A1: TIMEHOUSE SỬA CHỮA THÁNG 7.26
A2: NGÀY | B2: TÒA | C2: MÃ PHÒNG | D2: NỘI DUNG SỬA CHỮA | E2: TIỀN CÔNG | F2: MUA VẬT TƯ | G2: GHI CHÚ
E3: =SUM(E4:E98) -> 10000000 | F3: =SUM(F4:F98) -> 6278000
A4: 28/6 | B4: S48A | D4: Sơn chống thấm giếng trời | E4: 300000 | F4: 595000 | G4: 2kg sơn chống thấm + lu sơn + chổi sơn
A5: 46202 | B5: G10 | C5: 202 | D5: Sơn phòng | E5: 300000
A6: 46202 | B6: G10 | C6: 202 | D6: Dọn phòng | E6: 100000
A7: 46202 | B7: G10 | C7: 202 | D7: Thay vòi xịt | F7: 40000
A8: 46202 | B8: G10 | C8: 202 | D8: Thay dây sen | F8: 40000
A9: 46203 | B9: G10 | C9: 101 | D9: Sơn phòng | E9: 300000
A10: 46203 | B10: G10 | C10: 101 | D10: Dọn phòng | E10: 100000
A11: 46203 | B11: G10 | C11: 101 | D11: Thay vòi gạt | F11: 35000
A12: 46203 | B12: T13 | C12: 501 | D12: Sơn+ dọn phòng | E12: 500000 | G12: 1 thùng lấy T20 ( khách chi )
A13: 46203 | B13: T13 | C13: 501 | D13: Bắn tấm alu gác lửng | E13: 150000 | F13: 295000
A14: 46203 | B14: S31 | C14: 601 | D14: Thay dây sen | F14: 80000 | G14: Khách báo từ lúc đầu đã bị
A15: 46204 | B15: T35 | C15: 404 | D15: Sơn phòng | E15: 300000
A16: 46204 | B16: T35 | C16: 404 | D16: Dọn phòng | E16: 200000 | G16: Quá bẩn
A17: 46204 | B17: T35 | C17: 404 | D17: Sơn cửa sổ + sơn mặt trong cửa chính + lan can | E17: 150000 | F17: 202000 | G17: Sơn + chổi sơn
A18: 46204 | B18: T25 | C18: 106 | D18: Sơn cao chũi bỏ tủ cũ | E18: 350000 | G18: Phòng đôi
A19: 46204 | B19: T25 | C19: 106 | D19: Dọn phòng | E19: 200000
A20: 46204 | B20: T25 | C20: 106 | D20: Thông tắc thoát chậu rửa bát | F20: 115000
A21: 46205 | B21: S22 | C21: 404 | D21: Sơn + Dọn phòng | E21: 300000
A22: 46205 | B22: S22 | C22: 404 | D22: Thay 2 bản lề cửa nhà WC | F22: 35000
A23: 46205 | B23: S45 | C23: 202 | D23: Sơn + Dọn phòng | E23: 350000 | G23: Thùng sơn T33
A24: 46205 | B24: S5 | C24: 203 | D24: Sơn + Dọn phòng | E24: 350000
A25: 46205 | B25: S5 | C25: 203 | D25: Thay 2 bóng tròn | F25: 50000
A26: 46205 | B26: S5 | C26: 203 | D26: Thay bóng típ | F26: 45000
A27: 46205 | B27: S5 | C27: 203 | D27: Thay nắp bệt + sửa cửa WC | F27: 80000
A28: 46205 | B28: S5 | D28: Thay bóng điện hành lang t1 - t2 | F28: 110000
A29: 46206 | B29: G9 | C29: 501 | D29: Cạo + chũi sơn phòng + dọn phòng | E29: 350000
A30: 46206 | B30: G9 | C30: 501 | D30: Thay bóng típ | F30: 45000
A31: 46206 | B31: T18 | C31: 202 | D31: Dọn phòng | E31: 100000
A32: 46206 | B32: S50 | C32: 703 | D32: Dọn phòng | E32: 150000
A33: 46206 | B33: G5 | C33: 601 | D33: Sửa chậu rửa mặt xệ | F33: 25000
A34: 46206 | B34: G5 | D34: Xử lý đường thoát nước máy giặt sân thượng | F34: 65000
A35: 46207 | B35: S12 | C35: Tầng 4 | D35: Thay bóng điện hành lang | F35: 25000
A36: 46207 | B36: T25 | C36: 305 | D36: Sơn + Dọn phòng | E36: 350000
A37: 46207 | B37: T20 | C37: 503 | D37: Cạo chũi sơn dọn phòng | E37: 350000
A38: 46207 | B38: T7 | C38: 502 | D38: Sơn + Dọn phòng | E38: 350000
A39: 46208 | B39: T8 | C39: 402 | D39: Sơn phòng | E39: 200000
A40: 46208 | B40: T26 | C40: 402 | D40: Dọn phòng | E40: 100000
...

Sheet A Ước 7.26
A1: TIMEHOUSE SỬA CHỮA THÁNG 7.26
A2: NGÀY | B2: TÒA | C2: MÃ PHÒNG | D2: NỘI DUNG SỬA CHỮA | E2: TIỀN CÔNG | F2: MUA VẬT TƯ | G2: GHI CHÚ
E3: =SUM(E4:E71) -> 3850000 | F3: =SUM(F4:F71) -> 10235000
A4: 46204 | B4: S30 | C4: 303 | D4: Dọn phòng | E4: 150000
A5: 46204 | B5: S21 | C5: 701 | D5: Chống thấm mái | F5: 85000
A6: 46205 | B6: S25A | C6: 601 | D6: Thay 1 bộ sen tường | F6: 350000
A7: 46205 | B7: S44 | C7: 403 | D7: Dọn phòng | E7: 150000
A8: 46205 | B8: S1 | C8: 202 | D8: Dọn phòng + Sơn nvs | E8: 200000
A9: 46205 | B9: S1 | C9: 202 | D9: Bắn keo lại tấm alu | F9: 55000
A10: 46206 | B10: S36 | C10: 401 | D10: Dọn phòng | E10: 150000
A11: 46206 | B11: S4 | C11: 303 | D11: Dọn phòng | E11: 200000
A12: 46206 | B12: S25A | C12: 102 | D12: Đi lại đường ống thoát nước | F12: 50000
A13: 46206 | B13: S2 | C13: 204 | D13: Dọn phòng | E13: 150000
A14: 46206 | B14: T15 | C14: 202 | D14: Dọn phòng | E14: 150000
A15: 46207 | B15: T15 | C15: 603 | D15: Dọn phòng | E15: 150000
A16: 46207 | B16: T15 | C16: 501 | D16: Dọn phòng | E16: 200000
A17: 46207 | B17: T15 | C17: 501 | D17: Sơn phòng | E17: 200000 | G17: 1/2 lấy ở T42
A18: 46207 | B18: T15 | C18: 501 | D18: Thay bát sen | F18: 40000
A19: 46208 | B19: S3 | C19: 102 | D19: Dọn phòng | E19: 150000
A20: 46208 | B20: S3 | C20: 102 | D20: Thay vòi gạt | F20: 45000
A21: 46208 | B21: S3 | C21: 202 | D21: Dọn phòng | E21: 150000
A22: 46208 | B22: S3 | C22: 202 | D22: Thay bát sen | F22: 40000
A23: 46208 | B23: S3 | C23: 103 | D23: Dọn phòng | E23: 150000
A24: 46208 | B24: S3 | C24: 103 | D24: Thay bát sen | F24: 40000
A25: 46208 | B25: S3 | C25: 203 | D25: Dọn phòng | E25: 200000
A26: 46208 | B26: S3 | C26: 203 | D26: Thay nút ấn bồn cầu | F26: 80000
A27: 46208 | B27: S3 | C27: 203 | D27: Thay bát sen | F27: 40000 | G27: Khách hết hd
A28: 46208 | B28: S3 | C28: 203 | D28: Tiền công | E28: 100000
A29: 46209 | B29: T14 | D29: Thay bóng điện hành lang , cầu thang 8 bóng | F29: 176000
A30: 46209 | B30: T15 | D30: Thay bóng điện hành lang 2 bóng | F30: 44000
A31: 46209 | B31: T37 | C31: 402 | D31: Thay dây cấp | F31: 25000
A32: 46207 | B32: VP | D32: Sửa cửa vp | F32: 480000
A33: 46207 | B33: VP | D33: Thay khóa cửa và bản lề lõi thép
A34: 46215 | B34: S7 | D34: Thay van cấp máy giặt | F34: 35000
A35: 46216 | B35: S3 | C35: 102 | D35: Thay dây cấp | F35: 35000
A36: 46217 | B36: S13 | D36: Thông tắc bể phốt | E36: 200000
A37: 46218 | B37: S13 | D37: Sửa bảng mạch máy giặt | F37: 200000
A38: 46218 | B38: S43 | D38: Thay bóng cầu thang | F38: 30000
A39: 46218 | B39: G13 | D39: Mua đồ làm ở G13
A40: 46218 | B40: G13 | D40: Chậu đơn 1 hố | F40: 950000
...

Sheet LƯƠNG THÁNG 5
A12: BẢNG LƯƠNG THÁNG 5-A ĐIỆP
A13: TÊN | B13: MỨC LƯƠNG | C13: HỆ SỐ | D13: TỔNG | I13: BẢNG LƯƠNG THÁNG 5-A ƯỚC
A14: LƯƠNG CỨNG | B14: 7000000 | C14: 1 | D14: =B14*C14 -> 7000000 | I14: TÊN | J14: MỨC LƯƠNG | K14: HỆ SỐ | L14: TỔNG
A15: LƯƠNG THÂM NIÊN | B15: 2000000 | C15: 1 | D15: =B15*C15 -> 2000000 | I15: LƯƠNG CỨNG | J15: 7000000 | K15: 1 | L15: =J15*K15 -> 7000000
A16: TIỀN CÔNG ( THEO BẢNG KÊ) | B16: ='A Điệp 5.26'!E3 -> 7150000 | C16: 1 | D16: =B16*C16 -> 7150000 | I16: LƯƠNG THÂM NIÊN | J16: 2000000 | K16: 1 | L16: =J16*K16 -> 2000000
A17: HỖ TRỢ ĂN TRƯA | B17: 700000 | C17: 1 | D17: =B17*C17 -> 700000 | I17: TIỀN CÔNG ( THEO BẢNG KÊ) | J17: ='A Ước 5.26 '!E3 -> 7400000 | K17: 1 | L17: =J17*K17 -> 7400000
D18: =B18*C18 -> 0 | I18: HỖ TRỢ ĂN TRƯA | J18: 700000 | K18: 1 | L18: =J18*K18 -> 700000
D19: =B19*C19 -> 0
D20: =B20*C20 -> 0
A21: TỔNG | D21: =SUM(D14:D20) -> 16850000
L22: =J22*K22 -> 0
I23: TỔNG | L23: =SUM(L15:L22) -> 17100000
A24: BẢNG ỨNG CHI THÁNG 5- A ĐIỆP
A25: Ứng chi | B25: 8000000
A26: Chi thực tế | B26: ='A Điệp 5.26'!F3 -> 8003000 | I26: BẢNG ỨNG CHI THÁNG 5- A ƯỚC
A27: Tổng HT back lại | B27: =B26-B25 -> 3000 | I27: Ứng chi | J27: 5000000
I28: Chi thực tế | J28: ='A Ước 5.26 '!F3 -> 3248000
I29: Tổng HT back lại | J29: =J28-J27 -> -1752000
A34: BẢNG LƯƠNG THÁNG 5-TRƯỜNG
A35: TÊN | B35: MỨC LƯƠNG | C35: HỆ SỐ | D35: TỔNG
A36: LƯƠNG CỨNG | B36: 4000000 | C36: 1 | D36: =B36*C36 -> 4000000
A37: TIỀN CÔNG ( THEO BẢNG KÊ) | B37: 3400000 | C37: 1 | D37: =B37*C37 -> 3400000
D39: =B39*C39 -> 0
A41: TỔNG | D41: =SUM(D36:D40) -> 7400000
A44: BẢNG ỨNG CHI THÁNG 5- TRƯỜNG
A45: Ứng chi | B45: 3000000
A46: Chi thực tế | B46: 6468000
A47: Tổng HT back lại | B47: =B46-B45 -> 3468000

Sheet LƯƠNG THÁNG 6
A12: BẢNG LƯƠNG THÁNG 7-A ĐIỆP
A13: TÊN | B13: MỨC LƯƠNG | C13: HỆ SỐ | D13: TỔNG | I13: BẢNG LƯƠNG THÁNG 6-A ƯỚC
A14: LƯƠNG CỨNG | B14: 7000000 | C14: 1 | D14: =B14*C14 -> 7000000 | I14: TÊN | J14: MỨC LƯƠNG | K14: HỆ SỐ | L14: TỔNG
A15: LƯƠNG THÂM NIÊN | B15: 2000000 | C15: 1 | D15: =B15*C15 -> 2000000 | I15: LƯƠNG CỨNG | J15: 7000000 | K15: 1 | L15: =J15*K15 -> 7000000
A16: TIỀN CÔNG ( THEO BẢNG KÊ) | B16: ='A Điệp 6.26'!E3 -> 10300000 | C16: 1 | D16: =B16*C16 -> 10300000 | I16: LƯƠNG THÂM NIÊN | J16: 2000000 | K16: 1 | L16: =J16*K16 -> 2000000
A17: HỖ TRỢ ĂN TRƯA | B17: 700000 | C17: 1 | D17: =B17*C17 -> 700000 | I17: TIỀN CÔNG ( THEO BẢNG KÊ) | J17: ='A Ước 6.26'!E3 -> 7450000 | K17: 1 | L17: =J17*K17 -> 7450000
D18: =B18*C18 -> 0 | I18: HỖ TRỢ ĂN TRƯA | J18: 700000 | K18: 1 | L18: =J18*K18 -> 700000
D19: =B19*C19 -> 0
D20: =B20*C20 -> 0
A21: TỔNG | D21: =SUM(D14:D20) -> 20000000
L22: =J22*K22 -> 0
I23: TỔNG | L23: =SUM(L15:L22) -> 17150000
A24: BẢNG ỨNG CHI THÁNG 6- A ĐIỆP
A25: Ứng chi | B25: 8000000
A26: Chi thực tế | B26: 9186000 | I26: BẢNG ỨNG CHI THÁNG 6- A ƯỚC
A27: Tổng HT back lại | B27: =B26-B25 -> 1186000 | I27: Ứng chi | J27: 5000000
I28: Chi thực tế | J28: ='A Ước 6.26'!F3 -> 4265000
I29: Tổng HT back lại | J29: =J28-J27 -> -735000
A34: BẢNG LƯƠNG THÁNG 5-TRƯỜNG
A35: TÊN | B35: MỨC LƯƠNG | C35: HỆ SỐ | D35: TỔNG
A36: LƯƠNG CỨNG | B36: 4000000 | C36: 1 | D36: =B36*C36 -> 4000000
A37: TIỀN CÔNG ( THEO BẢNG KÊ) | B37: 1300000 | C37: 1 | D37: =B37*C37 -> 1300000
D39: =B39*C39 -> 0
A41: TỔNG | D41: =SUM(D36:D40) -> 5300000
A44: BẢNG ỨNG CHI THÁNG 5- TRƯỜNG
A45: Ứng chi | B45: 3000000
A46: Chi thực tế | B46: 2782000
A47: Tổng HT back lại | B47: =B46-B45 -> -218000

Sheet LƯƠNG THÁNG 7
A12: BẢNG LƯƠNG THÁNG 7-A ĐIỆP
A13: TÊN | B13: MỨC LƯƠNG | C13: HỆ SỐ | D13: TỔNG | I13: BẢNG LƯƠNG THÁNG 7-A ƯỚC
A14: LƯƠNG CỨNG | B14: 7500000 | C14: 1 | D14: =B14*C14 -> 7500000 | I14: TÊN | J14: MỨC LƯƠNG | K14: HỆ SỐ | L14: TỔNG
A15: LƯƠNG THÂM NIÊN | B15: 3000000 | C15: 1 | D15: =B15*C15 -> 3000000 | I15: LƯƠNG CỨNG | J15: 7500000 | K15: 1 | L15: =J15*K15 -> 7500000
