Workbook

Sheet ĐẦU TƯ BAN ĐẦU
A1: Thu Chi từ 1/10/2025 đến ngày 30/11/2025
D2: TỔNG | E2: =SUM(E4:E38) -> 38862000
A3: Tài khoản | B3: STT | C3: Ngày | D3: Diễn giải | E3: CHI | F3: Thu- Chi | G3: Tòa | H3: Phòng
D4: lắp máy bơm áp sân thượng | E4: 1175000
D5: điều hòa và vật tư lắp tầng 6 | E5: 5355000
D6: thạch cao ngăn phòng tầng 6 | E6: 3200000
D7: 2 tủ lạnh aqua | E7: 5000000
D8: rèm G1 | E8: 4782000
D9: tủ bếp trên | E9: 12600000
D10: 1 máy giặt aqua 8kg | E10: 4150000
D11: 1 bộ giường tủ P604 | E11: 2600000

Sheet THU CHI BAN ĐẦU
A1: Thu Chi từ 1/1/2026 đến ngày 31/1/2026
D2: TỔNG | E2: =SUM(E4:E143) -> 2.6990635e+08 | F2: =SUM(F4:F175) -> 104919000 | G2: =F2-E2 -> -1.6498735e+08
A3: Tài khoản | B3: STT | C3: Ngày | D3: Diễn giải | E3: CHI | F3: Thu | G3: Thu-Chi | H3: Toà | I3: Phòng | K3: TÒA G1 | L3: Chung 10% | M3: Hằng 20% | N3: Tùng 15% | O3: Ngọc 5% | P3: Mạnh 15% | Q3: Hào 10% | R3: A điệp 5% | S3: Lâm 10% | T3: Huy anh 10%
D4: Tiền nhà tháng | E4: =132000000-4000000 -> 128000000 | K4: chía CP G1 | L4: =10%*G2 -> -16498735 | M4: =20%*G2 -> -32997470 | N4: =15%*G2 -> -24748102 | O4: =5%*G2 -> -8249367.4 | P4: =15%*G2 -> -24748102 | Q4: =10%*G2 -> -16498735 | R4: =5%*G2 -> -8249367.4 | S4: =10%*G2 -> -16498735 | T4: =10%*G2 -> -16498735 | U4: =SUM(L4:T4) -> -1.6498735e+08
D5: Tiền cọc | E5: =46000000+2000000 -> 48000000 | K5: Đã đóng | L5: 23040000 | M5: 46080000 | N5: 34560000 | O5: 11520000 | P5: 34560000 | Q5: 23040000 | R5: 11520000 | S5: 23040000 | T5: 23040000 | U5: =SUM(L5:T5) -> 230400000
D6: Phí môi giới | E6: =6200000+8200000 -> 14400000 | K6: Thực nhận | L6: =L5+L4 -> 6541265.2 | M6: =M5+M4 -> 13082530 | N6: =N5+N4 -> 9811897.8 | O6: =O5+O4 -> 3270632.6 | P6: =P5+P4 -> 9811897.8 | Q6: =Q5+Q4 -> 6541265.2 | R6: =R5+R4 -> 3270632.6 | S6: =S5+S4 -> 6541265.2 | T6: =T5+T4 -> 6541265.2 | U6: =SUM(L6:T6) -> 65412652
D7: Điện | E7: 0
D8: Nước | E8: 0
D9: mạng 6th | E9: 3000000
D10: Lương quản lý | E10: 1500000
D11: Lương quản lý tổng | E11: =(10000000/1204)*15 -> 124584.72
D12: Lương TPVH | E12: =(10000000/1204)*15+7000*15 -> 229584.72
D13: Lương phó phòng vận hành | E13: =(8000000/1204)*15+5000*15 -> 174667.77
D14: Lương NVKD | E14: =(SUM('[3]THÁNG 1'!$Y$132/1204)*15) -> 356264.38
D15: Lương vệ sinh | E15: 550000
D16: Lương kế toán | E16: =10000*15+10000+(2000000/1204)*15 -> 184916.94
D17: Lương sửa chữa | E17: =(22000000/1204)*15 -> 274086.38
D18: Lương bảo vệ | E18: 0
D19: Thuê và dv vp | E19: =('[4]THÁNG 1.26 '!$B$19/1204)*15 -> 576124.46
D20: Phí marketing | E20: =('[4]THÁNG 1.26 '!$F$10/1204)*15 -> 55118.571
D21: Lương hỗ trợ quản lý | E21: 0
D22: Công mở mới kĩ thuật | E22: 0
D23: HH 101G1 | E23: 1800000
D24: HH 201G1 | E24: 0
D25: HH 202G1 | E25: 1900000
D26: HH 203G1 | E26: 1900000
D27: HH 301G1 | E27: 1950000
D28: HH 302G1 | E28: 1900000
D29: HH 303G1 | E29: 2000000
D30: HH 304G1 | E30: 2050000
D31: HH 401G1 | E31: 1950000
D32: HH 402G1 | E32: =975000*2 -> 1950000
D33: HH 403G1 | E33: 1950000
D34: HH 404G1 | E34: 1950000
D35: HH 601G1 | E35: =3800000/2 -> 1900000
D36: HH 603G1 | E36: 1500000
D37: HH 604G1 | E37: 1750000
D38: vật tư lắp máy giặt sân thượng | E38: 356000
D39: lắp máy bơm áp sân thượng | E39: 1175000
D40: lắp át nhà vệ sinh chung tầng 6 | E40: 60000
...

Sheet HD T1.26
A1: 0 | B1: 2 | C1: 3 | D1: 1 | E1: 5 | F1: 6 | G1: 7 | H1: 8 | J1: 10 | K1: 11 | M1: 13 | N1: 14 | O1: 15 | P1: 16 | Q1: 17 | R1: 18 | S1: 19 | T1: 20 | U1: 21 | V1: 22 | W1: 23 | X1: 24 | Y1: 25 | Z1: 26 | AA1: 27 | AB1: 28 | AC1: 29 | AD1: 30 | AE1: 31 | AF1: 32 | AG1: 33 | AH1: 34 | AI1: 35 | AJ1: 36 | AK1: 37 | AL1: 38 | AM1: 39 | AN1: 40 | AO1: 41 | AP1: 42 | AQ1: 43 | AR1: 44 | AS1: 45 | AT1: 46 | AX1: 48 | BW1: 49 | BX1: 50 | BY1: 51 | BZ1: 52 | CA1: 53 | CB1: 54 | CC1: 55
A2: Mã | B2: Tòa | C2: Phòng | D2: Quản lý | E2: Kỳ TT | F2: Giá Niêm yết | G2: Giá QL | H2: Gía phòng hiện tại | I2: CỌC | J2: Ngày ở | K2: Ngày DV | L2: Nợ Cũ | M2: Thu khác | N2: Số người | O2: Điện | T2: Nước | Y2: VỆ SINH | AB2: MẠNG | AE2: THANG MÁY | AH2: XE ĐIỆN | AK2: Máy giặt | AN2: DV khác | AQ2: Tổng DV | AR2: Tổng cần đóng | AS2: Ghi Chú Hóa đơn | AT2: Tổng đã đóng | AU2: Tình trạng | AV2: CÔNG NỢ | AW2: ĐIỆN PHÁ HĐ THU ĐƯỢC | AX2: NƯỚC PHÁ HĐ THU ĐƯỢC | AY2: ĐIỆN PHÒNG TRỐNG | BD2: ĐIỆN PHÒNG HẾT HĐ | BI2: NƯỚC PHÒNG HẾT HĐ | BO2: Khách mới tháng 7 | BT2: Hoàn cọc khách hết HĐ | BW2: Điện vệ sinh chung
F3: =SUM(F5:F642) -> 60800000 | G3: =SUM(G5:G642) -> 52900000 | H3: =SUM(H5:H642) -> 43796774 | I3: =SUBTOTAL(109,I5:I642) -> 52900000 | L3: =SUM(L5:L642) -> 0 | M3: =SUM(M5:M642) -> 0 | N3: =SUM(N5:N642) -> 23 | O3: =SUM(O5:O642) -> 5 | P3: =SUM(P5:P642) -> 5 | Q3: =SUM(Q5:Q642) -> 0 | R3: =SUM(R5:R642) -> 531900 | S3: =SUM(S5:S642) -> 0 | ... AP3: =SUM(AP5:AP642) -> 2760000 | AY3: =SUM(AY5:AY641) -> 215 | AZ3: =SUM(AZ5:AZ641) -> 239 | BA3: =SUM(BA5:BA641) -> 24 | BC3: =SUM(BC5:BC641) -> 151200 | BD3: =SUM(BD5:BD641) -> 65594 | BE3: =SUM(BE5:BE641) -> 66713 | BF3: =SUM(BF5:BF641) -> 1119 | BH3: =SUM(BH5:BH641) -> 3965400 | BI3: =SUM(BI5:BI641) -> 1856 | BJ3: =SUM(BJ5:BJ641) -> 883 | BK3: =SUM(BK5:BK641) -> -973 | BL3: =SUM(BL5:BL641) -> 120000 | BM3: =SUM(BM5:BM641) -> -29400000 | BN3: =SUM(BN5:BN641) -> 210000
C4: =COUNT(C5:C642) -> 15 | O4: CS cu | P4: Cs moi | Q4: SL | R4: Đơn giá | S4: Thành tiền | T4: CS cu | U4: CS moi | V4: SL | W4: Đơn giá | X4: Thành tiền | Y4: SL | Z4: Đơn giá | AA4: Thành tiền | AB4: SL | AC4: Đơn giá | AD4: Thành tiền | AE4: SL | AF4: Đơn giá | AG4: Thành tiền | AH4: SL | AI4: Đơn giá | AJ4: Thành tiền | AK4: SL | AL4: Đơn giá | AM4: Thành tiền | AN4: SL | AO4: Đơn giá | AP4: Thành tiền | AQ4: =SUM(AQ5:AQ641) -> 7417741.9 | AR4: =SUBTOTAL(109,AR5:AR641) -> 1.0411452e+08 | AS4: =SUBTOTAL(109,AS5:AS641) -> 0 | AT4: =SUBTOTAL(109,AT5:AT641) -> 104919000 | AV4: =AT4-AR4 -> 804483.87 | AW4: =SUM(AW5:AW116) -> 0 | AX4: =SUM(AX5:AX116) -> 0 | AY4: CS CŨ | AZ4: CS MỚI | BA4: SỐ LƯỢNG | BB4: ĐƠN GIÁ | BC4: THÀNH TIỀN | BD4: CS CŨ | BE4: CS MÓI | BF4: SỐ LƯỢNG | BG4: ĐƠN GIÁ | BH4: THÀNH TIỀN | BI4: CS CŨ | BJ4: CS MỚI | BK4: SL | BL4: ĐƠN GIÁ | BN4: THÀNH TIỀN | BO4: Cọc | BP4: ND và ngày ck | BQ4: Tiền nhà | BR4: ND và ngày ck | BS4: GHI CHÚ | BT4: Khấu Hao | BU4: Vệ sinh | BV4: Sửa chữa | BW4: CS cũ | BX4: CS mới | BY4: SL | BZ4: Đơn giá | CA4: Thành tiền | CB4: số người sử dụng | CC4: số tiền mỗi người phải đóng
A5: 101G1 | B5: G1 | C5: 101 | D5: Đỗ Thanh Hương | E5: 1 | F5: 3600000 | G5: 3600000 | H5: 3600000 | I5: 3600000 | J5: 30 | K5: 30 | N5: 1 | O5: 5 | P5: 5 | Q5: =P5-O5 -> 0 | R5: 4000 | S5: =Q5*R5 -> 0 | V5: 1 | W5: 120000 | X5: =V5*W5 -> 120000 | AB5: 1 | AC5: 100000 | AD5: =AB5*AC5 -> 100000 | AE5: 1 | AF5: 60000 | AG5: =AE5*AF5 -> 60000 | AN5: 1 | AO5: 120000 | AP5: =AN5*AO5 -> 120000 | AQ5: =(SUM(S5,X5,AA5,AD5,AG5,AJ5,AM5,AP5)) -> 400000 | AR5: =AQ5+H5*E5+I5+L5+M5 -> 7600000 | AS5: kh mới 1/1 chốt giá 3tr6 | AT5: =3600000+1000000+3000000 -> 7600000 | AU5: =IF(AND(AR5>0,AT5=0),"Chưa TT",IF(AT5-AR5>0,"Thừa",IF(AND(AR5=0,AT5=0),"Trống",IF(AND(AT5>0,AR5=0),"Đóng cọc",IF(AT5-AR5<0,"Thiếu",IF(AT5-AR5=0,"Đủ",0)))))) -> Đủ | AV5: =AT5-AR5 -> 0
A6: 201G1 | B6: G1 | C6: 201 | D6: Đỗ Thanh Hương | E6: 1 | F6: 4200000 | J6: 30 | K6: 30 | Q6: =P6-O6 -> 0 | R6: 4000 | S6: =Q6*R6 -> 0 | W6: 35000 | X6: =V6*W6 -> 0 | AC6: 100000 | AD6: =AB6*AC6 -> 0 | AF6: 50000 | AG6: =AE6*AF6 -> 0 | AP6: =AN6*AO6 -> 0 | AQ6: =(SUM(S6,X6,AA6,AD6,AG6,AJ6,AM6,AP6)/30)*21 -> 0 | AR6: =AQ6+H6*E6+I6+L6+M6 -> 0 | AS6: trống | AU6: =IF(AND(AR6>0,AT6=0),"Chưa TT",IF(AT6-AR6>0,"Thừa",IF(AND(AR6=0,AT6=0),"Trống",IF(AND(AT6>0,AR6=0),"Đóng cọc",IF(AT6-AR6<0,"Thiếu",IF(AT6-AR6=0,"Đủ",0)))))) -> Trống | AV6: =AT6-AR6 -> 0 | BW6: 1935 | BX6: 1967 | BY6: =BX6-BW6 -> 32 | BZ6: 3800 | CA6: =BY6*BZ6 -> 121600 | CC6: =CA6/3 -> 40533.333
A7: 202G1 | B7: G1 | C7: 202 | D7: Đỗ Thanh Hương | E7: 1 | F7: 4000000 | G7: 3800000 | H7: 3800000 | I7: 3800000 | J7: 30 | K7: 30 | N7: 1 | Q7: =P7-O7 -> 0 | R7: 4000 | S7: =Q7*R7 -> 0 | V7: 1 | W7: 120000 | X7: =V7*W7 -> 120000 | AB7: 1 | AC7: 100000 | AD7: =AB7*AC7 -> 100000 | AE7: 1 | AF7: 60000 | AG7: =AE7*AF7 -> 60000 | AM7: =AK7*AL7 -> 0 | AN7: 1 | AO7: 120000 | AP7: =AN7*AO7 -> 120000 | AQ7: =SUM(S7,X7,AA7,AD7,AG7,AJ7,AM7,AP7) -> 400000 | AR7: =AQ7+H7*E7+I7+L7+M7 -> 8000000 | AS7: kh mới 1/1 chốt giá 3tr8 | AT7: =4200000+3800000 -> 8000000 | AU7: =IF(AND(AR7>0,AT7=0),"Chưa TT",IF(AT7-AR7>0,"Thừa",IF(AND(AR7=0,AT7=0),"Trống",IF(AND(AT7>0,AR7=0),"Đóng cọc",IF(AT7-AR7<0,"Thiếu",IF(AT7-AR7=0,"Đủ",0)))))) -> Đủ | AV7: =AT7-AR7 -> 0 | BW7: 1935 | BX7: 1967 | BY7: =BX7-BW7 -> 32 | BZ7: 3800 | CA7: =BY7*BZ7 -> 121600 | CC7: =CA7/3 -> 40533.333
A8: 203G1 | B8: G1 | C8: 203 | D8: Đỗ Thanh Hương | E8: 1 | F8: 4300000 | G8: 3800000 | H8: =(3800000/31)*13 -> 1593548.4 | I8: 3800000 | J8: 30 | K8: 30 | N8: 1 | Q8: =P8-O8 -> 0 | R8: 4000 | S8: =Q8*R8 -> 0 | V8: 1 | W8: 120000 | X8: =V8*W8 -> 120000 | AC8: 100000 | AD8: =AB8*AC8 -> 0 | AE8: 1 | AF8: 60000 | AG8: =AE8*AF8 -> 60000 | AN8: 1 | AO8: 120000 | AP8: =AN8*AO8 -> 120000 | AQ8: =(SUM(S8,X8,AA8,AD8,AG8,AJ8,AM8,AP8)/31)*13 -> 125806.45 | AR8: =AQ8+H8*E8+I8+L8+M8 -> 5519354.8 | AS8: kh mới 19/1 chốt giá 3tr8 | AT8: =3800000+1694000 -> 5494000 | AU8: =IF(AND(AR8>0,AT8=0),"Chưa TT",IF(AT8-AR8>0,"Thừa",IF(AND(AR8=0,AT8=0),"Trống",IF(AND(AT8>0,AR8=0),"Đóng cọc",IF(AT8-AR8<0,"Thiếu",IF(AT8-AR8=0,"Đủ",0)))))) -> Thiếu | AV8: =AT8-AR8 -> -25354.839 | BW8: 144 | BX8: 209 | BY8: =BX8-BW8 -> 65 | BZ8: 3800 | CA8: =BY8*BZ8 -> 247000 | CC8: =CA8/3 -> 82333.333
A9: 301G1 | B9: G1 | C9: 301 | D9: Đỗ Thanh Hương | E9: 1 | F9: 4200000 | G9: 3900000 | H9: =(3900000/31)*15 -> 1887096.8 | I9: 3900000 | J9: 30 | K9: 30 | N9: 1 | Q9: =P9-O9 -> 0 | R9: 4000 | S9: =Q9*R9 -> 0 | V9: 1 | W9: 120000 | X9: =V9*W9 -> 120000 | AB9: 1 | AC9: 100000 | AD9: =AB9*AC9 -> 100000 | AE9: 1 | AF9: 60000 | AG9: =AE9*AF9 -> 60000 | AH9: 1 | AI9: 150000 | AJ9: =AH9*AI9 -> 150000 | AN9: 1 | AO9: 120000 | AP9: =AN9*AO9 -> 120000 | AQ9: =(SUM(S9,X9,AA9,AD9,AG9,AJ9,AM9,AP9)/31)*15 -> 266129.03 | AR9: =AQ9+H9*E9+I9+L9+M9 -> 6053225.8 | AS9: kh mo 17/1 chot gia 3tr9 | AT9: 6053000 | AU9: =IF(AND(AR9>0,AT9=0),"Chưa TT",IF(AT9-AR9>0,"Thừa",IF(AND(AR9=0,AT9=0),"Trống",IF(AND(AT9>0,AR9=0),"Đóng cọc",IF(AT9-AR9<0,"Thiếu",IF(AT9-AR9=0,"Đủ",0)))))) -> Thiếu | AV9: =AT9-AR9 -> -225.80645 | BW9: 144 | BX9: 209 | BY9: =BX9-BW9 -> 65 | BZ9: 3800 | CA9: =BY9*BZ9 -> 247000 | CC9: =CA9/3 -> 82333.333
A10: 302G1 | B10: G1 | C10: 302 | D10: Đỗ Thanh Hương | E10: 1 | F10: 4000000 | G10: 3800000 | H10: 3800000 | I10: 3800000 | J10: 30 | K10: 30 | N10: 2 | Q10: =P10-O10 -> 0 | R10: 4000 | S10: =Q10*R10 -> 0 | V10: 2 | W10: 120000 | X10: =V10*W10 -> 240000 | AB10: 1 | AC10: 100000 | AD10: =AB10*AC10 -> 100000 | AE10: 2 | AF10: 60000 | AG10: =AE10*AF10 -> 120000 | AN10: 2 | AO10: 120000 | AP10: =AN10*AO10 -> 240000 | AQ10: =(SUM(S10,X10,AA10,AD10,AG10,AJ10,AM10,AP10)) -> 700000 | AR10: =AQ10+H10*E10+I10+L10+M10 -> 8300000 | AS10: kh mới 1/1 chốt giá 3tr8 | AT10: 8300000 | AU10: =IF(AND(AR10>0,AT10=0),"Chưa TT",IF(AT10-AR10>0,"Thừa",IF(AND(AR10=0,AT10=0),"Trống",IF(AND(AT10>0,AR10=0),"Đóng cọc",IF(AT10-AR10<0,"Thiếu",IF(AT10-AR10=0,"Đủ",0)))))) -> Đủ | AV10: =AT10-AR10 -> 0 | BW10: 144 | BX10: 209 | BY10: =BX10-BW10 -> 65 | BZ10: 3800 | CA10: =BY10*BZ10 -> 247000 | CC10: =CA10/3 -> 82333.333
A11: 303G1 | B11: G1 | C11: 303 | D11: Đỗ Thanh Hương | E11: 1 | F11: 4300000 | G11: 4000000 | H11: 4000000 | I11: 4000000 | J11: 30 | K11: 30 | N11: 3 | Q11: =P11-O11 -> 0 | R11: 4200 | S11: =Q11*R11 -> 0 | V11: 3 | W11: 120000 | X11: =V11*W11 -> 360000 | AA11: =Y11*Z11 -> 0 | AC11: 100000 | AD11: =AB11*AC11 -> 0 | AE11: 3 | AF11: 60000 | AG11: =AE11*AF11 -> 180000 | AN11: 3 | AO11: 120000 | AP11: =AN11*AO11 -> 360000 | AQ11: =SUM(S11,X11,AA11,AD11,AG11,AJ11,AM11,AP11) -> 900000 | AR11: =AQ11+H11*E11+I11+L11+M11 -> 8900000 | AS11: kh mới 1/1 chốt giá 4tr, 500k tiền mặt 30/12 | AT11: =2000000+500000+4400000+2000000 -> 8900000 | AU11: =IF(AND(AR11>0,AT11=0),"Chưa TT",IF(AT11-AR11>0,"Thừa",IF(AND(AR11=0,AT11=0),"Trống",IF(AND(AT11>0,AR11=0),"Đóng cọc",IF(AT11-AR11<0,"Thiếu",IF(AT11-AR11=0,"Đủ",0)))))) -> Đủ | AV11: =AT11-AR11 -> 0
A12: 304G1 | B12: G1 | C12: 304 | D12: Đỗ Thanh Hương | E12: 1 | F12: 4400000 | G12: 4100000 | H12: 4100000 | I12: 4100000 | J12: 30 | K12: 30 | N12: 2 | Q12: =P12-O12 -> 0 | R12: 4000 | S12: =Q12*R12 -> 0 | V12: 2 | W12: 120000 | X12: =V12*W12 -> 240000 | AA12: =Y12*Z12 -> 0 | AB12: 1 | AC12: 100000 | AD12: =AB12*AC12 -> 100000 | AE12: 2 | AF12: 60000 | AG12: =AE12*AF12 -> 120000 | AN12: 2 | AO12: 120000 | AP12: =AN12*AO12 -> 240000 | AQ12: =SUM(S12,X12,AA12,AD12,AG12,AJ12,AM12,AP12) -> 700000 | AR12: =AQ12+H12*E12+I12+L12+M12 -> 8900000 | AS12: kh mới 1/1 chốt giá 4tr1 | AT12: =4800000+4100000 -> 8900000 | AU12: =IF(AND(AR12>0,AT12=0),"Chưa TT",IF(AT12-AR12>0,"Thừa",IF(AND(AR12=0,AT12=0),"Trống",IF(AND(AT12>0,AR12=0),"Đóng cọc",IF(AT12-AR12<0,"Thiếu",IF(AT12-AR12=0,"Đủ",0)))))) -> Đủ | AV12: =AT12-AR12 -> 0
A13: 401G1 | B13: G1 | C13: 401 | D13: Đỗ Thanh Hương | E13: 1 | F13: 4200000 | G13: 3900000 | H13: =(3900000/31)*21 -> 2641935.5 | I13: 3900000 | J13: 30 | K13: 30 | N13: 2 | Q13: =P13-O13 -> 0 | R13: 4000 | V13: 2 | W13: 120000 | X13: =V13*W13 -> 240000 | AB13: 1 | AC13: 100000 | AD13: =AB13*AC13 -> 100000 | AE13: 2 | AF13: 60000 | AG13: =AE13*AF13 -> 120000 | AN13: 2 | AO13: 120000 | AP13: =AN13*AO13 -> 240000 | AQ13: =(SUM(S13,X13,AA13,AD13,AG13,AJ13,AM13,AP13)/31)*21 -> 474193.55 | AR13: =AQ13+H13*E13+I13+L13+M13 -> 7016129 | AS13: kh mới 11.1 chốt giá 3tr9 | AT13: =3900000+3464000 -> 7364000 | AU13: =IF(AND(AR13>0,AT13=0),"Chưa TT",IF(AT13-AR13>0,"Thừa",IF(AND(AR13=0,AT13=0),"Trống",IF(AND(AT13>0,AR13=0),"Đóng cọc",IF(AT13-AR13<0,"Thiếu",IF(AT13-AR13=0,"Đủ",0)))))) -> Thừa | AV13: =AT13-AR13 -> 347870.97
A14: 402G1 | B14: G1 | C14: 402 | D14: Đỗ Thanh Hương | E14: 1 | F14: 4000000 | G14: 3900000 | H14: 3900000 | I14: 3900000 | J14: 30 | K14: 30 | N14: 2 | Q14: =P14-O14 -> 0 | R14: 4000 | V14: 2 | W14: 120000 | X14: =V14*W14 -> 240000 | AB14: 1 | AC14: 100000 | AD14: =AB14*AC14 -> 100000 | AE14: 2 | AF14: 60000 | AG14: =AE14*AF14 -> 120000 | AH14: 1 | AI14: 400000 | AJ14: =AH14*AI14 -> 400000 | AN14: 2 | AO14: 120000 | AP14: =AN14*AO14 -> 240000 | AQ14: =(SUM(S14,X14,AA14,AD14,AG14,AJ14,AM14,AP14)) -> 1100000 | AR14: =AQ14+H14*E14+I14+L14+M14 -> 8900000 | AS14: kh mới 1/1 chốt giá 3tr9 | AT14: =5000000+900000+3000000 -> 8900000 | AU14: =IF(AND(AR14>0,AT14=0),"Chưa TT",IF(AT14-AR14>0,"Thừa",IF(AND(AR14=0,AT14=0),"Trống",IF(AND(AT14>0,AR14=0),"Đóng cọc",IF(AT14-AR14<0,"Thiếu",IF(AT14-AR14=0,"Đủ",0)))))) -> Đủ | AV14: =AT14-AR14 -> 0
A15: 403G1 | B15: G1 | C15: 403 | D15: Đỗ Thanh Hương | E15: 1 | F15: 4300000 | G15: 3900000 | H15: =(3900000/31)*13 -> 1635483.9 | I15: 3900000 | J15: 30 | K15: 30 | N15: 2 | Q15: =P15-O15 -> 0 | R15: 4000 | V15: 2 | W15: 120000 | X15: =V15*W15 -> 240000 | AB15: 1 | AC15: 100000 | AD15: =AB15*AC15 -> 100000 | AE15: 2 | AF15: 60000 | AG15: =AE15*AF15 -> 120000 | AN15: 2 | AO15: 120000 | AP15: =AN15*AO15 -> 240000 | AQ15: =((SUM(S15,X15,AA15,AD15,AG15,AJ15,AM15,AP15))/31)*13 -> 293548.39 | AR15: =AQ15+H15*E15+I15+L15+M15 -> 5829032.3 | AS15: kh moi 19/1 chot gia 3tr9 | AT15: =2000000+4212000 -> 6212000 | AU15: =IF(AND(AR15>0,AT15=0),"Chưa TT",IF(AT15-AR15>0,"Thừa",IF(AND(AR15=0,AT15=0),"Trống",IF(AND(AT15>0,AR15=0),"Đóng cọc",IF(AT15-AR15<0,"Thiếu",IF(AT15-AR15=0,"Đủ",0)))))) -> Thừa | AV15: =AT15-AR15 -> 382967.74
A16: 404G1 | B16: G1 | C16: 404 | D16: Đỗ Thanh Hương | E16: 1 | F16: 4400000 | G16: 3900000 | H16: =(3900000/31)*27 -> 3396774.2 | I16: 3900000 | J16: 30 | K16: 30 | N16: 1 | Q16: =P16-O16 -> 0 | R16: 4000 | V16: 1 | W16: 120000 | X16: =V16*W16 -> 120000 | AB16: 1 | AC16: 100000 | AD16: =AB16*AC16 -> 100000 | AE16: 1 | AF16: 60000 | AG16: =AE16*AF16 -> 60000 | AN16: 1 | AO16: 120000 | AP16: =AN16*AO16 -> 120000 | AQ16: =(SUM(S16,X16,AA16,AD16,AG16,AJ16,AM16,AP16)/31)*27 -> 348387.1 | AR16: =AQ16+H16*E16+I16+L16+M16 -> 7645161.3 | AS16: kh mới 5/1 chốt giá 3tr9 | AT16: =2900000+1000000+3845000 -> 7745000 | AU16: =IF(AND(AR16>0,AT16=0),"Chưa TT",IF(AT16-AR16>0,"Thừa",IF(AND(AR16=0,AT16=0),"Trống",IF(AND(AT16>0,AR16=0),"Đóng cọc",IF(AT16-AR16<0,"Thiếu",IF(AT16-AR16=0,"Đủ",0)))))) -> Thừa | AV16: =AT16-AR16 -> 99838.71
A17: 601G1 | B17: G1 | C17: 601 | D17: Đỗ Thanh Hương | E17: 1 | F17: 4100000 | G17: 3800000 | H17: =(3800000/31)*24 -> 2941935.5 | I17: 3800000 | J17: 30 | K17: 30 | N17: 1 | Q17: =P17-O17 -> 0 | R17: 4000 | V17: 1 | W17: 120000 | X17: =V17*W17 -> 120000 | AB17: 1 | AC17: 100000 | AD17: =AB17*AC17 -> 100000 | AE17: 1 | AF17: 60000 | AG17: =AE17*AF17 -> 60000 | AN17: 1 | AO17: 120000 | AP17: =AN17*AO17 -> 120000 | AQ17: =((SUM(S17,X17,AA17,AD17,AG17,AJ17,AM17,AP17))/31)*24 -> 309677.42 | AR17: =AQ17+H17*E17+I17+L17+M17 -> 7051612.9 | AS17: kh mới 8.1 chốt giá3tr8 | AT17: =2000000+5051000 -> 7051000 | AU17: =IF(AND(AR17>0,AT17=0),"Chưa TT",IF(AT17-AR17>0,"Thừa",IF(AND(AR17=0,AT17=0),"Trống",IF(AND(AT17>0,AR17=0),"Đóng cọc",IF(AT17-AR17<0,"Thiếu",IF(AT17-AR17=0,"Đủ",0)))))) -> Thiếu | AV17: =AT17-AR17 -> -612.90323
A18: 603G1 | B18: G1 | C18: 603 | D18: Đỗ Thanh Hương | E18: 1 | F18: 3300000 | G18: 3000000 | H18: 3000000 | I18: 3000000 | J18: 30 | K18: 30 | N18: 2 | Q18: =P18-O18 -> 0 | R18: 4000 | V18: 2 | W18: 120000 | X18: =V18*W18 -> 240000 | AA18: =Y18*Z18 -> 0 | AB18: 1 | AC18: 100000 | AD18: =AB18*AC18 -> 100000 | AE18: 2 | AF18: 60000 | AG18: =AE18*AF18 -> 120000 | AN18: 2 | AO18: 120000 | AP18: =AN18*AO18 -> 240000 | AQ18: =SUM(S18,X18,AA18,AD18,AG18,AJ18,AM18,AP18) -> 700000 | AR18: =AQ18+H18*E18+I18+L18+M18 -> 6700000 | AS18: kh mới 1/1 chốt giá 3tr | AT18: =2500000+3700000+500000 -> 6700000 | AU18: =IF(AND(AR18>0,AT18=0),"Chưa TT",IF(AT18-AR18>0,"Thừa",IF(AND(AR18=0,AT18=0),"Trống",IF(AND(AT18>0,AR18=0),"Đóng cọc",IF(AT18-AR18<0,"Thiếu",IF(AT18-AR18=0,"Đủ",0)))))) -> Đủ | AV18: =AT18-AR18 -> 0
A19: 604G1 | B19: G1 | C19: 604 | D19: Đỗ Thanh Hương | E19: 1 | F19: 3500000 | G19: 3500000 | H19: 3500000 | I19: 3500000 | J19: 30 | K19: 30 | N19: 2 | Q19: =P19-O19 -> 0 | R19: 4000 | V19: 2 | W19: 120000 | X19: =V19*W19 -> 240000 | AB19: 1 | AC19: 100000 | AD19: =AB19*AC19 -> 100000 | AE19: 2 | AF19: 60000 | AG19: =AE19*AF19 -> 120000 | AN19: 2 | AO19: 120000 | AP19: =AN19*AO19 -> 240000 | AQ19: =(SUM(S19,X19,AA19,AD19,AG19,AJ19,AM19,AP19)) -> 700000 | AR19: =AQ19+H19*E19+I19+L19+M19 -> 7700000 | AS19: kh mới 1/1 chốt giá 3tr5 | AT19: =5700000+2000000 -> 7700000 | AU19: =IF(AND(AR19>0,AT19=0),"Chưa TT",IF(AT19-AR19>0,"Thừa",IF(AND(AR19=0,AT19=0),"Trống",IF(AND(AT19>0,AR19=0),"Đóng cọc",IF(AT19-AR19<0,"Thiếu",IF(AT19-AR19=0,"Đủ",0)))))) -> Đủ | AV19: =AT19-AR19 -> 0
D20: Đỗ Thanh Hương | E20: 1 | J20: 30 | K20: 30 | R20: 4000 | W20: 35000 | X20: =V20*W20 -> 0 | AC20: 100000 | AD20: =AB20*AC20 -> 0 | AF20: 50000 | AG20: =AE20*AF20 -> 0 | AP20: =AN20*AO20 -> 0 | AQ20: =(SUM(S20,X20,AA20,AD20,AG20,AJ20,AM20,AP20)/31)*31 -> 0 | AR20: =AQ20+H20*E20+I20+L20+M20 -> 0 | AU20: =IF(AND(AR20>0,AT20=0),"Chưa TT",IF(AT20-AR20>0,"Thừa",IF(AND(AR20=0,AT20=0),"Trống",IF(AND(AT20>0,AR20=0),"Đóng cọc",IF(AT20-AR20<0,"Thiếu",IF(AT20-AR20=0,"Đủ",0)))))) -> Trống | AV20: =AT20-AR20 -> 0
D21: Đỗ Thanh Hương | E21: 1 | J21: 30 | K21: 30 | R21: 4000 | W21: 35000 | X21: =V21*W21 -> 0 | AC21: 100000 | AD21: =AB21*AC21 -> 0 | AF21: 50000 | AG21: =AE21*AF21 -> 0 | AP21: =AN21*AO21 -> 0 | AQ21: =(SUM(S21,X21,AA21,AD21,AG21,AJ21,AM21,AP21)/31)*31 -> 0 | AR21: =AQ21+H21*E21+I21+L21+M21 -> 0 | AU21: =IF(AND(AR21>0,AT21=0),"Chưa TT",IF(AT21-AR21>0,"Thừa",IF(AND(AR21=0,AT21=0),"Trống",IF(AND(AT21>0,AR21=0),"Đóng cọc",IF(AT21-AR21<0,"Thiếu",IF(AT21-AR21=0,"Đủ",0)))))) -> Trống | AV21: =AT21-AR21 -> 0
D22: Đỗ Thanh Hương | E22: 1 | J22: 30 | K22: 30 | R22: 4000 | W22: 35000 | X22: =V22*W22 -> 0 | AC22: 100000 | AD22: =AB22*AC22 -> 0 | AF22: 50000 | AG22: =AE22*AF22 -> 0 | AP22: =AN22*AO22 -> 0 | AQ22: =(SUM(S22,X22,AA22,AD22,AG22,AJ22,AM22,AP22)) -> 0 | AR22: =AQ22+H22*E22+I22+L22+M22 -> 0 | AU22: =IF(AND(AR22>0,AT22=0),"Chưa TT",IF(AT22-AR22>0,"Thừa",IF(AND(AR22=0,AT22=0),"Trống",IF(AND(AT22>0,AR22=0),"Đóng cọc",IF(AT22-AR22<0,"Thiếu",IF(AT22-AR22=0,"Đủ",0)))))) -> Trống | AV22: =AT22-AR22 -> 0
D23: Đỗ Thanh Hương | E23: 1 | J23: 30 | K23: 30 | Q23: =P23-O23 -> 0 | R23: 4000 | S23: =Q23*R23 -> 0 | W23: 35000 | X23: =V23*W23 -> 0 | Z23: 30000 | AA23: =Y23*Z23 -> 0 | AC23: 100000 | AD23: =AC23*AB23 -> 0 | AF23: 50000 | AG23: =AE23*AF23 -> 0 | AP23: =AN23*AO23 -> 0 | AQ23: =((SUM(S23,X23,AA23,AD23,AG23,AJ23,AM23,AP23)/30)*21) -> 0 | AR23: =AQ23+H23*E23+I23+L23+M23 -> 0 | AU23: =IF(AND(AR23>0,AT23=0),"Chưa TT",IF(AT23-AR23>0,"Thừa",IF(AND(AR23=0,AT23=0),"Trống",IF(AND(AT23>0,AR23=0),"Đóng cọc",IF(AT23-AR23<0,"Thiếu",IF(AT23-AR23=0,"Đủ",0)))))) -> Trống | AV23: =AT23-AR23 -> 0
D24: Đỗ Thanh Hương | E24: 1 | J24: 30 | K24: 30 | Q24: =P24-O24 -> 0 | R24: 4000 | S24: =Q24*R24 -> 0 | W24: 35000 | X24: =V24*W24 -> 0 | Z24: 30000 | AA24: =Y24*Z24 -> 0 | AC24: 100000 | AD24: =AC24*AB24 -> 0 | AF24: 50000 | AG24: =AE24*AF24 -> 0 | AP24: =AN24*AO24 -> 0 | AQ24: =(SUM(S24,X24,AA24,AD24,AG24,AJ24,AM24,AP24)/30)*19 -> 0 | AR24: =AQ24+H24*E24+I24+L24+M24 -> 0 | AU24: =IF(AND(AR24>0,AT24=0),"Chưa TT",IF(AT24-AR24>0,"Thừa",IF(AND(AR24=0,AT24=0),"Trống",IF(AND(AT24>0,AR24=0),"Đóng cọc",IF(AT24-AR24<0,"Thiếu",IF(AT24-AR24=0,"Đủ",0)))))) -> Trống | AV24: =AT24-AR24 -> 0
D25: Đỗ Thanh Hương | E25: 1 | J25: 30 | K25: 30 | Q25: =P25-O25 -> 0 | R25: 4000 | S25: =Q25*R25 -> 0 | W25: 35000 | X25: =V25*W25 -> 0 | Z25: 30000 | AA25: =Y25*Z25 -> 0 | AC25: 100000 | AD25: =AC25*AB25 -> 0 | AF25: 50000 | AG25: =AE25*AF25 -> 0 | AP25: =AN25*AO25 -> 0 | AQ25: =(SUM(S25,X25,AA25,AD25,AG25,AJ25,AM25,AP25)/30)*26 -> 0 | AR25: =AQ25+H25*E25+I25+L25+M25 -> 0 | AU25: =IF(AND(AR25>0,AT25=0),"Chưa TT",IF(AT25-AR25>0,"Thừa",IF(AND(AR25=0,AT25=0),"Trống",IF(AND(AT25>0,AR25=0),"Đóng cọc",IF(AT25-AR25<0,"Thiếu",IF(AT25-AR25=0,"Đủ",0)))))) -> Trống | AV25: =AT25-AR25 -> 0
D26: Đỗ Thanh Hương | E26: 1 | J26: 30 | K26: 30 | Q26: =P26-O26 -> 0 | R26: 4000 | S26: =Q26*R26 -> 0 | W26: 35000 | X26: =V26*W26 -> 0 | Z26: 30000 | AA26: =Y26*Z26 -> 0 | AC26: 100000 | AD26: =AC26*AB26 -> 0 | AF26: 50000 | AG26: =AE26*AF26 -> 0 | AQ26: =(SUM(S26,X26,AA26,AD26,AG26,AJ26,AM26,AP26)) -> 0 | AR26: =AQ26+H26*E26+I26+L26+M26 -> 0 | AU26: =IF(AND(AR26>0,AT26=0),"Chưa TT",IF(AT26-AR26>0,"Thừa",IF(AND(AR26=0,AT26=0),"Trống",IF(AND(AT26>0,AR26=0),"Đóng cọc",IF(AT26-AR26<0,"Thiếu",IF(AT26-AR26=0,"Đủ",0)))))) -> Trống | AV26: =AT26-AR26 -> 0
D27: Đỗ Thanh Hương | E27: 1 | J27: 30 | K27: 30 | Q27: =P27-O27 -> 0 | R27: 4000 | S27: =Q27*R27 -> 0 | X27: =V27*W27 -> 0 | Z27: 30000 | AA27: =Y27*Z27 -> 0 | AC27: 100000 | AD27: =AC27*AB27 -> 0 | AF27: 50000 | AG27: =AE27*AF27 -> 0 | AQ27: =(SUM(S27,X27,AA27,AD27,AG27,AJ27,AM27,AP27)/31)*14 -> 0 | AR27: =AQ27+H27*E27+I27+L27+M27 -> 0 | AU27: =IF(AND(AR27>0,AT27=0),"Chưa TT",IF(AT27-AR27>0,"Thừa",IF(AND(AR27=0,AT27=0),"Trống",IF(AND(AT27>0,AR27=0),"Đóng cọc",IF(AT27-AR27<0,"Thiếu",IF(AT27-AR27=0,"Đủ",0)))))) -> Trống | AV27: =AT27-AR27 -> 0
D28: Đỗ Thanh Hương | E28: 1 | J28: 30 | K28: 30 | Q28: =P28-O28 -> 0 | R28: 4000 | S28: =Q28*R28 -> 0 | X28: =V28*W28 -> 0 | Z28: 30000 | AA28: =Y28*Z28 -> 0 | AC28: 100000 | AD28: =AC28*AB28 -> 0 | AP28: =AN28*AO28 -> 0 | AQ28: =(SUM(S28,X28,AA28,AD28,AG28,AJ28,AM28,AP28)/31)*16 -> 0 | AR28: =AQ28+H28*E28+I28+L28+M28 -> 0 | AU28: =IF(AND(AR28>0,AT28=0),"Chưa TT",IF(AT28-AR28>0,"Thừa",IF(AND(AR28=0,AT28=0),"Trống",IF(AND(AT28>0,AR28=0),"Đóng cọc",IF(AT28-AR28<0,"Thiếu",IF(AT28-AR28=0,"Đủ",0)))))) -> Trống | AV28: =AT28-AR28 -> 0
D29: Đỗ Thanh Hương | E29: 1 | J29: 30 | K29: 30 | Q29: =P29-O29 -> 0 | R29: 4000 | S29: =Q29*R29 -> 0 | X29: =V29*W29 -> 0 | Z29: 30000 | AA29: =Y29*Z29 -> 0 | AC29: 100000 | AD29: =AC29*AB29 -> 0 | AQ29: =SUM(S29,X29,AA29,AD29,AG29,AJ29,AM29,AP29) -> 0 | AR29: =AQ29+H29*E29+I29+L29+M29 -> 0 | AU29: =IF(AND(AR29>0,AT29=0),"Chưa TT",IF(AT29-AR29>0,"Thừa",IF(AND(AR29=0,AT29=0),"Trống",IF(AND(AT29>0,AR29=0),"Đóng cọc",IF(AT29-AR29<0,"Thiếu",IF(AT29-AR29=0,"Đủ",0)))))) -> Trống | AV29: =AT29-AR29 -> 0
D30: Đỗ Thanh Hương | E30: 1 | J30: 30 | K30: 30 | Q30: =P30-O30 -> 0 | R30: 4000 | S30: =Q30*R30 -> 0 | X30: =V30*W30 -> 0 | Z30: 30000 | AA30: =Y30*Z30 -> 0 | AC30: 100000 | AD30: =AC30*AB30 -> 0 | AP30: =AN30*AO30 -> 0 | AQ30: =(SUM(S30,X30,AA30,AD30,AG30,AJ30,AM30,AP30)/31)*15 -> 0 | AR30: =AQ30+H30*E30+I30+L30+M30 -> 0 | AU30: =IF(AND(AR30>0,AT30=0),"Chưa TT",IF(AT30-AR30>0,"Thừa",IF(AND(AR30=0,AT30=0),"Trống",IF(AND(AT30>0,AR30=0),"Đóng cọc",IF(AT30-AR30<0,"Thiếu",IF(AT30-AR30=0,"Đủ",0)))))) -> Trống | AV30: =AT30-AR30 -> 0 | BF30: =BE30-BD30 -> 0 | BG30: 3800 | BH30: =BF30*BG30 -> 0
D31: Đỗ Thanh Hương | E31: 1 | J31: 30 | K31: 30 | Q31: =P31-O31 -> 0 | R31: 3800 | S31: =Q31*R31 -> 0 | X31: =V31*W31 -> 0 | Z31: 30000 | AA31: =Y31*Z31 -> 0 | AC31: 100000 | AD31: =AC31*AB31 -> 0 | AP31: =AN31*AO31 -> 0 | AQ31: =(SUM(S31,X31,AA31,AD31,AG31,AJ31,AM31,AP31)/31)*21 -> 0 | AR31: =AQ31+H31*E31+I31+L31+M31 -> 0 | AU31: =IF(AND(AR31>0,AT31=0),"Chưa TT",IF(AT31-AR31>0,"Thừa",IF(AND(AR31=0,AT31=0),"Trống",IF(AND(AT31>0,AR31=0),"Đóng cọc",IF(AT31-AR31<0,"Thiếu",IF(AT31-AR31=0,"Đủ",0)))))) -> Trống | AV31: =AT31-AR31 -> 0
J32: 30 | K32: 30 | Q32: =P32-O32 -> 0 | R32: 3800 | S32: =Q32*R32 -> 0 | X32: =V32*W32 -> 0 | Z32: 30000 | AA32: =Y32*Z32 -> 0 | AC32: 100000 | AD32: =AC32*AB32 -> 0 | AQ32: =SUM(S32,X32,AA32,AD32,AG32,AJ32,AM32,AP32) -> 0 | AR32: =AQ32+H32*E32+I32+L32+M32 -> 0 | AU32: =IF(AND(AR32>0,AT32=0),"Chưa TT",IF(AT32-AR32>0,"Thừa",IF(AND(AR32=0,AT32=0),"Trống",IF(AND(AT32>0,AR32=0),"Đóng cọc",IF(AT32-AR32<0,"Thiếu",IF(AT32-AR32=0,"Đủ",0)))))) -> Trống | AV32: =AT32-AR32 -> 0 | BF32: =BE32-BD32 -> 0 | BG32: 3800 | BH32: =BF32*BG32 -> 0
J33: 30 | K33: 30 | Q33: =P33-O33 -> 0 | R33: 3800 | S33: =Q33*R33 -> 0 | X33: =V33*W33 -> 0 | Z33: 30000 | AA33: =Y33*Z33 -> 0 | AC33: 100000 | AD33: =AC33*AB33 -> 0 | AQ33: =SUM(S33,X33,AA33,AD33,AG33,AJ33,AM33,AP33) -> 0 | AR33: =AQ33+H33*E33+I33+L33+M33 -> 0 | AU33: =IF(AND(AR33>0,AT33=0),"Chưa TT",IF(AT33-AR33>0,"Thừa",IF(AND(AR33=0,AT33=0),"Trống",IF(AND(AT33>0,AR33=0),"Đóng cọc",IF(AT33-AR33<0,"Thiếu",IF(AT33-AR33=0,"Đủ",0)))))) -> Trống | AV33: =AT33-AR33 -> 0
J34: 30 | K34: 30 | Q34: =P34-O34 -> 0 | R34: 3800 | S34: =Q34*R34 -> 0 | X34: =V34*W34 -> 0 | Z34: 30000 | AA34: =Y34*Z34 -> 0 | AC34: 100000 | AD34: =AC34*AB34 -> 0 | AQ34: =SUM(S34,X34,AA34,AD34,AG34,AJ34,AM34,AP34) -> 0 | AR34: =AQ34+H34*E34+I34+L34+M34 -> 0 | AU34: =IF(AND(AR34>0,AT34=0),"Chưa TT",IF(AT34-AR34>0,"Thừa",IF(AND(AR34=0,AT34=0),"Trống",IF(AND(AT34>0,AR34=0),"Đóng cọc",IF(AT34-AR34<0,"Thiếu",IF(AT34-AR34=0,"Đủ",0)))))) -> Trống | AV34: =AT34-AR34 -> 0
J35: 30 | K35: 30 | Q35: =P35-O35 -> 0 | R35: 3800 | S35: =Q35*R35 -> 0 | X35: =V35*W35 -> 0 | Z35: 30000 | AA35: =Y35*Z35 -> 0 | AC35: 100000 | AD35: =AC35*AB35 -> 0 | AF35: 50000 | AG35: =AE35*AF35 -> 0 | AQ35: =SUM(S35,X35,AA35,AD35,AG35,AJ35,AM35,AP35) -> 0 | AR35: =AQ35+H35*E35+I35+L35+M35 -> 0 | AU35: =IF(AND(AR35>0,AT35=0),"Chưa TT",IF(AT35-AR35>0,"Thừa",IF(AND(AR35=0,AT35=0),"Trống",IF(AND(AT35>0,AR35=0),"Đóng cọc",IF(AT35-AR35<0,"Thiếu",IF(AT35-AR35=0,"Đủ",0)))))) -> Trống | AV35: =AT35-AR35 -> 0
J36: 30 | K36: 30 | Q36: =P36-O36 -> 0 | R36: 3800 | S36: =Q36*R36 -> 0 | X36: =V36*W36 -> 0 | Z36: 30000 | AA36: =Y36*Z36 -> 0 | AC36: 100000 | AD36: =AC36*AB36 -> 0 | AF36: 50000 | AG36: =AE36*AF36 -> 0 | AP36: =AN36*AO36 -> 0 | AQ36: =(SUM(S36,X36,AA36,AD36,AG36,AJ36,AM36,AP36)/31)*15 -> 0 | AR36: =AQ36+H36*E36+I36+L36+M36 -> 0 | AU36: =IF(AND(AR36>0,AT36=0),"Chưa TT",IF(AT36-AR36>0,"Thừa",IF(AND(AR36=0,AT36=0),"Trống",IF(AND(AT36>0,AR36=0),"Đóng cọc",IF(AT36-AR36<0,"Thiếu",IF(AT36-AR36=0,"Đủ",0)))))) -> Trống | AV36: =AT36-AR36 -> 0
J37: 30 | K37: 30 | Q37: =P37-O37 -> 0 | R37: 3800 | S37: =Q37*R37 -> 0 | X37: =V37*W37 -> 0 | Z37: 30000 | AA37: =Y37*Z37 -> 0 | AC37: 100000 | AD37: =AC37*AB37 -> 0 | AF37: 50000 | AG37: =AE37*AF37 -> 0 | AQ37: =SUM(S37,X37,AA37,AD37,AG37,AJ37,AM37,AP37) -> 0 | AR37: =AQ37+H37*E37+I37+L37+M37 -> 0 | AU37: =IF(AND(AR37>0,AT37=0),"Chưa TT",IF(AT37-AR37>0,"Thừa",IF(AND(AR37=0,AT37=0),"Trống",IF(AND(AT37>0,AR37=0),"Đóng cọc",IF(AT37-AR37<0,"Thiếu",IF(AT37-AR37=0,"Đủ",0)))))) -> Trống | AV37: =AT37-AR37 -> 0
J38: 30 | K38: 30 | Q38: =P38-O38 -> 0 | R38: 3800 | S38: =Q38*R38 -> 0 | X38: =V38*W38 -> 0 | Z38: 30000 | AA38: =Y38*Z38 -> 0 | AC38: 100000 | AD38: =AC38*AB38 -> 0 | AQ38: =SUM(S38,X38,AA38,AD38,AG38,AJ38,AM38,AP38) -> 0 | AR38: =AQ38+H38*E38+I38+L38+M38 -> 0 | AU38: =IF(AND(AR38>0,AT38=0),"Chưa TT",IF(AT38-AR38>0,"Thừa",IF(AND(AR38=0,AT38=0),"Trống",IF(AND(AT38>0,AR38=0),"Đóng cọc",IF(AT38-AR38<0,"Thiếu",IF(AT38-AR38=0,"Đủ",0)))))) -> Trống | AV38: =AT38-AR38 -> 0
J39: 30 | K39: 30 | Q39: =P39-O39 -> 0 | R39: 3800 | S39: =Q39*R39 -> 0 | X39: =V39*W39 -> 0 | Z39: 30000 | AA39: =Y39*Z39 -> 0 | AC39: 100000 | AD39: =AC39*AB39 -> 0 | AQ39: =SUM(S39,X39,AA39,AD39,AG39,AJ39,AM39,AP39) -> 0 | AR39: =AQ39+H39*E39+I39+L39+M39 -> 0 | AU39: =IF(AND(AR39>0,AT39=0),"Chưa TT",IF(AT39-AR39>0,"Thừa",IF(AND(AR39=0,AT39=0),"Trống",IF(AND(AT39>0,AR39=0),"Đóng cọc",IF(AT39-AR39<0,"Thiếu",IF(AT39-AR39=0,"Đủ",0)))))) -> Trống | AV39: =AT39-AR39 -> 0
J40: 30 | K40: 30 | Q40: =P40-O40 -> 0 | R40: 3800 | S40: =Q40*R40 -> 0 | X40: =V40*W40 -> 0 | Z40: 30000 | AA40: =Y40*Z40 -> 0 | AC40: 100000 | AD40: =AC40*AB40 -> 0 | AQ40: =SUM(S40,X40,AA40,AD40,AG40,AJ40,AM40,AP40) -> 0 | AR40: =AQ40+H40*E40+I40+L40+M40 -> 0 | AU40: =IF(AND(AR40>0,AT40=0),"Chưa TT",IF(AT40-AR40>0,"Thừa",IF(AND(AR40=0,AT40=0),"Trống",IF(AND(AT40>0,AR40=0),"Đóng cọc",IF(AT40-AR40<0,"Thiếu",IF(AT40-AR40=0,"Đủ",0)))))) -> Trống | AV40: =AT40-AR40 -> 0
...

Sheet BÁO CÁO THÁNG 2
A1: BÁO CÁO KINH DOANH G1 THÁNG 2/2026 | F1: BẢNG CHIA CỔ PHẦN G1
A2: Tổng doanh thu tháng 2 | C2: ='HĐ T2.26'!AX2 -> 71112000 | D2: DT TRÊN HĐ - HOÀN CỌC | G2: Tỷ lệ % | H2: Vốn | I2: LN Gộp | J2: LN ròng | K2: LNR/GV | L2: CP/LNG | M2: Tổng nhận
A3: Cọc phòng mới | C3: 4100000 | D3: P201 | F3: CHUNG | G3: 10 | H3: =G3*($C$22/100) -> 4800000 | I3: =G3*$C$71/100 -> 1627802.2 | J3: =G3*$C$72/100 -> 516357.65 | M3: =H3+J3 -> 5316357.7
F4: HẰNG | G4: 20 | H4: =G4*($C$22/100) -> 9600000 | I4: =G4*$C$71/100 -> 3255604.4 | J4: =G4*$C$72/100 -> 1032715.3 | M4: =H4+J4 -> 10632715
F5: TÙNG | G5: 15 | H5: =G5*($C$22/100) -> 7200000 | I5: =G5*$C$71/100 -> 2441703.3 | J5: =G5*$C$72/100 -> 774536.48 | M5: =H5+J5 -> 7974536.5
A6: Cọc khách bỏ không ở | F6: NGỌC | G6: 5 | H6: =G6*($C$22/100) -> 2400000 | I6: =G6*$C$71/100 -> 813901.1 | J6: =G6*$C$72/100 -> 258178.83 | M6: =H6+J6 -> 2658178.8
A7: Hoàn Cọc | F7: MẠNH | G7: 15 | H7: =G7*($C$22/100) -> 7200000 | I7: =G7*$C$71/100 -> 2441703.3 | J7: =G7*$C$72/100 -> 774536.48 | M7: =H7+J7 -> 7974536.5
F8: HÀO | G8: 10 | H8: =G8*($C$22/100) -> 4800000 | I8: =G8*$C$71/100 -> 1627802.2 | J8: =G8*$C$72/100 -> 516357.65 | M8: =H8+J8 -> 5316357.7 | N8: =H13+J13 -> 53163577
B9: Tổng số phòng phá hđ | C9: 1 | F9: A ĐIỆP | G9: 5 | H9: =G9*($C$22/100) -> 2400000 | I9: =G9*$C$71/100 -> 813901.1 | J9: =G9*$C$72/100 -> 258178.83 | M9: =H9+J9 -> 2658178.8 | N9: =H13+J13 -> 53163577
B10: Tổng số phòng mới | C10: 1 | F10: LÂM | G10: 10 | H10: =G10*($C$22/100) -> 4800000 | I10: =G10*$C$71/100 -> 1627802.2 | J10: =G10*$C$72/100 -> 516357.65 | M10: =H10+J10 -> 5316357.7
B11: Tổng số phòng trống | C11: 1 | F11: HUY ANH | G11: 10 | H11: =G11*($C$22/100) -> 4800000 | I11: =G11*$C$71/100 -> 1627802.2 | J11: =G11*$C$72/100 -> 516357.65 | M11: =H11+J11 -> 5316357.7
B12: Doanh thu tiền phòng | C12: ='HĐ T2.26'!I2-'HĐ T2.26'!I5 -> 54000000
B13: Doanh thu điện | C13: ='HĐ T2.26'!T2+'HĐ T2.26'!AT2 -> 4172000 | G13: =SUM(G3:G12) -> 100 | H13: =SUM(H3:H12) -> 48000000 | I13: =SUM(I3:I12) -> 16278022 | J13: =SUM(J3:J12) -> 5163576.5 | K13: =C76*100 -> 9.4167462 | L13: =C78 -> 4.0513782 | M13: =SUM(M3:M12) -> 53163577
B14: Doanh thu nước | C14: ='HĐ T2.26'!Y2-'HĐ T2.26'!Y5 -> 2880000
B15: Doanh thu phí vệ sinh | C15: =('HĐ T2.26'!AQ2-'HĐ T2.26'!AQ5)/2 -> 1440000
B16: Doanh thu mạng | C16: ='HĐ T2.26'!AE2-'HĐ T2.26'!AE5 -> 1000000
B17: Doanh thu xe điện | C17: ='HĐ T2.26'!AK2 -> 700000
B18: Doanh thu phí thang máy | C18: ='HĐ T2.26'!AH2-'HĐ T2.26'!AH5 -> 1380000
B19: Doanh thu máy giặt | C19: =('HĐ T2.26'!AQ2-'HĐ T2.26'!AQ5)/2 -> 1440000
B20: Doanh thu tổng dịch vụ nhà | C20: =SUM(C13:C19) -> 13012000
A22: Tiền thuê nhà 1 tháng | B22: Tiền thuê nhà | C22: 48000000
A23: Mua sắm thêm thiết bị
A28: Gía gốc dịch vụ | B28: Điện | C28: 6533978
B29: Nước | C29: 0
B30: Mạng | C30: 0
B31: Phí thu rác | C31: 300000
B32: Phí môi trường
B33: Phí bảo trì thang máy
A34: Gía vốn( GV) | C34: =SUM(C22:C33) -> 54833978
A35: Chi phí vận hành | B35: Lương quản lý | C35: ='[5]THÁNG 2 '!$W$116 -> 1379432.1
B36: Lương quản lý tổng | C36: =(12000000/1205)*15 -> 149377.59
B37: Lương trưởng phòng vận hành | C37: =(10000000/1205)*15+7000*15 -> 229481.33
B38: Lương phó phòng vận hành | C38: =(8000000/1205)*15+5000*15 -> 174585.06
B39: Lương nhân viên nguồn | C39: =(6000000/1205)*15 -> 74688.797
B40: Lương NVKD partime | C40: =(SUM('[5]THÁNG 2 '!$Y$126/1205)*15) -> 291573.57
B41: Lương vệ sinh | C41: 550000
B42: Lương kế toán | C42: =150000+10000+(2000000/1205)*15 -> 184896.27
B43: Lương sửa chữa | C43: =(22000000/1205)*15 -> 273858.92
B44: Lương bảo vệ
B45: Thuê và dv VP | C45: =('[6]THÁNG 2.26 '!$B$19/1205)*15 -> 2268821.6
...

Sheet HĐ T2.26
A1: Mã | B1: Tòa | C1: Phòng | D1: Quản lý | E1: Kỳ TT | F1: Cọc khách cũ | G1: Giá Niêm yết | H1: Giá QL | I1: Gía phòng hiện tại | J1: Cọc | K1: Ngày ở | L1: Ngày DV | M1: Nợ cũ | N1: Thu khác | O1: Số người | P1: Điện | U1: Nước | Z1: VỆ SINH | AC1: MẠNG | AF1: THANG MÁY | AI1: XE ĐIỆN | AL1: Máy giặt | AO1: DV khác | AR1: Điện chung | AU1: Tổng DV | AV1: Tổng cần đóng | AW1: Ghi Chú Hóa đơn | AX1: Tổng đã đóng link | AY1: Tình trạng | AZ1: Công nợ KH | BA1: GHI CHÚ
G2: =SUM(G4:G19) -> 61200000 | H2: =SUM(H4:H19) -> 57600000 | I2: =SUM(I4:I19) -> 57600000 | J2: =SUM(J4:J19) -> 4100000 | K2: =SUM(K4:K19) -> 480 | L2: =SUM(L4:L19) -> 480 | M2: =SUM(M4:M19) -> 0 | N2: =SUM(N4:N19) -> 0 | ... AX2: =SUM(AX4:AX19) -> 71112000
M3: (thiếu ghi âm) | N3: + | P3: CS cu | Q3: Cs moi | R3: SL | S3: Đơn giá | T3: Thành tiền | U3: CS cu | V3: CS moi | W3: SL | X3: Đơn giá | Y3: Thành tiền | Z3: SL | AA3: Đơn giá | AB3: Thành tiền | AC3: SL | AD3: Đơn giá | AE3: Thành tiền | AF3: SL | AG3: Đơn giá | AH3: Thành tiền | AI3: SL | AJ3: Đơn giá | AK3: Thành tiền | AL3: SL | AM3: Đơn giá | AN3: Thành tiền | AO3: SL | AP3: Đơn giá | AQ3: Thành tiền | AR3: SL | AS3: Đơn giá | AT3: Thành tiền | AY3: =AX3-AV3 -> 0
A4: 000G1 | B4: G1 | C4: 0 | D4: ĐỖ THANH HƯƠNG | E4: 1 | K4: 30 | L4: 30 | R4: 640 | S4: 3500 | T4: =R4*S4 -> 2240000 | AU4: =(SUM(T4,Y4,AB4,AE4,AH4,AK4,AN4,AQ4,AT4)) -> 2240000 | AV4: =AU4+I4*E4+J4+M4+N4 -> 2240000 | AW4: thanh toán chủ nhà 300k tiền nước | AX4: =1940000+300000 -> 2240000 | AY4: =IF(AND(AV4>0,AX4=0),"Chưa TT",IF(AX4-AV4>0,"Thừa",IF(AND(AV4=0,AX4=0),"Trống",IF(AND(AX4>0,AV4=0),"Đóng cọc",IF(AX4-AV4<0,"Thiếu",IF(AX4-AV4=0,"Đủ",0)))))) -> Đủ | AZ4: =AX4-AV4 -> 0
A5: 101G1 | B5: G1 | C5: 101 | D5: ĐỖ THANH HƯƠNG | E5: 1 | F5: 3600000 | G5: 3600000 | H5: 3600000 | I5: 3600000 | K5: 30 | L5: 30 | O5: 1 | P5: 5 | Q5: 38 | R5: =Q5-P5 -> 33 | S5: 4000 | T5: =R5*S5 -> 132000 | W5: 1 | X5: 120000 | Y5: =W5*X5 -> 120000 | AC5: 1 | AD5: 100000 | AE5: =AC5*AD5 -> 100000 | AF5: 1 | AG5: 60000 | AH5: =AF5*AG5 -> 60000 | AO5: 1 | AP5: 120000 | AQ5: =AO5*AP5 -> 120000 | AT5: =AR5*AS5 -> 0 | AU5: =(SUM(T5,Y5,AB5,AE5,AH5,AK5,AN5,AQ5,AT5)) -> 532000 | AV5: =AU5+I5*E5+J5+M5+N5 -> 4132000 | AW5: kh phá hd | AX5: 132000 | AY5: =IF(AND(AV5>0,AX5=0),"Chưa TT",IF(AX5-AV5>0,"Thừa",IF(AND(AV5=0,AX5=0),"Trống",IF(AND(AX5>0,AV5=0),"Đóng cọc",IF(AX5-AV5<0,"Thiếu",IF(AX5-AV5=0,"Đủ",0)))))) -> Thiếu | AZ5: =AX5-AV5 -> -4000000
A6: 201G1 | B6: G1 | C6: 201 | D6: ĐỖ THANH HƯƠNG | E6: 1 | F6: 4100000 | G6: 4200000 | H6: 4100000 | I6: 4100000 | J6: 4100000 | K6: 30 | L6: 30 | O6: 2 | P6: 33 | Q6: 33 | R6: =Q6-P6 -> 0 | S6: 4000 | T6: =R6*S6 -> 0 | W6: 2 | X6: 120000 | Y6: =W6*X6 -> 240000 | AC6: 1 | AD6: 100000 | AE6: =AC6*AD6 -> 100000 | AF6: 2 | AG6: 60000 | AH6: =AF6*AG6 -> 120000 | AI6: 1 | AJ6: 150000 | AK6: =AI6*AJ6 -> 150000 | AO6: 2 | AP6: 120000 | AQ6: =AO6*AP6 -> 240000 | AT6: =AR6*AS6 -> 0 | AU6: =(SUM(T6,Y6,AB6,AE6,AH6,AK6,AN6,AQ6,AT6)) -> 850000 | AV6: =AU6+I6*E6+J6+M6+N6 -> 9050000 | AW6: Kh mới 1/2 chốt giá 4tr1 | AX6: =4100000+4950000 -> 9050000 | AY6: =IF(AND(AV6>0,AX6=0),"Chưa TT",IF(AX6-AV6>0,"Thừa",IF(AND(AV6=0,AX6=0),"Trống",IF(AND(AX6>0,AV6=0),"Đóng cọc",IF(AX6-AV6<0,"Thiếu",IF(AX6-AV6=0,"Đủ",0)))))) -> Đủ | AZ6: =AX6-AV6 -> 0 | CA6: 1935 | CB6: 1967 | CC6: =CB6-CA6 -> 32 | CD6: 3800 | CE6: =CC6*CD6 -> 121600 | CG6: =CE6/3 -> 40533.333
A7: 202G1 | B7: G1 | C7: 202 | D7: ĐỖ THANH HƯƠNG | E7: 1 | F7: 3800000 | G7: 4000000 | H7: 3800000 | I7: 3800000 | K7: 30 | L7: 30 | O7: 1 | P7: 5 | Q7: 60 | R7: =Q7-P7 -> 55 | S7: 4000 | T7: =R7*S7 -> 220000 | W7: 1 | X7: 120000 | Y7: =W7*X7 -> 120000 | AC7: 1 | AD7: 100000 | AE7: =AC7*AD7 -> 100000 | AF7: 1 | AG7: 60000 | AH7: =AF7*AG7 -> 60000 | AN7: =AL7*AM7 -> 0 | AO7: 1 | AP7: 120000 | AQ7: =AO7*AP7 -> 120000 | AT7: =AR7*AS7 -> 0 | AU7: =(SUM(T7,Y7,AB7,AE7,AH7,AK7,AN7,AQ7,AT7)) -> 620000 | AV7: =AU7+I7*E7+J7+M7+N7 -> 4420000 | AX7: 4420000 | AY7: =IF(AND(AV7>0,AX7=0),"Chưa TT",IF(AX7-AV7>0,"Thừa",IF(AND(AV7=0,AX7=0),"Trống",IF(AND(AX7>0,AV7=0),"Đóng cọc",IF(AX7-AV7<0,"Thiếu",IF(AX7-AV7=0,"Đủ",0)))))) -> Đủ | AZ7: =AX7-AV7 -> 0 | CA7: 1935 | CB7: 1967 | CC7: =CB7-CA7 -> 32 | CD7: 3800 | CE7: =CC7*CD7 -> 121600 | CG7: =CE7/3 -> 40533.333
A8: 203G1 | B8: G1 | C8: 203 | D8: ĐỖ THANH HƯƠNG | E8: 1 | F8: 3800000 | G8: 4300000 | H8: 3800000 | I8: 3800000 | K8: 30 | L8: 30 | O8: 1 | P8: 5 | Q8: 5 | R8: =Q8-P8 -> 0 | S8: 4000 | T8: =R8*S8 -> 0 | W8: 1 | X8: 120000 | Y8: =W8*X8 -> 120000 | AD8: 100000 | AE8: =AC8*AD8 -> 0 | AG8: 60000 | AH8: =AF8*AG8 -> 0 | AO8: 1 | AP8: 120000 | AQ8: =AO8*AP8 -> 120000 | AT8: =AR8*AS8 -> 0 | AU8: =(SUM(T8,Y8,AB8,AE8,AH8,AK8,AN8,AQ8,AT8)) -> 240000 | AV8: =AU8+I8*E8+J8+M8+N8 -> 4040000 | AX8: 4040000 | AY8: =IF(AND(AV8>0,AX8=0),"Chưa TT",IF(AX8-AV8>0,"Thừa",IF(AND(AV8=0,AX8=0),"Trống",IF(AND(AX8>0,AV8=0),"Đóng cọc",IF(AX8-AV8<0,"Thiếu",IF(AX8-AV8=0,"Đủ",0)))))) -> Đủ | AZ8: =AX8-AV8 -> 0 | CA8: 144 | CB8: 209 | CC8: =CB8-CA8 -> 65 | CD8: 3800 | CE8: =CC8*CD8 -> 247000 | CG8: =CE8/3 -> 82333.333
A9: 301G1 | B9: G1 | C9: 301 | D9: ĐỖ THANH HƯƠNG | E9: 1 | F9: 3900000 | G9: 4200000 | H9: 3900000 | I9: 3900000 | K9: 30 | L9: 30 | O9: 1 | P9: 4 | Q9: 4 | R9: =Q9-P9 -> 0 | S9: 4000 | T9: =R9*S9 -> 0 | W9: 1 | X9: 120000 | Y9: =W9*X9 -> 120000 | AC9: 1 | AD9: 100000 | AE9: =AC9*AD9 -> 100000 | AF9: 1 | AG9: 60000 | AH9: =AF9*AG9 -> 60000 | AI9: 1 | AJ9: 150000 | AK9: =AI9*AJ9 -> 150000 | AO9: 1 | AP9: 120000 | AQ9: =AO9*AP9 -> 120000 | AT9: =AR9*AS9 -> 0 | AU9: =(SUM(T9,Y9,AB9,AE9,AH9,AK9,AN9,AQ9,AT9)) -> 550000 | AV9: =AU9+I9*E9+J9+M9+N9 -> 4450000 | AX9: 4450000 | AY9: =IF(AND(AV9>0,AX9=0),"Chưa TT",IF(AX9-AV9>0,"Thừa",IF(AND(AV9=0,AX9=0),"Trống",IF(AND(AX9>0,AV9=0),"Đóng cọc",IF(AX9-AV9<0,"Thiếu",IF(AX9-AV9=0,"Đủ",0)))))) -> Đủ | AZ9: =AX9-AV9 -> 0 | CA9: 144 | CB9: 209 | CC9: =CB9-CA9 -> 65 | CD9: 3800 | CE9: =CC9*CD9 -> 247000 | CG9: =CE9/3 -> 82333.333
A10: 302G1 | B10: G1 | C10: 302 | D10: ĐỖ THANH HƯƠNG | E10: 1 | F10: 3800000 | G10: 4000000 | H10: 3800000 | I10: 3800000 | K10: 30 | L10: 30 | O10: 2 | P10: 6 | Q10: 53 | R10: =Q10-P10 -> 47 | S10: 4000 | T10: =R10*S10 -> 188000 | W10: 2 | X10: 120000 | Y10: =W10*X10 -> 240000 | AC10: 1 | AD10: 100000 | AE10: =AC10*AD10 -> 100000 | AF10: 2 | AG10: 60000 | AH10: =AF10*AG10 -> 120000 | AO10: 2 | AP10: 120000 | AQ10: =AO10*AP10 -> 240000 | AT10: =AR10*AS10 -> 0 | AU10: =(SUM(T10,Y10,AB10,AE10,AH10,AK10,AN10,AQ10,AT10)) -> 888000 | AV10: =AU10+I10*E10+J10+M10+N10 -> 4688000 | AX10: 4688000 | AY10: =IF(AND(AV10>0,AX10=0),"Chưa TT",IF(AX10-AV10>0,"Thừa",IF(AND(AV10=0,AX10=0),"Trống",IF(AND(AX10>0,AV10=0),"Đóng cọc",IF(AX10-AV10<0,"Thiếu",IF(AX10-AV10=0,"Đủ",0)))))) -> Đủ | AZ10: =AX10-AV10 -> 0 | CA10: 144 | CB10: 209 | CC10: =CB10-CA10 -> 65 | CD10: 3800 | CE10: =CC10*CD10 -> 247000 | CG10: =CE10/3 -> 82333.333
A11: 303G1 | B11: G1 | C11: 303 | D11: ĐỖ THANH HƯƠNG | E11: 1 | F11: 4000000 | G11: 4300000 | H11: 4000000 | I11: 4000000 | K11: 30 | L11: 30 | O11: 3 | P11: 3 | Q11: 128 | R11: =Q11-P11 -> 125 | S11: 4000 | T11: =R11*S11 -> 500000 | W11: 3 | X11: 120000 | Y11: =W11*X11 -> 360000 | AB11: =Z11*AA11 -> 0 | AD11: 100000 | AE11: =AC11*AD11 -> 0 | AF11: 3 | AG11: 60000 | AH11: =AF11*AG11 -> 180000 | AO11: 3 | AP11: 120000 | AQ11: =AO11*AP11 -> 360000 | AT11: =AR11*AS11 -> 0 | AU11: =(SUM(T11,Y11,AB11,AE11,AH11,AK11,AN11,AQ11,AT11)) -> 1400000 | AV11: =AU11+I11*E11+J11+M11+N11 -> 5400000 | AX11: 5400000 | AY11: =IF(AND(AV11>0,AX11=0),"Chưa TT",IF(AX11-AV11>0,"Thừa",IF(AND(AV11=0,AX11=0),"Trống",IF(AND(AX11>0,AV11=0),"Đóng cọc",IF(AX11-AV11<0,"Thiếu",IF(AX11-AV11=0,"Đủ",0)))))) -> Đủ | AZ11: =AX11-AV11 -> 0
A12: 304G1 | B12: G1 | C12: 304 | D12: ĐỖ THANH HƯƠNG | E12: 1 | F12: 4100000 | G12: 4400000 | H12: 4100000 | I12: 4100000 | K12: 30 | L12: 30 | O12: 2 | P12: 2 | Q12: 48 | R12: =Q12-P12 -> 46 | S12: 4000 | T12: =R12*S12 -> 184000 | W12: 2 | X12: 120000 | Y12: =W12*X12 -> 240000 | AB12: =Z12*AA12 -> 0 | AC12: 1 | AD12: 100000 | AE12: =AC12*AD12 -> 100000 | AF12: 2 | AG12: 60000 | AH12: =AF12*AG12 -> 120000 | AO12: 2 | AP12: 120000 | AQ12: =AO12*AP12 -> 240000 | AT12: =AR12*AS12 -> 0 | AU12: =(SUM(T12,Y12,AB12,AE12,AH12,AK12,AN12,AQ12,AT12)) -> 884000 | AV12: =AU12+I12*E12+J12+M12+N12 -> 4984000 | AX12: 4984000 | AY12: =IF(AND(AV12>0,AX12=0),"Chưa TT",IF(AX12-AV12>0,"Thừa",IF(AND(AV12=0,AX12=0),"Trống",IF(AND(AX12>0,AV12=0),"Đóng cọc",IF(AX12-AV12<0,"Thiếu",IF(AX12-AV12=0,"Đủ",0)))))) -> Đủ | AZ12: =AX12-AV12 -> 0
A13: 401G1 | B13: G1 | C13: 401 | D13: ĐỖ THANH HƯƠNG | E13: 1 | F13: 4100000 | G13: =4200000+200000 -> 4400000 | H13: 4100000 | I13: 4100000 | K13: 30 | L13: 30 | O13: 2 | P13: 27 | Q13: 44 | R13: =Q13-P13 -> 17 | S13: 4000 | T13: =R13*S13 -> 68000 | W13: 2 | X13: 120000 | Y13: =W13*X13 -> 240000 | AC13: 1 | AD13: 100000 | AE13: =AC13*AD13 -> 100000 | AF13: 2 | AG13: 60000 | AH13: =AF13*AG13 -> 120000 | AO13: 2 | AP13: 120000 | AQ13: =AO13*AP13 -> 240000 | AT13: =AR13*AS13 -> 0 | AU13: =(SUM(T13,Y13,AB13,AE13,AH13,AK13,AN13,AQ13,AT13)) -> 768000 | AV13: =AU13+I13*E13+J13+M13+N13 -> 4868000 | AX13: =1868000+3000000 -> 4868000 | AY13: =IF(AND(AV13>0,AX13=0),"Chưa TT",IF(AX13-AV13>0,"Thừa",IF(AND(AV13=0,AX13=0),"Trống",IF(AND(AX13>0,AV13=0),"Đóng cọc",IF(AX13-AV13<0,"Thiếu",IF(AX13-AV13=0,"Đủ",0)))))) -> Đủ | AZ13: =AX13-AV13 -> 0
A14: 402G1 | B14: G1 | C14: 402 | D14: ĐỖ THANH HƯƠNG | E14: 1 | F14: 3900000 | G14: 4000000 | H14: 3900000 | I14: 3900000 | K14: 30 | L14: 30 | O14: 2 | P14: 6 | Q14: 29 | R14: =Q14-P14 -> 23 | S14: 4000 | T14: =R14*S14 -> 92000 | W14: 2 | X14: 120000 | Y14: =W14*X14 -> 240000 | AC14: 1 | AD14: 100000 | AE14: =AC14*AD14 -> 100000 | AF14: 2 | AG14: 60000 | AH14: =AF14*AG14 -> 120000 | AI14: 1 | AJ14: 400000 | AK14: =AI14*AJ14 -> 400000 | AO14: 2 | AP14: 120000 | AQ14: =AO14*AP14 -> 240000 | AT14: =AR14*AS14 -> 0 | AU14: =(SUM(T14,Y14,AB14,AE14,AH14,AK14,AN14,AQ14,AT14)) -> 1192000 | AV14: =AU14+I14*E14+J14+M14+N14 -> 5092000 | AX14: =1000000+4092000 -> 5092000 | AY14: =IF(AND(AV14>0,AX14=0),"Chưa TT",IF(AX14-AV14>0,"Thừa",IF(AND(AV14=0,AX14=0),"Trống",IF(AND(AX14>0,AV14=0),"Đóng cọc",IF(AX14-AV14<0,"Thiếu",IF(AX14-AV14=0,"Đủ",0)))))) -> Đủ | AZ14: =AX14-AV14 -> 0
A15: 403G1 | B15: G1 | C15: 403 | D15: ĐỖ THANH HƯƠNG | E15: 1 | F15: 4200000 | G15: =4300000+200000 -> 4500000 | H15: 4200000 | I15: 4200000 | K15: 30 | L15: 30 | O15: 2 | P15: 12 | Q15: 12 | R15: =Q15-P15 -> 0 | S15: 4000 | T15: =R15*S15 -> 0 | W15: 2 | X15: 120000 | Y15: =W15*X15 -> 240000 | AD15: 100000 | AE15: =AC15*AD15 -> 0 | AF15: 2 | AG15: 60000 | AH15: =AF15*AG15 -> 120000 | AO15: 2 | AP15: 120000 | AQ15: =AO15*AP15 -> 240000 | AT15: =AR15*AS15 -> 0 | AU15: =(SUM(T15,Y15,AB15,AE15,AH15,AK15,AN15,AQ15,AT15)) -> 600000 | AV15: =AU15+I15*E15+J15+M15+N15 -> 4800000 | AX15: 4800000 | AY15: =IF(AND(AV15>0,AX15=0),"Chưa TT",IF(AX15-AV15>0,"Thừa",IF(AND(AV15=0,AX15=0),"Trống",IF(AND(AX15>0,AV15=0),"Đóng cọc",IF(AX15-AV15<0,"Thiếu",IF(AX15-AV15=0,"Đủ",0)))))) -> Đủ | AZ15: =AX15-AV15 -> 0
A16: 404G1 | B16: G1 | C16: 404 | D16: ĐỖ THANH HƯƠNG | E16: 1 | F16: 4000000 | G16: 4400000 | H16: 4000000 | I16: 4000000 | K16: 30 | L16: 30 | O16: 1 | P16: 5 | Q16: 53 | R16: =Q16-P16 -> 48 | S16: 4000 | T16: =R16*S16 -> 192000 | W16: 1 | X16: 120000 | Y16: =W16*X16 -> 120000 | AD16: 100000 | AE16: =AC16*AD16 -> 0 | AF16: 1 | AG16: 60000 | AH16: =AF16*AG16 -> 60000 | AO16: 1 | AP16: 120000 | AQ16: =AO16*AP16 -> 120000 | AT16: =AR16*AS16 -> 0 | AU16: =(SUM(T16,Y16,AB16,AE16,AH16,AK16,AN16,AQ16,AT16)) -> 492000 | AV16: =AU16+I16*E16+J16+M16+N16 -> 4492000 | AX16: 4492000 | AY16: =IF(AND(AV16>0,AX16=0),"Chưa TT",IF(AX16-AV16>0,"Thừa",IF(AND(AV16=0,AX16=0),"Trống",IF(AND(AX16>0,AV16=0),"Đóng cọc",IF(AX16-AV16<0,"Thiếu",IF(AX16-AV16=0,"Đủ",0)))))) -> Đủ | AZ16: =AX16-AV16 -> 0
A17: 601G1 | B17: G1 | C17: 601 | D17: ĐỖ THANH HƯƠNG | E17: 1 | F17: 3800000 | G17: 4100000 | H17: 3800000 | I17: 3800000 | K17: 30 | L17: 30 | O17: 1 | P17: 1 | Q17: 15 | R17: =Q17-P17 -> 14 | S17: 4000 | T17: =R17*S17 -> 56000 | W17: 1 | X17: 120000 | Y17: =W17*X17 -> 120000 | AC17: 1 | AD17: 100000 | AE17: =AC17*AD17 -> 100000 | AF17: 1 | AG17: 60000 | AH17: =AF17*AG17 -> 60000 | AO17: 1 | AP17: 120000 | AQ17: =AO17*AP17 -> 120000 | AT17: =AR17*AS17 -> 0 | AU17: =(SUM(T17,Y17,AB17,AE17,AH17,AK17,AN17,AQ17,AT17)) -> 456000 | AV17: =AU17+I17*E17+J17+M17+N17 -> 4256000 | AX17: 4256000 | AY17: =IF(AND(AV17>0,AX17=0),"Chưa TT",IF(AX17-AV17>0,"Thừa",IF(AND(AV17=0,AX17=0),"Trống",IF(AND(AX17>0,AV17=0),"Đóng cọc",IF(AX17-AV17<0,"Thiếu",IF(AX17-AV17=0,"Đủ",0)))))) -> Đủ | AZ17: =AX17-AV17 -> 0
A18: 603G1 | B18: G1 | C18: 603 | D18: ĐỖ THANH HƯƠNG | E18: 1 | F18: 3000000 | G18: 3300000 | H18: 3000000 | I18: 3000000 | K18: 30 | L18: 30 | O18: 2 | P18: 3 | Q18: 33 | R18: =Q18-P18 -> 30 | S18: 4000 | T18: =R18*S18 -> 120000 | W18: 2 | X18: 120000 | Y18: =W18*X18 -> 240000 | AB18: =Z18*AA18 -> 0 | AC18: 1 | AD18: 100000 | AE18: =AC18*AD18 -> 100000 | AF18: 2 | AG18: 60000 | AH18: =AF18*AG18 -> 120000 | AO18: 2 | AP18: 120000 | AQ18: =AO18*AP18 -> 240000 | AR18: =(37-3)/2 -> 17 | AS18: 4000 | AT18: =AR18*AS18 -> 68000 | AU18: =(SUM(T18,Y18,AB18,AE18,AH18,AK18,AN18,AQ18,AT18)) -> 888000 | AV18: =AU18+I18*E18+J18+M18+N18 -> 3888000 | AX18: 3888000 | AY18: =IF(AND(AV18>0,AX18=0),"Chưa TT",IF(AX18-AV18>0,"Thừa",IF(AND(AV18=0,AX18=0),"Trống",IF(AND(AX18>0,AV18=0),"Đóng cọc",IF(AX18-AV18<0,"Thiếu",IF(AX18-AV18=0,"Đủ",0)))))) -> Đủ | AZ18: =AX18-AV18 -> 0
A19: 604G1 | B19: G1 | C19: 604 | D19: ĐỖ THANH HƯƠNG | E19: 1 | F19: 3500000 | G19: 3500000 | H19: 3500000 | I19: 3500000 | K19: 30 | L19: 30 | O19: 2 | P19: 1 | Q19: 12 | R19: =Q19-P19 -> 11 | S19: 4000 | T19: =R19*S19 -> 44000 | W19: 2 | X19: 120000 | Y19: =W19*X19 -> 240000 | AC19: 1 | AD19: 100000 | AE19: =AC19*AD19 -> 100000 | AF19: 2 | AG19: 60000 | AH19: =AF19*AG19 -> 120000 | AO19: 2 | AP19: 120000 | AQ19: =AO19*AP19 -> 240000 | AR19: =(37-3)/2 -> 17 | AS19: 4000 | AT19: =AR19*AS19 -> 68000 | AU19: =(SUM(T19,Y19,AB19,AE19,AH19,AK19,AN19,AQ19,AT19)) -> 812000 | AV19: =AU19+I19*E19+J19+M19+N19 -> 4312000 | AX19: 4312000 | AY19: =IF(AND(AV19>0,AX19=0),"Chưa TT",IF(AX19-AV19>0,"Thừa",IF(AND(AV19=0,AX19=0),"Trống",IF(AND(AX19>0,AV19=0),"Đóng cọc",IF(AX19-AV19<0,"Thiếu",IF(AX19-AV19=0,"Đủ",0)))))) -> Đủ | AZ19: =AX19-AV19 -> 0

Sheet BÁO CÁO THÁNG 3
A1: BÁO CÁO KINH DOANH G1 THÁNG 3/2026 | F1: BẢNG CHIA CỔ PHẦN G1
A2: Tổng doanh thu tháng 3 | C2: ='HĐ T3.26 '!AX2 -> 74940000 | D2: DT TRÊN HĐ - HOÀN CỌC | G2: Tỷ lệ % | H2: Vốn | I2: LN Gộp | J2: LN ròng | K2: LNR/GV | L2: CP/LNG | M2: Tổng nhận
A3: Cọc phòng mới | C3: 3500000 | D3: P101 | F3: CHUNG | G3: 10 | H3: =G3*($C$22/100) -> 4800000 | I3: =G3*$C$71/100 -> 2071885.7 | J3: =G3*$C$72/100 -> 1445326 | M3: =H3+J3 -> 6245326
F4: HẰNG | G4: 20 | H4: =G4*($C$22/100) -> 9600000 | I4: =G4*$C$71/100 -> 4143771.4 | J4: =G4*$C$72/100 -> 2890652 | M4: =H4+J4 -> 12490652
F5: TÙNG | G5: 15 | H5: =G5*($C$22/100) -> 7200000 | I5: =G5*$C$71/100 -> 3107828.5 | J5: =G5*$C$72/100 -> 2167989 | M5: =H5+J5 -> 9367989
A6: Cọc khách bỏ không ở | F6: NGỌC | G6: 5 | H6: =G6*($C$22/100) -> 2400000 | I6: =G6*$C$71/100 -> 1035942.8 | J6: =G6*$C$72/100 -> 722662.99 | M6: =H6+J6 -> 3122663
A7: Hoàn Cọc | F7: MẠNH | G7: 15 | H7: =G7*($C$22/100) -> 7200000 | I7: =G7*$C$71/100 -> 3107828.5 | J7: =G7*$C$72/100 -> 2167989 | M7: =H7+J7 -> 9367989
F8: HÀO | G8: 10 | H8: =G8*($C$22/100) -> 4800000 | I8: =G8*$C$71/100 -> 2071885.7 | J8: =G8*$C$72/100 -> 1445326 | M8: =H8+J8 -> 6245326 | N8: =H13+J13 -> 62453260
B9: Tổng số phòng phá hđ | C9: 0 | F9: A ĐIỆP | G9: 5 | H9: =G9*($C$22/100) -> 2400000 | I9: =G9*$C$71/100 -> 1035942.8 | J9: =G9*$C$72/100 -> 722662.99 | M9: =H9+J9 -> 3122663 | N9: =H13+J13 -> 62453260
B10: Tổng số phòng mới | C10: 0 | F10: LÂM | G10: 10 | H10: =G10*($C$22/100) -> 4800000 | I10: =G10*$C$71/100 -> 2071885.7 | J10: =G10*$C$72/100 -> 1445326 | M10: =H10+J10 -> 6245326
B11: Tổng số phòng trống | C11: 0 | F11: HUY ANH | G11: 10 | H11: =G11*($C$22/100) -> 4800000 | I11: =G11*$C$71/100 -> 2071885.7 | J11: =G11*$C$72/100 -> 1445326 | M11: =H11+J11 -> 6245326
B12: Doanh thu tiền phòng | C12: ='HĐ T3.26 '!I2 -> 57500000
B13: Doanh thu điện | C13: ='HĐ T3.26 '!T2+'HĐ T3.26 '!AT2 -> 4100000 | G13: =SUM(G3:G12) -> 100 | H13: =SUM(H3:H12) -> 48000000 | I13: =SUM(I3:I12) -> 20718857 | J13: =SUM(J3:J12) -> 14453260 | K13: =C76*100 -> 26.656133 | L13: =C78 -> 2.9194053 | M13: =SUM(M3:M12) -> 62453260
B14: Doanh thu nước | C14: ='HĐ T3.26 '!Y2 -> 3240000
B15: Doanh thu phí vệ sinh | C15: ='HĐ T3.26 '!AQ2/2 -> 1620000
B16: Doanh thu mạng | C16: ='HĐ T3.26 '!AE2 -> 1100000
B17: Doanh thu xe điện | C17: ='HĐ T3.26 '!AK2 -> 700000
B18: Doanh thu phí thang máy | C18: ='HĐ T3.26 '!AH2 -> 1560000
B19: Doanh thu máy giặt | C19: ='HĐ T3.26 '!AQ2/2 -> 1620000
B20: Doanh thu tổng dịch vụ nhà | C20: =SUM(C13:C19) -> 13940000
A22: Tiền thuê nhà 1 tháng | B22: Tiền thuê nhà | C22: 48000000
A23: Mua sắm thêm thiết bị
A28: Gía gốc dịch vụ | B28: Điện | C28: 5921143
B29: Nước | C29: 0
B30: Mạng | C30: 0
B31: Phí thu rác | C31: 300000
B32: Phí môi trường
B33: Phí bảo trì thang máy
A34: Gía vốn( GV) | C34: =SUM(C22:C33) -> 54221143
A35: Chi phí vận hành | B35: Lương quản lý | C35: ='[7]THÁNG 3'!$W$117 -> 1604489.8
B36: Lương quản lý tổng | C36: =(12000000/1282)*15 -> 140405.62
B37: Lương trưởng phòng vận hành | C37: =(10000000/1282)*15+7000*15 -> 222004.68
B38: Lương phó phòng vận hành | C38: =(8000000/1282)*15+5000*15 -> 168603.74
B39: Lương nhân viên nguồn | C39: =(6000000/1282)*15 -> 70202.808
B40: Lương NVKD partime | C40: =(SUM('[7]THÁNG 3'!$Y$125/1282)*15) -> 403261.13
B41: Lương vệ sinh | C41: 550000
B42: Lương kế toán | C42: =150000+10000+(2000000/1282)*15 -> 183400.94
B43: Lương sửa chữa | C43: =(22000000/1282)*15 -> 257410.3
B44: Lương bảo vệ
B45: Thuê và dv VP | C45: =('[8]THÁNG 3.26 '!$B$19/1282)*15 -> 536407.82
...

Sheet HĐ T3.26 
A1: Mã | B1: Tòa | C1: Phòng | D1: Quản lý | E1: Kỳ TT | F1: Cọc khách cũ | G1: Giá Niêm yết | H1: Giá QL | I1: Gía phòng hiện tại | J1: Cọc | K1: Ngày ở | L1: Ngày DV | M1: Nợ cũ | N1: Thu khác | O1: Số người | P1: Điện | U1: Nước | Z1: VỆ SINH | AC1: MẠNG | AF1: THANG MÁY | AI1: XE ĐIỆN | AL1: Máy giặt | AO1: DV khác | AR1: Điện chung | AU1: Tổng DV | AV1: Tổng cần đóng | AW1: Ghi Chú Hóa đơn | AX1: Tổng đã đóng link | AY1: Tình trạng | AZ1: Công nợ KH | BA1: GHI CHÚ
G2: =SUM(G4:G19) -> 61200000 | H2: =SUM(H4:H19) -> 57500000 | I2: =SUM(I4:I19) -> 57500000 | J2: =SUM(J4:J19) -> 3500000 | K2: =SUM(K4:K19) -> 480 | L2: =SUM(L4:L19) -> 480 | M2: =SUM(M4:M19) -> 0 | N2: =SUM(N4:N19) -> 0 | ... AX2: =SUM(AX4:AX19) -> 74940000
M3: (thiếu ghi âm) | N3: + | P3: CS cu | Q3: Cs moi | R3: SL | S3: Đơn giá | T3: Thành tiền | U3: CS cu | V3: CS moi | W3: SL | X3: Đơn giá | Y3: Thành tiền | Z3: SL | AA3: Đơn giá | AB3: Thành tiền | AC3: SL | AD3: Đơn giá | AE3: Thành tiền | AF3: SL | AG3: Đơn giá | AH3: Thành tiền | AI3: SL | AJ3: Đơn giá | AK3: Thành tiền | AL3: SL | AM3: Đơn giá | AN3: Thành tiền | AO3: SL | AP3: Đơn giá | AQ3: Thành tiền | AR3: SL | AS3: Đơn giá | AT3: Thành tiền | AY3: =AX3-AV3 -> 0
A4: 000G1 | B4: G1 | C4: 0 | D4: ĐỖ THANH HƯƠNG | E4: 1 | K4: 30 | L4: 30 | S4: 3500 | T4: =R4*S4 -> 0 | AU4: =(SUM(T4,Y4,AB4,AE4,AH4,AK4,AN4,AQ4,AT4)) -> 0 | AV4: =AU4+I4*E4+J4+M4+N4 -> 0 | AY4: =IF(AND(AV4>0,AX4=0),"Chưa TT",IF(AX4-AV4>0,"Thừa",IF(AND(AV4=0,AX4=0),"Trống",IF(AND(AX4>0,AV4=0),"Đóng cọc",IF(AX4-AV4<0,"Thiếu",IF(AX4-AV4=0,"Đủ",0)))))) -> Trống | AZ4: =AX4-AV4 -> 0
A5: 101G1 | B5: G1 | C5: 101 | D5: ĐỖ THANH HƯƠNG | E5: 1 | F5: 3500000 | G5: 3600000 | H5: 3500000 | I5: 3500000 | J5: 3500000 | K5: 30 | L5: 30 | O5: 1 | P5: 116 | Q5: 116 | R5: =Q5-P5 -> 0 | S5: 4000 | T5: =R5*S5 -> 0 | W5: 1 | X5: 120000 | Y5: =W5*X5 -> 120000 | AC5: 1 | AD5: 100000 | AE5: =AC5*AD5 -> 100000 | AF5: 1 | AG5: 60000 | AH5: =AF5*AG5 -> 60000 | AO5: 1 | AP5: 120000 | AQ5: =AO5*AP5 -> 120000 | AT5: =AR5*AS5 -> 0 | AU5: =(SUM(T5,Y5,AB5,AE5,AH5,AK5,AN5,AQ5,AT5)) -> 400000 | AV5: =AU5+I5*E5+J5+M5+N5 -> 7400000 | AW5: kh mới 1/3 chốt giá 3tr5 | AX5: =3500000+3900000 -> 7400000 | AY5: =IF(AND(AV5>0,AX5=0),"Chưa TT",IF(AX5-AV5>0,"Thừa",IF(AND(AV5=0,AX5=0),"Trống",IF(AND(AX5>0,AV5=0),"Đóng cọc",IF(AX5-AV5<0,"Thiếu",IF(AX5-AV5=0,"Đủ",0)))))) -> Đủ | AZ5: =AX5-AV5 -> 0
A6: 201G1 | B6: G1 | C6: 201 | D6: ĐỖ THANH HƯƠNG | E6: 1 | F6: 4100000 | G6: 4200000 | H6: 4100000 | I6: 4100000 | K6: 30 | L6: 30 | O6: 2 | P6: 33 | Q6: 43 | R6: =Q6-P6 -> 10 | S6: 4000 | T6: =R6*S6 -> 40000 | W6: 2 | X6: 120000 | Y6: =W6*X6 -> 240000 | AC6: 1 | AD6: 100000 | AE6: =AC6*AD6 -> 100000 | AF6: 2 | AG6: 60000 | AH6: =AF6*AG6 -> 120000 | AI6: 1 | AJ6: 150000 | AK6: =AI6*AJ6 -> 150000 | AO6: 2 | AP6: 120000 | AQ6: =AO6*AP6 -> 240000 | AT6: =AR6*AS6 -> 0 | AU6: =(SUM(T6,Y6,AB6,AE6,AH6,AK6,AN6,AQ6,AT6)) -> 890000 | AV6: =AU6+I6*E6+J6+M6+N6 -> 4990000 | AX6: 4990000 | AY6: =IF(AND(AV6>0,AX6=0),"Chưa TT",IF(AX6-AV6>0,"Thừa",IF(AND(AV6=0,AX6=0),"Trống",IF(AND(AX6>0,AV6=0),"Đóng cọc",IF(AX6-AV6<0,"Thiếu",IF(AX6-AV6=0,"Đủ",0)))))) -> Đủ | AZ6: =AX6-AV6 -> 0 | CA6: 1935 | CB6: 1967 | CC6: =CB6-CA6 -> 32 | CD6: 3800 | CE6: =CC6*CD6 -> 121600 | CG6: =CE6/3 -> 40533.333
A7: 202G1 | B7: G1 | C7: 202 | D7: ĐỖ THANH HƯƠNG | E7: 1 | F7: 3800000 | G7: 4000000 | H7: 3800000 | I7: 3800000 | K7: 30 | L7: 30 | O7: 2 | P7: 60 | Q7: 174 | R7: =Q7-P7 -> 114 | S7: 4000 | T7: =R7*S7 -> 456000 | W7: 2 | X7: 120000 | Y7: =W7*X7 -> 240000 | AC7: 1 | AD7: 100000 | AE7: =AC7*AD7 -> 100000 | AF7: 2 | AG7: 60000 | AH7: =AF7*AG7 -> 120000 | AN7: =AL7*AM7 -> 0 | AO7: 2 | AP7: 120000 | AQ7: =AO7*AP7 -> 240000 | AT7: =AR7*AS7 -> 0 | AU7: =(SUM(T7,Y7,AB7,AE7,AH7,AK7,AN7,AQ7,AT7)) -> 1156000 | AV7: =AU7+I7*E7+J7+M7+N7 -> 4956000 | AX7: 4956000 | AY7: =IF(AND(AV7>0,AX7=0),"Chưa TT",IF(AX7-AV7>0,"Thừa",IF(AND(AV7=0,AX7=0),"Trống",IF(AND(AX7>0,AV7=0),"Đóng cọc",IF(AX7-AV7<0,"Thiếu",IF(AX7-AV7=0,"Đủ",0)))))) -> Đủ | AZ7: =AX7-AV7 -> 0 | CA7: 1935 | CB7: 1967 | CC7: =CB7-CA7 -> 32 | CD7: 3800 | CE7: =CC7*CD7 -> 121600 | CG7: =CE7/3 -> 40533.333
A8: 203G1 | B8: G1 | C8: 203 | D8: ĐỖ THANH HƯƠNG | E8: 1 | F8: 3800000 | G8: 4300000 | H8: 3800000 | I8: 3800000 | K8: 30 | L8: 30 | O8: 1 | P8: 5 | Q8: 30 | R8: =Q8-P8 -> 25 | S8: 4000 | T8: =R8*S8 -> 100000 | W8: 1 | X8: 120000 | Y8: =W8*X8 -> 120000 | AD8: 100000 | AE8: =AC8*AD8 -> 0 | AG8: 60000 | AH8: =AF8*AG8 -> 0 | AO8: 1 | AP8: 120000 | AQ8: =AO8*AP8 -> 120000 | AT8: =AR8*AS8 -> 0 | AU8: =(SUM(T8,Y8,AB8,AE8,AH8,AK8,AN8,AQ8,AT8)) -> 340000 | AV8: =AU8+I8*E8+J8+M8+N8 -> 4140000 | AX8: 4140000 | AY8: =IF(AND(AV8>0,AX8=0),"Chưa TT",IF(AX8-AV8>0,"Thừa",IF(AND(AV8=0,AX8=0),"Trống",IF(AND(AX8>0,AV8=0),"Đóng cọc",IF(AX8-AV8<0,"Thiếu",IF(AX8-AV8=0,"Đủ",0)))))) -> Đủ | AZ8: =AX8-AV8 -> 0 | CA8: 144 | CB8: 209 | CC8: =CB8-CA8 -> 65 | CD8: 3800 | CE8: =CC8*CD8 -> 247000 | CG8: =CE8/3 -> 82333.333
A9: 301G1 | B9: G1 | C9: 301 | D9: ĐỖ THANH HƯƠNG | E9: 1 | F9: 3900000 | G9: 4200000 | H9: 3900000 | I9: 3900000 | K9: 30 | L9: 30 | O9: 1 | P9: 4 | Q9: 21 | R9: =Q9-P9 -> 17 | S9: 4000 | T9: =R9*S9 -> 68000 | W9: 1 | X9: 120000 | Y9: =W9*X9 -> 120000 | AC9: 1 | AD9: 100000 | AE9: =AC9*AD9 -> 100000 | AF9: 1 | AG9: 60000 | AH9: =AF9*AG9 -> 60000 | AI9: 1 | AJ9: 150000 | AK9: =AI9*AJ9 -> 150000 | AO9: 1 | AP9: 120000 | AQ9: =AO9*AP9 -> 120000 | AT9: =AR9*AS9 -> 0 | AU9: =(SUM(T9,Y9,AB9,AE9,AH9,AK9,AN9,AQ9,AT9)) -> 618000 | AV9: =AU9+I9*E9+J9+M9+N9 -> 4518000 | AX9: 4518000 | AY9: =IF(AND(AV9>0,AX9=0),"Chưa TT",IF(AX9-AV9>0,"Thừa",IF(AND(AV9=0,AX9=0),"Trống",IF(AND(AX9>0,AV9=0),"Đóng cọc",IF(AX9-AV9<0,"Thiếu",IF(AX9-AV9=0,"Đủ",0)))))) -> Đủ | AZ9: =AX9-AV9 -> 0 | CA9: 144 | CB9: 209 | CC9: =CB9-CA9 -> 65 | CD9: 3800 | CE9: =CC9*CD9 -> 247000 | CG9: =CE9/3 -> 82333.333
A10: 302G1 | B10: G1 | C10: 302 | D10: ĐỖ THANH HƯƠNG | E10: 1 | F10: 3800000 | G10: 4000000 | H10: 3800000 | I10: 3800000 | K10: 30 | L10: 30 | O10: 2 | P10: 53 | Q10: 101 | R10: =Q10-P10 -> 48 | S10: 4000 | T10: =R10*S10 -> 192000 | W10: 2 | X10: 120000 | Y10: =W10*X10 -> 240000 | AC10: 1 | AD10: 100000 | AE10: =AC10*AD10 -> 100000 | AF10: 2 | AG10: 60000 | AH10: =AF10*AG10 -> 120000 | AO10: 2 | AP10: 120000 | AQ10: =AO10*AP10 -> 240000 | AT10: =AR10*AS10 -> 0 | AU10: =(SUM(T10,Y10,AB10,AE10,AH10,AK10,AN10,AQ10,AT10)) -> 892000 | AV10: =AU10+I10*E10+J10+M10+N10 -> 4692000 | AX10: 4692000 | AY10: =IF(AND(AV10>0,AX10=0),"Chưa TT",IF(AX10-AV10>0,"Thừa",IF(AND(AV10=0,AX10=0),"Trống",IF(AND(AX10>0,AV10=0),"Đóng cọc",IF(AX10-AV10<0,"Thiếu",IF(AX10-AV10=0,"Đủ",0)))))) -> Đủ | AZ10: =AX10-AV10 -> 0 | CA10: 144 | CB10: 209 | CC10: =CB10-CA10 -> 65 | CD10: 3800 | CE10: =CC10*CD10 -> 247000 | CG10: =CE10/3 -> 82333.333
A11: 303G1 | B11: G1 | C11: 303 | D11: ĐỖ THANH HƯƠNG | E11: 1 | F11: 4000000 | G11: 4300000 | H11: 4000000 | I11: 4000000 | K11: 30 | L11: 30 | O11: 3 | P11: 128 | Q11: 294 | R11: =Q11-P11 -> 166 | S11: 4000 | T11: =R11*S11 -> 664000 | W11: 3 | X11: 120000 | Y11: =W11*X11 -> 360000 | AB11: =Z11*AA11 -> 0 | AD11: 100000 | AE11: =AC11*AD11 -> 0 | AF11: 3 | AG11: 60000 | AH11: =AF11*AG11 -> 180000 | AO11: 3 | AP11: 120000 | AQ11: =AO11*AP11 -> 360000 | AT11: =AR11*AS11 -> 0 | AU11: =(SUM(T11,Y11,AB11,AE11,AH11,AK11,AN11,AQ11,AT11)) -> 1564000 | AV11: =AU11+I11*E11+J11+M11+N11 -> 5564000 | AX11: 5564000 | AY11: =IF(AND(AV11>0,AX11=0),"Chưa TT",IF(AX11-AV11>0,"Thừa",IF(AND(AV11=0,AX11=0),"Trống",IF(AND(AX11>0,AV11=0),"Đóng cọc",IF(AX11-AV11<0,"Thiếu",IF(AX11-AV11=0,"Đủ",0)))))) -> Đủ | AZ11: =AX11-AV11 -> 0
A12: 304G1 | B12: G1 | C12: 304 | D12: ĐỖ THANH HƯƠNG | E12: 1 | F12: 4100000 | G12: 4400000 | H12: 4100000 | I12: 4100000 | K12: 30 | L12: 30 | O12: 2 | P12: 48 | Q12: 110 | R12: =Q12-P12 -> 62 | S12: 4000 | T12: =R12*S12 -> 248000 | W12: 2 | X12: 120000 | Y12: =W12*X12 -> 240000 | AB12: =Z12*AA12 -> 0 | AC12: 1 | AD12: 100000 | AE12: =AC12*AD12 -> 100000 | AF12: 2 | AG12: 60000 | AH12: =AF12*AG12 -> 120000 | AO12: 2 | AP12: 120000 | AQ12: =AO12*AP12 -> 240000 | AT12: =AR12*AS12 -> 0 | AU12: =(SUM(T12,Y12,AB12,AE12,AH12,AK12,AN12,AQ12,AT12)) -> 948000 | AV12: =AU12+I12*E12+J12+M12+N12 -> 5048000 | AX12: 5048000 | AY12: =IF(AND(AV12>0,AX12=0),"Chưa TT",IF(AX12-AV12>0,"Thừa",IF(AND(AV12=0,AX12=0),"Trống",IF(AND(AX12>0,AV12=0),"Đóng cọc",IF(AX12-AV12<0,"Thiếu",IF(AX12-AV12=0,"Đủ",0)))))) -> Đủ | AZ12: =AX12-AV12 -> 0
