Workbook

Sheet Hướng dẫn
A1: TIMOHOUSE — BẢNG CÂU HỎI LÀM RÕ NGHIỆP VỤ ĐỂ XÂY DỰNG PHẦN MỀM
A2: Mục tiêu: thống nhất cách hiểu để phần mềm tự sinh được 2 báo cáo hàng tháng đúng như file Excel công ty đang dùng (Báo cáo tòa – mẫu G1 tháng 6/2026 và Báo cáo tổng T/S/G – mẫu tháng 8/2026).
A4: CÁCH TRẢ LỜI
A5: 1. | B5: Mở lần lượt 3 sheet: «Câu hỏi», «Định nghĩa», «Công thức». Mỗi dòng là 1 điểm cần công ty xác nhận.
A6: 2. | B6: Đọc cột «Cách hiểu hiện tại của bên phát triển». Nếu đúng → chọn «Đúng» ở cột Xác nhận (màu vàng). Nếu sai → chọn «Sai - xem cột trả lời» và ghi cách đúng vào cột «Trả lời / bổ sung của công ty».
A7: 3. | B7: Dòng có trạng thái «Đã trả lời» là câu công ty đã trả lời trước đó – chỉ cần xem lại phần diễn giải và xác nhận.
A8: 4. | B8: Dòng «Chưa có thông tin» là câu bên phát triển chưa biết – rất mong công ty trả lời càng cụ thể càng tốt (kèm ví dụ số nếu có).
A9: 5. | B9: Sheet «Tài liệu cần cung cấp»: đánh dấu tài liệu nào đã gửi / chưa gửi / không có.
A10: 6. | B10: Sheet «Tổng quan» tự đếm tiến độ trả lời, không cần chỉnh.
A12: MÀU SẮC
A13: Ô màu vàng | B13: Ô công ty cần điền / chọn.
A14: Xanh lá | B14: Trạng thái «Đã trả lời».
A15: Vàng đậm | B15: Trạng thái «Chờ xác nhận» – bên phát triển đã suy ra từ số liệu/công thức trong file Excel, cần công ty xác nhận đúng/sai.
A16: Cam | B16: Trạng thái «Chưa có thông tin» – cần công ty trả lời mới.
A18: VÍ DỤ TRẢ LỜI (dòng mẫu)
A19: Câu hỏi | B19: Phòng trống là gì?
A20: Cách hiểu hiện tại | B20: Phòng không có hợp đồng hiệu lực tại ngày cuối tháng.
A21: Xác nhận | B21: Sai - xem cột trả lời
A22: Trả lời của công ty | B22: Phòng trống = phòng chưa có người thuê. Phòng trống cuối tháng = phòng hết HĐ vào cuối tháng và sẽ trống. (Người trả lời: A. Hằng – 22/09/2026)
A24: NGUỒN ĐỐI CHIẾU | B24: Timohouse.xlsx (sheet Báo cáo tháng 6, Báo cáo kinh doanh Tháng 8, Bảng lương, HD, HD theo tòa, Cập nhật thu tiền, DS phòng phá hợp đồng); Hoa hồng năm 2025-2026.xlsx; Hợp đồng thuê nhà 2026 (Mẫu); Tài liệu mô tả chức năng v1.8.
A25: NGƯỜI LẬP / NGÀY | B25: Bên phát triển – 22/09/2026
A27: CẬP NHẬT 22/09/2026 | B27: Đã điền sẵn vào cột «Trả lời / bổ sung» các nội dung lấy từ: (1) file «Câu hỏi làm rõ nghiệp vụ» KH trả lời ngày 06/09/2026 – đánh dấu [KH trả lời 06/09/2026]; (2) file «nội dung làm web Timehouse 31.8.2026» – đánh dấu [File 'nội dung làm web']; (3) đối chiếu công thức trong các file gốc KH gửi ngày 22/09/2026 (bảng lương tháng 8, G1.31.8.26, BÁO CÁO KINH DOANH THÁNG 8, Hoá đơn tháng 9) – đánh dấu [Đối chiếu công thức file nguồn]. KH chỉ cần xem lại và chọn Xác nhận; dòng nào không đúng xin ghi đè.
A29: CẬP NHẬT 22/09/2026 (lần 2) | B29: Bên phát triển đã điền GIẢ ĐỊNH cho toàn bộ mục còn lại (đánh dấu [GIẢ ĐỊNH bên PT – cần KH xác nhận]), dựa trên: công thức trong sổ tháng 9 (Hoá đơn tiền nhà tháng 9), bảng lương tháng 8, file G1 (THU CHI BAN ĐẦU), file hoa hồng và thông lệ kế toán. Mục nào KH thấy đúng chỉ cần chọn «Đúng»; mục nào khác thực tế xin ghi cách đúng vào cùng ô. LƯU Ý sửa so với lần 1: mốc thu tiền CÓ trọng số (mốc 1 100%, mốc 2 90%, mốc 3 70%) theo công thức trong sheet «cập nhật thu tiền» – xem Q33, D47, F39, F46.
A31: CẬP NHẬT 22/09/2026 (lần 3) | B31: Ghi nhận trả lời của KH cho Q01, Q16, Q04, Q06, Q07, Q23, Q30, Q31, Q33 (đánh dấu [KH trả lời 22/09/2026]). Các mục còn lại bên PT đã chuẩn hóa giả định theo thông lệ kế toán Việt Nam (ghi nhận theo kỳ phát sinh cho Báo cáo kinh doanh, theo tiền thực thu/chi cho Báo cáo dòng tiền, khấu hao đường thẳng, không bù trừ doanh thu–chi phí, lũy kế bù lỗ trước khi chia) và thực tế trong sổ của công ty. KH chỉ cần rà và chọn «Đúng».

Sheet Tổng quan
A1: TỔNG QUAN TIẾN ĐỘ TRẢ LỜI
A2: Sheet này tự đếm từ 3 sheet Câu hỏi / Định nghĩa / Công thức. Không cần chỉnh.
A4: Sheet | B4: Tổng số mục | C4: Đã trả lời | D4: Chờ xác nhận | E4: Chưa có thông tin | F4: Công ty đã xác nhận | G4: Còn lại chưa xác nhận | H4: % hoàn thành
A5: Câu hỏi | B5: =COUNTA('Câu hỏi'!A2:A65) | C5: =COUNTIF('Câu hỏi'!F2:F65,"Đã trả lời") | D5: =COUNTIF('Câu hỏi'!F2:F65,"Chờ xác nhận") | E5: =COUNTIF('Câu hỏi'!F2:F65,"Chưa có thông tin") | F5: =COUNTA('Câu hỏi'!G2:G65) | G5: =B5-F5 | H5: =IF(B5=0,0,F5/B5)
A6: Định nghĩa | B6: =COUNTA('Định nghĩa'!A2:A59) | C6: =COUNTIF('Định nghĩa'!E2:E59,"Đã trả lời") | D6: =COUNTIF('Định nghĩa'!E2:E59,"Chờ xác nhận") | E6: =COUNTIF('Định nghĩa'!E2:E59,"Chưa có thông tin") | F6: =COUNTA('Định nghĩa'!F2:F59) | G6: =B6-F6 | H6: =IF(B6=0,0,F6/B6)
A7: Công thức | B7: =COUNTA('Công thức'!A2:A57) | C7: =COUNTIF('Công thức'!F2:F57,"Đã trả lời") | D7: =COUNTIF('Công thức'!F2:F57,"Chờ xác nhận") | E7: =COUNTIF('Công thức'!F2:F57,"Chưa có thông tin") | F7: =COUNTA('Công thức'!G2:G57) | G7: =B7-F7 | H7: =IF(B7=0,0,F7/B7)
A8: TỔNG | B8: =SUM(B5:B7) | C8: =SUM(C5:C7) | D8: =SUM(D5:D7) | E8: =SUM(E5:E7) | F8: =SUM(F5:F7) | G8: =SUM(G5:G7) | H8: =IF(B8=0,0,F8/B8)
A10: Chú giải trạng thái:
A11: Đã trả lời | B11: Công ty đã trả lời trước đó – chỉ cần xác nhận lại.
A12: Chờ xác nhận | B12: Bên phát triển suy ra từ số liệu/công thức Excel – cần công ty xác nhận đúng/sai.
A13: Chưa có thông tin | B13: Bên phát triển chưa có thông tin – cần công ty trả lời.
A14: Ô công ty cần điền | B14: Cột màu vàng ở các sheet: Xác nhận, Trả lời / bổ sung, Người trả lời, Ngày.

Sheet Câu hỏi
A1: Mã | B1: Nhóm | C1: Câu hỏi | D1: Vì sao cần hỏi | E1: Cách hiểu hiện tại của bên phát triển | F1: Trạng thái | G1: Xác nhận (chọn) | H1: Trả lời / bổ sung của công ty | I1: Người trả lời | J1: Ngày
A2: Q01 | B2: Doanh thu | C2: Tổng doanh thu tháng tính theo tiền khách ĐÃ ĐÓNG thực tế trong tháng, hay theo hóa đơn đã phát hành (kể cả chưa thu)? | D2: Quyết định phần mềm lấy số từ Thu tiền hay từ Hóa đơn. | E2: Theo công thức file G1 (ô C2 = cột «Tổng đã đóng»): doanh thu = tiền thực thu trong tháng. | F2: Đã trả lời | H2: [KH trả lời 22/09/2026] Cần 2 loại báo cáo: «Báo cáo lợi nhuận dòng tiền» và «Báo cáo kinh doanh». Làm báo cáo từng tòa rồi gộp vào báo cáo tổng (T/S/G → toàn hệ thống), theo tháng. [GIẢ ĐỊNH bên PT theo chuẩn kế toán & thực tế DN – cần KH xác nhận] (1) Dòng tiền = ghi theo tiền thực thu/thực chi trong tháng (đúng như Excel hiện tại). (2) Kinh doanh = ghi theo kỳ phát sinh: doanh thu theo hóa đơn phát hành trong tháng (không gồm cọc thu/hoàn), chi phí theo tháng phát sinh nghĩa vụ (tiền nhà theo tháng dù trả quý, lương theo kỳ lương, giá gốc điện nước theo kỳ hóa đơn NCC), thiết bị và đầu tư ban đầu tính khấu hao. Hai báo cáo dùng chung sổ giao dịch, chỉ khác quy tắc ghi nhận thời điểm. | I2: KH 22/09 + Bên PT
A3: Q02 | B3: Doanh thu | C3: Tiền của hóa đơn tháng trước nhưng khách nộp trong tháng này thì tính doanh thu tháng nào? | D3: Tránh đếm trùng hoặc sót giữa 2 tháng. | E3: Tính vào tháng khách nộp tiền. | F3: Chờ xác nhận | H3: [GIẢ ĐỊNH bên PT theo chuẩn kế toán & thực tế DN – cần KH xác nhận] BC dòng tiền: doanh thu = tháng khách nộp tiền (kể cả nộp cho hóa đơn cũ). BC kinh doanh: doanh thu = tháng phát hành hóa đơn; tiền nộp cho hóa đơn cũ chỉ giảm công nợ. Tiền nộp trước cho tháng sau (đóng quý) = «doanh thu chưa thực hiện», phân bổ đều các tháng. | I3: KH 22/09 + Bên PT
A4: Q03 | B4: Doanh thu | C4: Cọc phòng mới: ghi nhận khi khách nộp cọc hay khi khách vào ở? Cọc giữ chỗ nhưng chưa vào ở có tính không? | D4: Dòng «Cọc phòng mới» trên báo cáo. | E4: ĐÃ TRẢ LỜI: trong tháng có phòng thuê mới (khách vào ở ngày 10, 15…) thì lấy cọc phòng đó tính vào báo cáo tháng đó. | F4: Đã trả lời | H4: [File 'nội dung làm web' 31/08/2026] Bảng doanh số có cột «số tiền đặt cọc», «ngày tính tiền», «tình trạng phòng chốt (ở luôn / cuối tháng / đang chờ)» → cọc mới ghi theo ngày tính tiền; phù hợp câu trả lời trước. | I4: KH
A5: Q04 | B5: Doanh thu | C5: Cọc khách bỏ không ở: ghi vào tháng khách báo bỏ hay tháng quyết toán? Số tiền là toàn bộ cọc hay cọc trừ tiền nhà những ngày đã ở? | D5: Dòng «Cọc khách bỏ không ở». | E5: Ghi vào tháng khách báo bỏ; số tiền = cọc − tiền nhà theo ngày đã ở (giống cách tính trong file hoa hồng). | F5: Đã trả lời | H5: [KH trả lời 22/09/2026] Cọc khách bỏ: coi như phòng đó không có phần hoàn cọc, KHÔNG tính thêm vào báo cáo – vì lúc thu đã tính vào «Cọc phòng mới» rồi. [GIẢ ĐỊNH bên PT theo chuẩn kế toán & thực tế DN – cần KH xác nhận] BC dòng tiền: dòng «Cọc khách bỏ không ở» chỉ là số theo dõi (memo), không cộng vào Tổng doanh thu; hoàn cọc = 0. BC kinh doanh: phần cọc bị giữ lại ghi nhận là «Thu nhập khác – cọc giữ lại» tại tháng khách bỏ (theo chuẩn kế toán, cọc chuyển từ nợ phải trả sang thu nhập khi bị tịch thu). | I5: KH 22/09 + Bên PT
A6: Q05 | B6: Doanh thu | C6: Hoàn cọc trừ khỏi doanh thu tháng nào: tháng khách ra hay tháng công ty thực chi tiền hoàn? | D6: Dòng «Hoàn cọc». | E6: Tháng thực chi tiền hoàn. | F6: Đã trả lời | H6: [KH trả lời 06/09/2026] (câu 17) Hoàn cọc = tiền cọc − khấu hao cố định 200.000đ/phòng − sửa chữa, vệ sinh… theo chi phí thực tế phát sinh; admin và kế toán duyệt. [Đối chiếu công thức file nguồn KH gửi 22/09/2026] File G1 báo cáo tháng 8: Tổng doanh thu = Tổng đã đóng − Hoàn cọc (ô C2 = AX2 − C7) → hoàn cọc trừ vào tháng ghi nhận hoàn. | I6: KH + đối chiếu file
A7: Q06 | B7: Doanh thu | C7: Phòng khách trả giữa tháng: tiền phòng tháng đó xử lý thế nào (không thu, tính theo số ngày ở, hay trừ vào cọc)? | D7: Công thức DT tiền phòng trong file G1 đang trừ nguyên giá của phòng đã trả. | E7: Chưa rõ. | F7: Đã trả lời | H7: [KH trả lời 22/09/2026] Phòng ký HĐ: trước khi hết HĐ 35 ngày hệ thống lập danh sách; quản lý review và xác nhận phòng nào khách báo không thuê nữa, phòng nào tự gia hạn HĐ lần mới (HĐ mới được thay đổi thời hạn, giá, các điều khoản). Nếu không báo mà rời đi → phá hợp đồng → thu ở phần «khách hàng phá hợp đồng». [GIẢ ĐỊNH bên PT theo chuẩn kế toán & thực tế DN – cần KH xác nhận] Kết thúc đúng hạn (có báo): tiền phòng tính đến ngày hết HĐ; nếu ngày hết HĐ giữa tháng thì tháng cuối = giá ÷ 30 × số ngày ở; điện nước chốt ngày ra; quyết toán → hoàn cọc. Rời sớm hơn ngày hết HĐ (dù có báo) = phá HĐ: mất cọc theo HĐ, không tính tiền phòng các tháng còn lại, phần nợ còn thiếu (điện nước, nợ cũ) theo dõi ở DS phòng phá HĐ. Gia hạn = tạo HĐ phiên bản mới nối tiếp, giữ mã khách, giữ cọc (thu/hoàn phần chênh nếu đổi giá). | I7: KH 22/09 + Bên PT
A8: Q07 | B8: Doanh thu | C8: Điện/nước của phòng đã trả trong tháng có tính vào doanh thu không? (File G1: tiền điện tính đủ cả phòng đã trả, nhưng nước/mạng/thang máy lại trừ đi) | D8: Các dòng dịch vụ đang xử lý không giống nhau. | E8: Chưa rõ – đề nghị công ty giải thích cách làm đúng. | F8: Đã trả lời | H8: [KH trả lời 22/09/2026] Điện nước đã báo trên hóa đơn từng phòng thì đó là doanh thu. [GIẢ ĐỊNH bên PT theo chuẩn kế toán & thực tế DN – cần KH xác nhận] → Doanh thu dịch vụ = Σ dòng dịch vụ trên hóa đơn (kể cả hóa đơn cuối của phòng đã trả và phần khấu trừ vào cọc). Điện nước phòng trống/không xuất hóa đơn = chi phí (nằm trong giá gốc điện nước của tòa). Phần mềm áp dụng một quy tắc cho mọi dịch vụ, không còn cộng/trừ tay như file G1. | I8: KH 22/09 + Bên PT
A9: Q08 | B9: Doanh thu | C9: Tiền phòng tính theo ngày (phòng mới vào giữa tháng, phòng trả giữa tháng) chia cho 30 hay chia cho số ngày thực của tháng (28/30/31)? | D9: Sổ tòa ghi «Ngày ở = 30», file hoa hồng lại chia 31. | E9: Chưa rõ. | F9: Chờ xác nhận | H9: [GIẢ ĐỊNH bên PT theo chuẩn kế toán & thực tế DN – cần KH xác nhận] Chọn quy ước công ty đang dùng trên sổ: tiền phòng theo ngày = giá tháng ÷ 30 × số ngày ở (đơn giản cho khách, nhất quán với «Ngày ở = 30»). Áp dụng cùng quy ước cho hoa hồng bỏ cọc và DT thu thêm (file hoa hồng/bảng lương hiện chia 31 → đổi về 30). Tham số cấu hình được nếu sau này muốn theo số ngày thực. | I9: KH 22/09 + Bên PT
A10: Q09 | B10: Doanh thu | C10: Khách chuyển phòng trong cùng tòa: phòng cũ có tính «phá hợp đồng», phòng mới có tính «phòng mới», có thu cọc mới không? | D10: Ảnh hưởng số phòng mới / phá HĐ và dòng cọc. | E10: Không tính phá HĐ, không tính phòng mới, cọc chuyển theo phòng mới. | F10: Chờ xác nhận | H10: [GIẢ ĐỊNH bên PT – cần KH xác nhận] Chuyển phòng nội bộ = 1 sự kiện «đổi phòng» trên cùng HĐ: phòng cũ không tính phá HĐ, phòng mới không tính phòng mới, cọc chuyển theo (chỉ thu thêm/hoàn phần chênh nếu giá cọc khác). Chỉ ghi nhận hoa hồng 1 lần theo phòng chốt ban đầu. | I10: Bên PT (giả định)
A11: Q10 | B11: Doanh thu | C11: Khoản «DV khác / Combo 120.000đ/người» có phải = 60.000 vệ sinh + 60.000 máy giặt ở mọi tòa? Tòa có phí vệ sinh riêng (VD T18: 30.000) thì xử lý sao? | D11: Báo cáo G1 đang chia đôi khoản này thành 2 dòng vệ sinh và máy giặt. | E11: Đúng với đa số tòa; tòa có giá riêng thì tách theo giá riêng của tòa. | F11: Chờ xác nhận | H11: [Căn cứ file KH gửi 22/09] Sổ tháng 9: NHÀ T dùng «DV khác» 120.000/người; phòng mới G6/S42 dùng vệ sinh 60.000 + (máy giặt 50–60.000) tách riêng; T18 nước 100.000 + vệ sinh 30.000. [GIẢ ĐỊNH bên PT – cần KH xác nhận] Phần mềm tách thành 2 dịch vụ riêng «Vệ sinh» và «Máy giặt» với đơn giá mặc định 60.000/người mỗi loại; tòa nào có giá riêng cấu hình override theo tòa; combo 120.000 chỉ là cách ghi gộp cũ. | I11: Bên PT (giả định)
A12: Q11 | B12: Doanh thu | C12: Cột «Thu khác» trong sổ tòa gồm những khoản gì và nằm ở dòng nào của báo cáo? | D12: Để khớp tổng doanh thu. | E12: Chưa rõ. | F12: Chờ xác nhận | H12: [Căn cứ file KH gửi 22/09] Sổ tháng 9: «Thu khác» là các khoản phụ thu ghi kèm tiền phòng (VD +100.000, +200.000 thêm người/xe) và tiền điện chốt bổ sung. [GIẢ ĐỊNH bên PT – cần KH xác nhận] Thu khác = dòng «Phụ thu / khoản khác» trên hóa đơn (thêm người, thêm xe, phạt, đền bù, bán đồ); trên báo cáo gộp vào «Doanh thu tiền phòng» nếu là phụ thu tiền phòng, còn phạt/đền bù đưa vào «Doanh thu khác» (dòng mới, mặc định 0). | I12: Bên PT (giả định)
A13: Q12 | B13: Doanh thu | C13: «Điện chung» tính vào doanh thu điện hay dòng riêng? Chia cho các phòng theo cách nào (theo phòng / theo người)? | D13: Dòng doanh thu điện. | E13: Chưa rõ. | F13: Chờ xác nhận | H13: [Căn cứ file KH gửi 22/09] Sổ tháng 9 có cột «ĐIỆN CHUNG» trong tổng DV và bảng «Điện vệ sinh chung» (CS cũ/mới, SL, đơn giá, số người sử dụng). [GIẢ ĐỊNH bên PT – cần KH xác nhận] Điện chung = điện công tơ khu vực chung, chia theo số người ở của từng phòng; ghi thành dòng dịch vụ «Điện chung» trên hóa đơn và cộng vào «Doanh thu điện» trên báo cáo. | I13: Bên PT (giả định)
... A19: Q18 | B19: Giá vốn & chi phí | C19: Điện nước của phòng trống nằm trong giá gốc điện/nước của tòa hay ghi thành «chi phí khác»? | D19: Phân loại chi phí. | E19: Nằm trong giá gốc điện/nước của tòa. | F19: Chờ xác nhận | H19: [Căn cứ file KH gửi 22/09] Sheet «ĐIỆN NƯỚC PHÒNG TRỐNG/KHÔNG THU ĐƯỢC» gồm cả phòng trống và phòng phá HĐ. [GIẢ ĐỊNH bên PT – cần KH xác nhận] Không tách dòng riêng: phần này đã nằm trong giá gốc điện/nước của tòa (tiền trả EVN); phần mềm chỉ thống kê riêng để theo dõi thất thoát (báo cáo «âm dương điện nước»). | I19: Bên PT (giả định)
A20: Q19 | B20: Giá vốn & chi phí | C20: Các chi phí marketing, giá gốc điện nước, thiết bị, sửa chữa, văn phòng… đều import vào mục Quản lý chi phí của phần mềm? | D20: Xác định nguồn số cho báo cáo. | E20: ĐÃ TRẢ LỜI: có, các chi phí này sẽ import vào mục quản lý chi phí để có dữ liệu làm báo cáo. (Riêng lương lấy từ bảng lương, không import lại.) | F20: Đã trả lời
A21: Q20 | B21: Giá vốn & chi phí | C21: Số phòng dùng để chia chi phí chung (tháng 6 = 1.303 phòng) là tổng phòng đang quản lý (kể cả phòng trống) hay chỉ phòng đang có khách? Lấy tại thời điểm nào trong tháng? | D21: Công thức chia chi phí chung: (Tổng chi phí ÷ 1.303) × số phòng của tòa. | E21: Tổng phòng đang quản lý tại cuối tháng. | F21: Chờ xác nhận | H21: [GIẢ ĐỊNH bên PT – cần KH xác nhận] Mẫu số = tổng số phòng đang quản lý toàn hệ thống tại ngày cuối tháng (kể cả phòng trống, không kể tòa đã trả chủ nhà). Tháng 6/2026 = 1.303 phòng. Phần mềm tính tự động từ master phòng và lưu snapshot theo kỳ. | I21: Bên PT (giả định)
A22: Q21 | B22: Giá vốn & chi phí | C22: Lương cơ bản + phụ cấp của quản lý tòa chia vào các tòa người đó quản lý, hay chia đều toàn hệ thống? | D22: Dòng «Lương quản lý» trên báo cáo tòa. | E22: Chưa rõ. | F22: Chờ xác nhận | H22: [Căn cứ file KH gửi 22/09] G1 sheet THU CHI BAN ĐẦU: «Lương quản lý» tòa = 1.500.000 (số cố định theo tòa) tách khỏi «Lương hỗ trợ quản lý». [GIẢ ĐỊNH bên PT – cần KH xác nhận] Lương cơ bản + phụ cấp của quản lý tòa chia đều theo số phòng cho các tòa người đó phụ trách (không chia toàn hệ thống). Phần mềm lấy từ bảng lương đã khóa và phân bổ tự động. | I22: Bên PT (giả định)
A23: Q22 | B23: Giá vốn & chi phí | C23: Lương hiệu suất của quản lý tòa (số phòng × mức lương/phòng) ghi thẳng vào tòa đó, không chia? | D23: Dòng «Lương quản lý». | E23: Có – theo trả lời trước: lương cố định theo bảng lương, còn lương hiệu suất + doanh thu + hoa hồng tính riêng. | F23: Chờ xác nhận | H23: [GIẢ ĐỊNH bên PT – cần KH xác nhận] Có: lương hiệu suất (số phòng × mức lương/phòng) tính riêng từng tòa nên ghi thẳng vào tòa đó, không phân bổ. Dòng «Lương quản lý» trên báo cáo tòa = lương hiệu suất của tòa + phần lương cố định phân bổ (Q21). | I23: Bên PT (giả định)
A24: Q23 | B24: Giá vốn & chi phí | C24: Các con số trong công thức chia chi phí: 12 triệu (quản lý tổng), 21 triệu (TPVH), 3 triệu (NV nguồn), 2 triệu (kế toán), 22 triệu (sửa chữa) là cố định hàng tháng hay lấy từ bảng lương thực tế? | D24: Công thức trong file G1 đang ghi số cứng. | E24: Chưa rõ. | F24: Đã trả lời | H24: [KH trả lời 22/09/2026] Lương cố định các mức đó theo từng level (chức danh/bậc); còn lương khác tính theo hiệu suất, cổ phần và các phần đã mô tả trong bảng lương. [GIẢ ĐỊNH bên PT theo chuẩn kế toán & thực tế DN – cần KH xác nhận] Phần mềm khai báo «Bảng lương cố định theo level» (lương cơ bản, phụ cấp, khoán) có hiệu lực theo ngày; báo cáo tòa lấy tổng lương cố định theo chức danh của tháng để phân bổ theo số phòng. Phần «cổ phần» của nhân viên là lợi nhuận được chia qua module Cổ đông (nhân viên đồng thời là cổ đông tòa), không đưa vào chi phí lương để tránh tính 2 lần; phiếu lương chỉ hiển thị tham chiếu. | I24: KH 22/09 + Bên PT
A25: Q24 | B25: Giá vốn & chi phí | C25: Lương vệ sinh 550.000đ/tòa: cố định mọi tòa hay tùy tòa (theo diện tích, số phòng)? | D25: Dòng «Lương vệ sinh». | E25: Chưa rõ. | F25: Chờ xác nhận | H25: [Căn cứ file KH gửi 22/09] G1 THU CHI BAN ĐẦU cũng ghi lương vệ sinh 550.000/tháng. [GIẢ ĐỊNH bên PT – cần KH xác nhận] Cố định 550.000đ/tòa/tháng (khoán vệ sinh khu vực chung) áp cho mọi tòa; tòa lớn có thể cấu hình mức khác. Nhập trong bảng lương/khoán, không import chi phí. | I25: Bên PT (giả định)
A26: Q25 | B26: Giá vốn & chi phí | C26: Hoa hồng ghi vào chi phí của tháng nào: tháng khách «đủ», tháng ký hợp đồng, hay tháng trả tiền hoa hồng? | D26: Dòng hoa hồng trên báo cáo. | E26: Tháng trả tiền hoa hồng. | F26: Đã trả lời | H26: [KH trả lời 06/09/2026] (câu 19) Hoa hồng chi trả ngay sau khi khách đóng đủ cọc 1 và ký HĐ → ghi nhận chi phí vào tháng khách đủ điều kiện / trả hoa hồng. | I26: KH
A27: Q26 | B27: Giá vốn & chi phí | C27: Sửa chữa do khách làm hỏng và đã trừ vào cọc của khách: có ghi thêm vào chi phí sửa chữa nữa không? | D27: Tránh tính 2 lần. | E27: Chưa rõ. | F27: Chờ xác nhận | H27: [GIẢ ĐỊNH bên PT theo chuẩn kế toán & thực tế DN – cần KH xác nhận] Chi phí sửa chữa thực trả thợ ghi đủ ở «Sửa chữa, thay thế, bảo trì»; khoản khấu trừ cọc của khách (sửa chữa, vệ sinh, sơn, khấu hao 200k) ghi «Thu nhập khác – khấu trừ cọc». Báo cáo hiển thị cả 2 dòng, không bù trừ (đúng nguyên tắc không bù trừ doanh thu – chi phí); có chỉ số phụ «chi phí sửa chữa ròng» để quản trị. | I27: KH 22/09 + Bên PT
A28: Q27 | B28: Giá vốn & chi phí | C28: «Chi phí khác» gồm những loại gì (công an tạm trú, biển xe, dọn phòng…)? Có cần chia nhỏ hơn trên báo cáo không? | D28: Danh mục chi phí. | E28: Chưa rõ. | F28: Chờ xác nhận | H28: [Căn cứ file KH gửi 22/09] File G1: chi phí khác gồm dọn vệ sinh phòng, sơn điểm, công an tạm trú, biển khóa xe. [GIẢ ĐỊNH bên PT – cần KH xác nhận] Danh mục con đề xuất: hành chính/pháp lý (tạm trú, giấy phép), vật tư nhỏ, dọn/sơn phòng, phí ngân hàng, khác. Báo cáo vẫn hiển thị 1 dòng «Chi phí khác», drill-down xem theo danh mục con. | I28: Bên PT (giả định)
A29: Q28 | B29: Giá vốn & chi phí | C29: Chi phí văn phòng và marketing: có tách riêng theo nhóm T/S/G không, hay là 1 số chung rồi chia theo số phòng? | D29: Báo cáo tổng có cột T/S/G. | E29: 1 số chung toàn hệ thống, chia theo số phòng. | F29: Chờ xác nhận | H29: [GIẢ ĐỊNH bên PT – cần KH xác nhận] 1 số chung toàn hệ thống (từ file chi phí văn phòng), phân bổ theo số phòng xuống từng tòa; báo cáo tổng cộng lại theo nhóm T/S/G. Nếu có chiến dịch marketing riêng cho 1 tòa thì import gắn thẳng tòa đó. | I29: Bên PT (giả định)
A30: Q29 | B30: Lương & hiệu suất | C30: Công thức «Tổng DT thu được» = (Thu mốc 1 + mốc 2 + mốc 3) × (1 − Dịch vụ ÷ DT phải thu) + DT thu thêm — có đúng không? | D30: Là công thức lõi để tính hiệu suất và lương; sheet Bảng lương không còn công thức nên bên phát triển phải suy từ số liệu. | E30: Suy từ số liệu tháng 8, khớp toàn bộ các dòng. | F30: Đã trả lời | H30: [Đối chiếu công thức file nguồn KH gửi 22/09/2026] Bảng lương tháng 8 (file gốc còn công thức): T = P − P×R + S, tức Tổng DT thu được = Tổng 3 mốc × (1 − Dịch vụ/DT phải thu) + DT thu thêm. Đúng như suy luận. | I30: Đối chiếu file
A31: Q30 | B31: Lương & hiệu suất | C31: Xin bảng mức lương/phòng chính thức theo hiệu suất (ví dụ: ≥95% → 130.000; 90–95% → ?; <90% → ?). | D31: Phần mềm không được đoán công thức lương. | E31: Suy đoán: 130.000 hoặc 120.000 × hiệu suất; giảm thêm khi hiệu suất < 95%. | F31: Đã trả lời | H31: [KH trả lời 22/09/2026] Các mức đơn giá/phòng là cố định theo từng level (bậc hiệu suất). [GIẢ ĐỊNH bên PT theo chuẩn kế toán & thực tế DN – cần KH xác nhận] Bảng bậc đề xuất từ số liệu tháng 8: HS ≥ 98% → 130.000/100; 95–<98% → 120.000/95; 93–<95% → 119.000/95; 91–<93% → 110.000/90; 88–<91% → 109.000/90; 75–<88% → 75.000/75; < 75% → 0; tòa mới → 100.000 cố định. Mức lương/phòng = HS × đơn giá ÷ ngưỡng. Lưu quy tắc có phiên bản; KH chỉ cần xác nhận ranh giới % giữa các bậc. | I31: KH 22/09 + Bên PT
A32: Q31 | B32: Lương & hiệu suất | C32: Vì sao có nhân viên đơn giá 130.000đ/phòng (Huyền, Linh, Khải, Trường, Lâm, Kiên, Hương) và có người 120.000đ/phòng (Phương, Thủy, Nụ, Giang, Tú)? Tiêu chí xếp bậc? | D32: Cấu hình bậc nhân viên. | E32: Chưa rõ (thâm niên?). | F32: Đã trả lời | H32: [KH trả lời 22/09/2026] Mức cố định theo level, không theo nhân viên. [GIẢ ĐỊNH bên PT theo chuẩn kế toán & thực tế DN – cần KH xác nhận] Không có hệ số thâm niên; đơn giá chỉ phụ thuộc bậc hiệu suất của từng tòa trong tháng. | I32: KH 22/09 + Bên PT
... A65: Q64 | B65: Vận hành & tổ chức | C65: Có tòa thuê của nhiều chủ (nhiều hợp đồng đầu vào) hoặc 1 hợp đồng cho nhiều tòa không? | D65: Thiết kế dữ liệu hợp đồng đầu vào. | E65: Chưa rõ. | F65: Chờ xác nhận | H65: [Căn cứ file KH gửi 22/09] HĐ mẫu: 1 chủ nhà – 1 tòa – 1 HĐ 5 năm; sổ có tòa S4A, S9B, S19A/B/C, S37A/B là các khối tách của cùng địa chỉ. [GIẢ ĐỊNH bên PT – cần KH xác nhận] Mặc định 1 HĐ đầu vào ↔ 1 tòa; cho phép 1 HĐ gắn nhiều tòa (các khối A/B/C) và 1 tòa có nhiều HĐ theo thời gian (gia hạn/ký lại). Không hỗ trợ 1 tòa nhiều chủ nhà cùng lúc. | I65: Bên PT (giả định)

Sheet Định nghĩa
A1: Mã | B1: Nhóm | C1: Thuật ngữ | D1: Cách hiểu hiện tại của bên phát triển | E1: Trạng thái | F1: Xác nhận (chọn) | G1: Định nghĩa đúng / bổ sung của công ty | H1: Người trả lời
A2: D01 | B2: Đối tượng | C2: Tòa (mã T42, S9B, G1) | D2: Một tòa nhà công ty thuê lại từ chủ nhà theo 1 hợp đồng đầu vào; chữ đầu = nhóm T/S/G. | E2: Đã trả lời
A3: D02 | B3: Đối tượng | C3: Nhóm tòa T / S / G | D3: Nhóm theo pháp nhân / nhóm đầu tư ký hợp đồng đầu vào, không theo địa lý; có thể đổi theo thời gian. | E3: Chờ xác nhận | G3: [KH trả lời 06/09/2026] (câu 2) T/S/G là ký hiệu mã tòa. Ý nghĩa phân nhóm chưa rõ; file BC DT còn có loại L1/L2/L3. [GIẢ ĐỊNH bên PT – cần KH xác nhận] Nhóm/dòng nhà T, S, G (ký hiệu mã tòa), có thể đổi theo HĐ đầu vào; kèm hạng L1/L2/L3 theo tình trạng tòa (xem Q63). | H3: KH + Bên PT (giả định)
A4: D03 | B4: Đối tượng | C4: Mã phòng (606T42) | D4: 3 số phòng + mã tòa; ngoại lệ có chữ (401S4A, 201S48A). | E4: Đã trả lời
A5: D04 | B5: Đối tượng | C5: Mã khách (606T42A001) | D5: Mã phòng + «A» + số thứ tự khách của phòng. | E5: Đã trả lời | G5: [Căn cứ file KH gửi 22/09] Hóa đơn: mã KH = mã phòng & "A001". [GIẢ ĐỊNH bên PT – cần KH xác nhận] Số thứ tự tăng theo HĐ mới của phòng (A001, A002…). | H5: Bên PT (giả định)
A6: D05 | B6: Đối tượng | C6: Quản lý tòa (NVVH) | D6: Nhân viên vận hành được phân công phụ trách chính tòa; 1 người phụ trách 3–12 tòa. | E6: Đã trả lời
A7: D06 | B7: Đối tượng | C7: TPVH / TNVH | D7: Trưởng phòng / trưởng nhóm vận hành – cấp trên trực tiếp của các quản lý tòa. | E7: Đã trả lời
A8: D07 | B8: Đối tượng | C8: Team (trong file hoa hồng) | D8: Người / đơn vị NHẬN hoa hồng: môi giới bên ngoài, cộng tác viên, hoặc lead nội bộ (ghi «(LEAD)»). | E8: Chờ xác nhận | G8: [KH trả lời 06/09/2026] (câu 20) Hoa hồng chia theo cá nhân. [File 'nội dung làm web' 31/08/2026] Bảng hoa hồng có cột «team sale»; thống kê khách có «nguồn khách (sale nội bộ, đối tác)». [GIẢ ĐỊNH bên PT – cần KH xác nhận] Team = người/đơn vị nhận hoa hồng (cá nhân sale nội bộ, lead, đối tác/môi giới, CTV); mỗi deal 1 người nhận chính, có thể tách nhiều dòng khi trùng nguồn. | H8: KH + Bên PT (giả định)
A9: D08 | B9: Đối tượng | C9: Cổ đông | D9: Người góp vốn vào TỪNG TÒA theo tỷ lệ %; mỗi tòa có danh sách cổ đông riêng. | E9: Đã trả lời | G9: [KH trả lời 06/09/2026] (câu 30) Một cổ đông có thể góp vào nhiều nhà; tỷ lệ nhập tay. (câu 31) Thống kê tài sản / tiền cọc của cổ đông liên kết với module Tòa nhà. | H9: KH
A10: D09 | B10: Đối tượng | C10: Kỳ báo cáo | D10: Tháng dương lịch; hóa đơn chốt số ngày 22 nhưng báo cáo tính theo tháng thu tiền. | E10: Chờ xác nhận | G10: [GIẢ ĐỊNH bên PT – cần KH xác nhận] Kỳ báo cáo = tháng dương lịch. Chỉ số điện nước chốt ngày 22 tháng trước; hóa đơn phát hành cuối tháng cho tiền phòng tháng sau + dịch vụ tháng này; thu tiền ngày 1–15 tháng sau; báo cáo dòng tiền theo tháng thu. | H10: Bên PT (giả định)
A11: D10 | B11: Giá & hợp đồng | C11: Giá niêm yết | D11: Giá công bố của phòng; là mẫu số khi tính hiệu suất thu tiền. | E11: Đã trả lời | G11: [KH trả lời 06/09/2026] (câu 13) Giá niêm yết là giá tiêu chuẩn của Timehouse. | H11: KH
A12: D11 | B12: Giá & hợp đồng | C12: Giá QL | D12: Mức giá sàn quản lý tòa được tự quyết khi chốt khách (thấp hơn phải xin duyệt). | E12: Chờ xác nhận | G12: [Căn cứ file KH gửi 22/09] Sổ: cột Giá QL thường = giá hiện tại, thấp hơn niêm yết 100–500k. [GIẢ ĐỊNH bên PT – cần KH xác nhận] Giá QL = mức sàn quản lý tòa được tự chốt với khách; chốt thấp hơn Giá QL phải được TNVH duyệt. Giá QL do TPVH đặt theo tòa/phòng. | H12: Bên PT (giả định)
A13: D12 | B13: Giá & hợp đồng | C13: Giá phòng hiện tại (giá chốt) | D13: Giá thực ký trên hợp đồng; là cơ sở tính tiền phòng và hoa hồng. | E13: Đã trả lời | G13: [KH trả lời 06/09/2026] (câu 13) Giá cho thuê là giá thực tế khách đang thuê. | H13: KH
A14: D13 | B14: Giá & hợp đồng | C14: Kỳ TT (1 / 3) | D14: Số tháng khách đóng tiền 1 lần: 1 = hàng tháng, 3 = theo quý. | E14: Chờ xác nhận | G14: [Căn cứ file KH gửi 22/09] Sổ: Tổng cần đóng = … + Giá phòng × Kỳ TT. [GIẢ ĐỊNH bên PT – cần KH xác nhận] Kỳ TT = số tháng tiền phòng thu trước trong 1 hóa đơn (1 hoặc 3; cho phép 6). | H14: Bên PT (giả định)
A15: D14 | B15: Giá & hợp đồng | C15: Ngày ở / Ngày DV (30) | D15: Số ngày tính tiền phòng / tính dịch vụ trong tháng; nhỏ hơn 30 thì tính theo tỷ lệ ngày. | E15: Chờ xác nhận | G15: [GIẢ ĐỊNH bên PT theo chuẩn kế toán & thực tế DN – cần KH xác nhận] Ngày ở/Ngày DV mặc định 30; tiền theo ngày = giá ÷ 30 × ngày (quy ước công ty). | H15: KH 22/09 + Bên PT
A16: D15 | B16: Giá & hợp đồng | C16: Số người | D16: Số người ở thực tế trong phòng → cơ sở tính nước, vệ sinh, máy giặt, combo. | E16: Đã trả lời
A17: D16 | B17: Giá & hợp đồng | C17: Nợ cũ | D17: Số còn thiếu của kỳ trước, cộng dồn thành 1 dòng trên hóa đơn kỳ này. | E17: Đã trả lời
A18: D17 | B18: Giá & hợp đồng | C18: Thu khác | D18: Khoản thu ngoài bảng giá (phạt, đền bù, bán đồ…). | E18: Chờ xác nhận | G18: [GIẢ ĐỊNH bên PT – cần KH xác nhận] Thu khác = phụ thu ghi kèm hóa đơn (thêm người, thêm xe, phạt, đền bù, bán đồ, điện chốt bổ sung); có danh mục con để báo cáo đúng dòng. | H18: Bên PT (giả định)
A19: D18 | B19: Giá & hợp đồng | C19: Điện chung | D19: Điện khu vực chung được chia cho các phòng. | E19: Chờ xác nhận | G19: [Căn cứ file KH gửi 22/09] Sổ có bảng «Điện vệ sinh chung» chia theo số người sử dụng. [GIẢ ĐỊNH bên PT – cần KH xác nhận] Điện chung = điện công tơ khu vực chung ÷ tổng số người ở × số người của phòng; dòng dịch vụ riêng, cộng vào doanh thu điện. | H19: Bên PT (giả định)
A20: D19 | B20: Giá & hợp đồng | C20: DV khác / Combo 120.000đ/người | D20: =60.000 vệ sinh + 60.000 máy giặt (báo cáo chia đôi). | E20: Chờ xác nhận | G20: [GIẢ ĐỊNH bên PT – cần KH xác nhận] Combo = 2 dịch vụ Vệ sinh 60.000/người + Máy giặt 60.000/người; phần mềm tách riêng, tòa có giá khác thì cấu hình. | H20: Bên PT (giả định)
A21: D20 | B21: Giá & hợp đồng | C21: Tình trạng Đủ / Thiếu / Chưa TT | D21: Đã đóng bằng cần đóng / đóng một phần / chưa đóng. | E21: Đã trả lời
A22: D21 | B22: Giá & hợp đồng | C22: Công nợ | D22: Tổng cần đóng − Tổng đã đóng (âm = khách còn nợ). | E22: Đã trả lời | G22: [KH trả lời 06/09/2026] (câu 14) Một khoản thu chuyển từ «hóa đơn» sang «công nợ» sau 5 ngày kể từ khi có hóa đơn. | H22: KH
A23: D22 | B23: Giá & hợp đồng | C23: Cọc khách cũ / Cọc | D23: Cọc đang giữ của khách hiện tại / cọc thu mới trong tháng. | E23: Chờ xác nhận | G23: [GIẢ ĐỊNH bên PT – cần KH xác nhận] Cọc khách cũ = số cọc đang giữ của HĐ hiện hành (Deposit đang giữ); Cọc = khoản cọc thu mới trong tháng (HĐ mới hoặc cọc bổ sung). | H23: Bên PT (giả định)
A24: D23 | B24: Trạng thái phòng | C24: Phòng mới | D24: Phòng có hợp đồng mới với ngày vào ở trong tháng (kể cả phòng cũ có khách mới). | E24: Chờ xác nhận | G24: [GIẢ ĐỊNH bên PT – cần KH xác nhận] Phòng mới = HĐ mới có ngày vào ở trong tháng (kể cả phòng cũ có khách mới); không tính đổi phòng nội bộ và gia hạn. | H24: Bên PT (giả định)
A25: D24 | B25: Trạng thái phòng | C25: Phòng trống | D25: ĐÃ TRẢ LỜI: phòng chưa có người thuê. Phòng trống cuối tháng = phòng hết hợp đồng vào cuối tháng và sẽ trống. | E25: Đã trả lời | G25: [File 'nội dung làm web' 31/08/2026] Phòng trống tách 3 loại: (1) trống ở luôn trong tháng, (2) trống hết tháng, (3) đang chờ. [KH trả lời 06/09/2026] (câu 21) Phòng phát sinh do hoàn cọc/phá HĐ cần kiểm tra/dọn dẹp trước khi đưa lại thị trường. | H25: KH
A26: D25 | B26: Trạng thái phòng | C26: Phòng phá hợp đồng | D26: Hợp đồng kết thúc TRƯỚC hạn do phía khách; tính vào tháng có ngày ra thực tế. | E26: Đã trả lời | G26: [KH trả lời 22/09/2026] Không báo trước (35 ngày) mà rời đi = phá hợp đồng; thu nợ ở phần khách hàng phá hợp đồng. [GIẢ ĐỊNH bên PT theo chuẩn kế toán & thực tế DN – cần KH xác nhận] Rời trước ngày hết HĐ cũng tính phá HĐ; tính vào tháng có ngày ra thực tế / ngày xác nhận bỏ. | H26: KH 22/09 + Bên PT
A27: D26 | B27: Trạng thái phòng | C27: Khách chuyển phòng nội bộ | D27: Không tính phòng mới / phá HĐ; cọc chuyển theo. | E27: Chờ xác nhận | G27: [GIẢ ĐỊNH bên PT – cần KH xác nhận] Sự kiện «đổi phòng» trên cùng HĐ: không tính phòng mới/phá HĐ, cọc và hoa hồng giữ nguyên. | H27: Bên PT (giả định)
A28: D27 | B28: Trạng thái phòng | C28: Khách bỏ cọc | D28: Đã đặt cọc (có thể ở vài ngày) rồi bỏ, không ký hợp đồng dài hạn. | E28: Chờ xác nhận | G28: [GIẢ ĐỊNH bên PT – cần KH xác nhận] Khách bỏ cọc = đã đóng cọc (có thể ở vài ngày) rồi không ký/không ở tiếp; cọc bị giữ lại = «doanh thu phá hợp đồng»; không đếm là phòng mới nếu chưa vào ở. | H28: Bên PT (giả định)
A29: D28 | B29: Trạng thái phòng | C29: Hợp đồng hết hạn đúng ngày | D29: Không phải phá hợp đồng; phòng trống nếu không gia hạn. | E29: Đã trả lời | G29: [KH trả lời 22/09/2026] Trước 35 ngày lập danh sách; quản lý xác nhận không thuê nữa hoặc tự gia hạn bằng HĐ lần mới (có thể đổi thời hạn, giá, điều khoản). | H29: KH 22/09 + Bên PT
A30: D29 | B30: Chỉ tiêu tài chính | C30: Tổng doanh thu | D30: Tổng tiền khách thực đóng trong tháng (cột «Tổng đã đóng»), gồm cọc mới, cọc bỏ, đã trừ hoàn cọc. | E30: Đã trả lời | G30: [KH trả lời 22/09/2026] Cọc khách bỏ không tính thêm (đã nằm trong cọc phòng mới); điện nước đã lên hóa đơn là doanh thu. [GIẢ ĐỊNH bên PT theo chuẩn kế toán & thực tế DN – cần KH xác nhận] BC dòng tiền: Tổng DT = Σ tiền thực đóng trong tháng (tiền phòng + dịch vụ + cọc mới + thu khác) − hoàn cọc; dòng «cọc khách bỏ» chỉ theo dõi. BC kinh doanh: Tổng DT = tiền phòng + dịch vụ + thu khác theo hóa đơn phát hành trong tháng + thu nhập khác (cọc giữ lại, khấu trừ cọc); không gồm cọc thu/hoàn. | H30: KH 22/09 + Bên PT
A31: D30 | B31: Chỉ tiêu tài chính | C31: Cọc phòng mới | D31: ĐÃ TRẢ LỜI: cọc thu của phòng có khách mới vào ở trong tháng. | E31: Đã trả lời
A32: D31 | B32: Chỉ tiêu tài chính | C32: Cọc khách bỏ không ở | D32: Phần cọc bị mất khi khách bỏ; ghi nhận tháng khách báo bỏ. | E32: Đã trả lời | G32: [KH trả lời 22/09/2026] Cọc khách bỏ: phòng đó không có hoàn cọc, không tính lại vào báo cáo. [GIẢ ĐỊNH bên PT theo chuẩn kế toán & thực tế DN – cần KH xác nhận] Dòng memo trên BC dòng tiền; trên BC kinh doanh là thu nhập khác tại tháng khách bỏ. | H32: KH 22/09 + Bên PT
A33: D32 | B33: Chỉ tiêu tài chính | C33: Hoàn cọc | D33: Tiền cọc trả lại khách trong tháng (sau khấu trừ). | E33: Đã trả lời | G33: [KH trả lời 06/09/2026] (câu 17) Hoàn cọc = cọc − khấu hao cố định 200.000đ/phòng − sửa chữa, vệ sinh… theo thực tế; admin/kế toán duyệt. [File 'nội dung làm web' 31/08/2026] Danh sách hoàn cọc: mã phòng tòa, số tiền hoàn, tiền cọc, chi phí khấu hao, sửa chữa, vệ sinh, khác. | H33: KH
A34: D33 | B34: Chỉ tiêu tài chính | C34: Doanh thu tiền phòng | D34: Tổng tiền phòng đã thu, trừ phòng đã trả, cộng tiền theo ngày của phòng mới. | E34: Đã trả lời
A35: D34 | B35: Chỉ tiêu tài chính | C35: Doanh thu dịch vụ (7 loại) | D35: Điện, nước, vệ sinh, mạng, xe điện, thang máy, máy giặt. | E35: Đã trả lời
A36: D35 | B36: Chỉ tiêu tài chính | C36: Tiền thuê nhà 1 tháng | D36: Tiền trả chủ nhà theo hợp đồng đầu vào (mẫu: 114 triệu/tháng). | E36: Đã trả lời
A37: D36 | B37: Chỉ tiêu tài chính | C37: Mua thêm thiết bị | D37: Thiết bị mua trong tháng cho tòa, tính thẳng vào giá vốn (không khấu hao). | E37: Đã trả lời | G37: [KH trả lời 22/09/2026] 1 lần (dòng tiền) / khấu hao (kinh doanh). [GIẢ ĐỊNH bên PT theo chuẩn kế toán & thực tế DN – cần KH xác nhận] Chính sách khấu hao xem Q16. | H37: KH 22/09 + Bên PT
A38: D37 | B38: Chỉ tiêu tài chính | C38: Giá gốc dịch vụ | D38: ĐÃ TRẢ LỜI: tiền thực trả nhà cung cấp điện/nước/mạng/rác/môi trường/thang máy theo tòa/tháng – import vào mục quản lý chi phí. | E38: Đã trả lời
A39: D38 | B39: Chỉ tiêu tài chính | C39: Giá vốn (GV) | D39: Tiền thuê nhà + thiết bị + giá gốc dịch vụ. | E39: Đã trả lời
A40: D39 | B40: Chỉ tiêu tài chính | C40: Chi phí vận hành (các dòng lương) | D40: Lương cố định chia theo số phòng + lương hiệu suất ghi thẳng vào tòa. | E40: Đã trả lời | G40: [KH trả lời 22/09/2026] Lương cố định theo level; lương hiệu suất, cổ phần và các phần khác tính riêng theo bảng lương. [GIẢ ĐỊNH bên PT theo chuẩn kế toán & thực tế DN – cần KH xác nhận] Trên báo cáo tòa: lương cố định phân bổ theo số phòng + lương hiệu suất ghi thẳng tòa; phần chia cổ phần không vào chi phí lương. | H40: KH 22/09 + Bên PT
...

Sheet Công thức
A1: Mã | B1: Nhóm | C1: Chỉ tiêu | D1: Công thức (cách hiểu hiện tại) | E1: Nguồn | F1: Trạng thái | G1: Xác nhận (chọn) | H1: Công thức đúng / bổ sung của công ty | I1: Người trả lời
A2: F01 | B2: Báo cáo tòa – doanh thu | C2: Tổng doanh thu | D2: =Tổng cột «Tổng đã đóng» của sổ tòa trong tháng | E2: Đọc từ ô công thức file G1 (C2) | F2: Đã trả lời | H2: [Đối chiếu công thức file nguồn KH gửi 22/09/2026] G1 tháng 8: C2 = 'HĐ T8.26'!AX2 − C7 → Tổng doanh thu = Tổng đã đóng − Hoàn cọc. | I2: Đối chiếu file
A3: F02 | B3: Báo cáo tòa – doanh thu | C3: Doanh thu tiền phòng | D3: =Σ Giá phòng hiện tại − Σ giá của phòng đã trả trong tháng + Σ tiền phòng theo ngày của phòng mới | E3: Đọc từ ô công thức file G1 (C12) | F3: Đã trả lời | H3: [KH trả lời 22/09/2026] Điện nước trên hóa đơn là doanh thu; cọc bỏ không cộng lại. [GIẢ ĐỊNH bên PT theo chuẩn kế toán & thực tế DN – cần KH xác nhận] Phần mềm: DT tiền phòng = Σ dòng «Tiền phòng» hóa đơn (BC kinh doanh: phát hành trong kỳ; BC dòng tiền: đã thu trong kỳ). | I3: KH 22/09 + Bên PT
A4: F03 | B4: Báo cáo tòa – doanh thu | C4: Doanh thu điện | D4: =Σ Điện thành tiền (KHÔNG trừ phòng đã trả) | E4: Đọc từ ô công thức (C13) | F4: Chờ xác nhận | H4: [GIẢ ĐỊNH bên PT – cần KH xác nhận] Phần mềm: Doanh thu điện = Σ dòng «Điện» + «Điện chung» của hóa đơn đã thu trong kỳ (kể cả hóa đơn cuối của phòng đã trả). Không cần trừ/cộng tay. | I4: Bên PT (giả định)
A5: F04 | B5: Báo cáo tòa – doanh thu | C5: Doanh thu nước / mạng / thang máy | D5: =Σ thành tiền − phòng đã trả + phòng mới | E5: Đọc từ ô công thức (C14, C16, C18) | F5: Chờ xác nhận | H5: [GIẢ ĐỊNH bên PT – cần KH xác nhận] Phần mềm: = Σ dòng dịch vụ tương ứng trên hóa đơn đã thu trong kỳ (tự nhiên gồm phòng mới, gồm hóa đơn cuối phòng đã trả). Cách trừ tay trong file chỉ là do phòng đã trả không còn dòng hóa đơn. | I5: Bên PT (giả định)
A6: F05 | B6: Báo cáo tòa – doanh thu | C6: Doanh thu xe điện | D6: =Σ thành tiền − phòng đã trả | E6: Đọc từ ô công thức (C17) | F6: Đã trả lời
A7: F06 | B7: Báo cáo tòa – doanh thu | C7: Doanh thu vệ sinh = Doanh thu máy giặt | D7: =(Σ Combo DV khác − phòng đã trả + phòng mới) ÷ 2 | E7: Đọc từ ô công thức (C15, C19) | F7: Chờ xác nhận | H7: [GIẢ ĐỊNH bên PT – cần KH xác nhận] Phần mềm: 2 dịch vụ riêng «Vệ sinh» và «Máy giặt» (60.000/người mỗi loại, override theo tòa); báo cáo = Σ từng dịch vụ, không chia đôi. | I7: Bên PT (giả định)
A8: F07 | B8: Báo cáo tòa – doanh thu | C8: Doanh thu tổng dịch vụ | D8: =Σ 7 dòng dịch vụ | E8: Đọc từ ô công thức (C20) | F8: Đã trả lời
A9: F08 | B9: Báo cáo tòa – giá vốn | C9: Giá vốn (GV) | D9: =Tiền thuê nhà + Mua thiết bị + Σ giá gốc điện, nước, mạng, rác, môi trường, thang máy | E9: Đọc từ ô công thức (C34) | F9: Đã trả lời
A10: F09 | B10: Báo cáo tòa – chi phí | C10: Lương quản lý tổng | D10: =(12.000.000 ÷ Tổng phòng hệ thống) × Số phòng của tòa [tháng 6: 1.303 phòng] | E10: Đọc từ ô công thức (C36) | F10: Chờ xác nhận | H10: [GIẢ ĐỊNH bên PT – cần KH xác nhận] = (Tổng lương chức danh «Quản lý tổng» tháng từ bảng lương khóa ÷ N) × n; N = tổng phòng quản lý cuối tháng, n = số phòng tòa. | I10: Bên PT (giả định)
A11: F10 | B11: Báo cáo tòa – chi phí | C11: Lương trưởng phòng vận hành | D11: =(21.000.000 ÷ Tổng phòng) × Số phòng tòa + 10.000 × Số phòng tòa | E11: Đọc từ ô công thức (C37) | F11: Chờ xác nhận | H11: [GIẢ ĐỊNH bên PT – cần KH xác nhận] = (Tổng lương cố định TPVH ÷ N) × n + 10.000 × n. (10.000/phòng chính là «lương trưởng nhóm» = 10.000 × số phòng dưới quyền.) | I11: Bên PT (giả định)
A12: F11 | B12: Báo cáo tòa – chi phí | C12: Lương nhân viên nguồn | D12: =(3.000.000 ÷ Tổng phòng) × Số phòng tòa | E12: Đọc từ ô công thức (C39) | F12: Chờ xác nhận | H12: [GIẢ ĐỊNH bên PT – cần KH xác nhận] = (Tổng lương NV nguồn ÷ N) × n. | I12: Bên PT (giả định)
A13: F12 | B13: Báo cáo tòa – chi phí | C13: Lương NVKD | D13: =(Tổng lương NVKD tháng theo bảng lương ÷ Tổng phòng) × Số phòng tòa | E13: Đọc từ ô công thức (C40) | F13: Chờ xác nhận | H13: [GIẢ ĐỊNH bên PT – cần KH xác nhận] = (Tổng lương NVKD tháng từ bảng lương khóa ÷ N) × n. | I13: Bên PT (giả định)
A14: F13 | B14: Báo cáo tòa – chi phí | C14: Lương vệ sinh | D14: =550.000 cố định mỗi tòa | E14: Đọc từ ô (C41) | F14: Chờ xác nhận | H14: [GIẢ ĐỊNH bên PT – cần KH xác nhận] = 550.000 cố định/tòa (khoán vệ sinh), cấu hình theo tòa. | I14: Bên PT (giả định)
A15: F14 | B15: Báo cáo tòa – chi phí | C15: Lương kế toán | D15: =150.000 + 10.000 + (2.000.000 ÷ Tổng phòng) × Số phòng tòa | E15: Đọc từ ô công thức (C42) | F15: Chờ xác nhận | H15: [GIẢ ĐỊNH bên PT – cần KH xác nhận] = 150.000 + 10.000 (phần cố định/tòa) + (Tổng lương kế toán ÷ N) × n. Đề xuất gộp phần cố định 160.000/tòa thành tham số. | I15: Bên PT (giả định)
A16: F15 | B16: Báo cáo tòa – chi phí | C16: Lương sửa chữa | D16: =(22.000.000 ÷ Tổng phòng) × Số phòng tòa | E16: Đọc từ ô công thức (C43) | F16: Chờ xác nhận | H16: [GIẢ ĐỊNH bên PT – cần KH xác nhận] = (Tổng lương sửa chữa ÷ N) × n. | I16: Bên PT (giả định)
A17: F16 | B17: Báo cáo tòa – chi phí | C17: Thuê và dịch vụ văn phòng | D17: =(Chi phí văn phòng tháng ÷ Tổng phòng) × Số phòng tòa | E17: Đọc từ ô công thức (C45) | F17: Chờ xác nhận | H17: [GIẢ ĐỊNH bên PT – cần KH xác nhận] = (Chi phí thuê & DV VP tháng, import chi phí phạm vi «toàn hệ thống» ÷ N) × n. | I17: Bên PT (giả định)
A18: F17 | B18: Báo cáo tòa – chi phí | C18: Phí marketing | D18: =(Chi phí marketing tháng ÷ Tổng phòng) × Số phòng tòa | E18: Đọc từ ô công thức (C46) | F18: Chờ xác nhận | H18: [GIẢ ĐỊNH bên PT – cần KH xác nhận] = (Chi phí marketing tháng, import phạm vi «toàn hệ thống» ÷ N) × n; marketing gắn riêng tòa thì cộng thẳng. | I18: Bên PT (giả định)
A19: F18 | B19: Báo cáo tòa – chi phí | C19: Tổng chi phí bán hàng (CPBH) | D19: =Σ (các dòng lương + văn phòng + marketing + hoa hồng + sửa chữa + chi phí khác) | E19: Đọc từ ô công thức (C71) | F19: Đã trả lời
A20: F19 | B20: Báo cáo tòa – lợi nhuận | C20: Tổng chi phí (TCP) | D20: =GV + CPBH | E20: Đọc từ ô công thức (C72) | F20: Đã trả lời
A21: F20 | B21: Báo cáo tòa – lợi nhuận | C21: Lợi nhuận gộp (LNG) | D21: =Tổng doanh thu − GV | E21: Đọc từ ô công thức (C73) | F21: Đã trả lời
A22: F21 | B22: Báo cáo tòa – lợi nhuận | C22: Lợi nhuận ròng (LNR) | D22: =Tổng doanh thu − TCP | E22: Đọc từ ô công thức (C74) | F22: Đã trả lời
A23: F22 | B23: Báo cáo tòa – tỷ lệ | C23: 8 tỷ lệ quản trị | D23: LNR/DT · LNG/DT · LNR/GV · LNR/LNG · CP/LNG (= TCP ÷ LNG) · GV/DT · CPBH/DT · TCP/DT | E23: Đọc từ ô công thức (C76–C83) | F23: Đã trả lời
A24: F23 | B24: Báo cáo tòa – tỷ lệ | C24: LƯƠNG/CPBH | D24: =Σ các dòng lương (KHÔNG gồm thuê văn phòng) ÷ CPBH | E24: Đọc từ ô công thức (C84) | F24: Đã trả lời
A25: F24 | B25: Báo cáo tòa – tỷ lệ | C25: HH/CPBH | D25: =(Marketing + Hoa hồng) ÷ CPBH | E25: Đọc từ ô công thức (C85) | F25: Đã trả lời
A26: F25 | B26: Báo cáo tòa – tỷ lệ | C26: CPK/CPBH | D26: =Chi phí khác ÷ CPBH | E26: Đọc từ ô công thức (C86) | F26: Đã trả lời
A27: F26 | B27: Bảng cổ phần | C27: Vốn của cổ đông | D27: =% cổ phần × Tiền thuê nhà 1 tháng | E27: Đọc từ ô công thức (H3:H11) | F27: Chờ xác nhận | H27: [GIẢ ĐỊNH bên PT – cần KH xác nhận] Giữ = % × Tiền thuê nhà 1 tháng cho báo cáo tháng; module Cổ đông theo dõi thêm «Vốn góp lũy kế» = Σ đợt đã đóng. | I27: Bên PT (giả định)
A28: F27 | B28: Bảng cổ phần | C28: LN gộp / LN ròng của cổ đông | D28: =% × LNG / = % × LNR | E28: Đọc từ ô công thức (I, J) | F28: Đã trả lời
A29: F28 | B29: Bảng cổ phần | C29: Tổng nhận của cổ đông | D29: =Vốn + LN ròng | E29: Đọc từ ô công thức (M) | F29: Chờ xác nhận | H29: [GIẢ ĐỊNH bên PT – cần KH xác nhận] Giữ = Vốn + LN ròng × % (tham khảo). Số chi thực = theo tài khoản lũy kế (Q50–Q51). | I29: Bên PT (giả định)
A30: F29 | B30: Báo cáo tổng | C30: DT DV / GIÁ NHẬP | D30: =Doanh thu tổng dịch vụ ÷ Σ giá gốc dịch vụ | E30: Suy từ số liệu tháng 8 (sheet không còn công thức) | F30: Đã trả lời | H30: [File 'nội dung làm web' 31/08/2026] Tương ứng «báo cáo âm dương điện nước» trong danh sách báo cáo KH yêu cầu. | I30: KH
A31: F30 | B31: Báo cáo tổng | C31: DT TIỀN NHÀ / GIÁ THUÊ NHÀ | D31: =Doanh thu tiền phòng ÷ Tiền thuê nhà | E31: Suy từ số liệu tháng 8 | F31: Đã trả lời | H31: [File 'nội dung làm web' 31/08/2026] Tương ứng «biên lợi nhuận tiền nhà (tiền nhà thu/chi)». | I31: KH
A32: F31 | B32: Hoa hồng | C32: Tòa | D32: =lấy mã phòng bỏ 3 ký tự đầu | E32: Đọc từ ô công thức file hoa hồng | F32: Đã trả lời
A33: F32 | B33: Hoa hồng | C33: Thành tiền | D33: =Giá chốt × Mức HH | E33: Đọc từ ô công thức | F33: Đã trả lời
A34: F33 | B34: Hoa hồng | C34: Mức theo nguồn | D34: =50% nếu Team là «(LEAD)» hoặc môi giới ngoài; 35% nếu nhân viên | E34: Đọc từ ô công thức (cột C) | F34: Chờ xác nhận
A35: F34 | B35: Hoa hồng | C35: Mức hợp đồng ngắn | D35: =50% ÷ 6 × số tháng (3 tháng → 25%; 2 tháng → 16,67%) | E35: Đọc từ ô công thức | F35: Chờ xác nhận
A36: F35 | B36: Hoa hồng | C36: Trùng nguồn | D36: =50% ÷ số nguồn | E36: Đọc từ ô công thức («Trùng 3» = 50%/3) | F36: Chờ xác nhận
A37: F36 | B37: Hoa hồng | C37: Cơ sở hoa hồng khi bỏ cọc | D37: =Tiền cọc − Giá thuê ÷ 31 × số ngày đã ở | E37: Đọc từ ô công thức | F37: Chờ xác nhận
A38: F37 | B38: Hoa hồng | C38: Khấu trừ CTV hỗ trợ | D38: =Thành tiền − tiền hỗ trợ CTV | E38: Đọc từ ô công thức | F38: Đã trả lời
A39: F38 | B39: Hoa hồng | C39: Tổng nhận | D39: =Σ Thành tiền các dòng cùng người nhận | E39: Đọc từ ô công thức | F39: Đã trả lời
A40: F39 | B40: Bảng lương | C40: Tổng DT sau 3 mốc | D40: =DT mốc 1 + DT mốc 2 + DT mốc 3 | E40: Suy từ số liệu (khớp) | F40: Đã trả lời | H40: [KH trả lời 22/09/2026] Đúng trọng số 100/90/70%. | I40: KH 22/09 + Bên PT
...

Sheet Tài liệu cần cung cấp
A1: STT | B1: Tài liệu | C1: Dùng để làm rõ | D1: Tình trạng (chọn) | E1: Ghi chú của công ty
A2: 1 | B2: bảng lương tháng 6.xlsx (bản gốc còn công thức) | C2: Lấy công thức gốc: hiệu suất, mức lương/phòng, lương trưởng nhóm (F41–F45, F50–F52, Q29–Q38) | D2: Đã gửi | E2: Nhận file «bảng lương tháng 8.xlsx» (sheet THÁNG 1–8, còn công thức) ngày 22/09/2026.
A3: 2 | B3: cập nhật thu tiền tháng 6 chuẩn.xlsx (sheet NHÀ T/S/G, PHÒNG MỚI, HOÀN CỌC, ĐIỆN NƯỚC PHÒNG TRỐNG, HĐ (VP)/(TECH)) | C3: Xác nhận cách tính doanh thu, phòng mới, hoàn cọc, điện nước phòng trống (Q01–Q14, Q58) | D3: Đã gửi | E3: Nhận file «Hoá đơn tiền nhà tháng 9 và dịch vụ tháng 9 năm 2026.xlsx» (NHÀ T/S/G, PHÒNG MỚI, HOÀN CỌC, ĐIỆN NƯỚC PHÒNG TRỐNG, HĐ (VP)/(TECH), cập nhật thu tiền, DS phòng phá hđ).
A4: 3 | B4: G1.31.8.26.xlsx (sheet ĐẦU TƯ BAN ĐẦU, THU CHI BAN ĐẦU) – và file tương tự của 1–2 tòa khác | C4: Xác nhận vốn góp, đầu tư ban đầu, chia lợi nhuận (Q49–Q54) | D4: Đã gửi | E4: Nhận «G1.31.8.26.xlsx» (ĐẦU TƯ BAN ĐẦU, THU CHI BAN ĐẦU, HĐ T1–T8, BÁO CÁO THÁNG 2–8). Chưa có file tòa khác.
A5: 4 | B5: chi phí văn phòng tháng 6.xlsx | C5: Danh mục chi phí văn phòng / marketing và cách chia (Q19, Q28) | D5: Chưa gửi | E5: Chưa nhận file chi phí văn phòng; tạm dùng tổng số trong công thức G1 (VP 60.785.000; marketing 30.188.000 tháng 6).
A6: 5 | B6: File gốc của «Báo cáo kinh doanh Tháng 8» (bản còn công thức) | C6: Đối chiếu cách cộng theo nhóm T/S/G và 2 tỷ lệ cuối (F29, F30) | D6: Đã gửi | E6: Nhận «BÁO CÁO KINH DOANH THÁNG 8.xlsx» (BC tổng, BC kinh doanh, BC DT theo tòa T/S/G tháng 1–8, còn công thức).
A7: 6 | B7: Bảng bậc mức lương/phòng theo hiệu suất (văn bản / quyết định) | C7: Cấu hình quy tắc lương (Q30–Q32) | D7: Chưa gửi | E7: Chưa có văn bản; bên PT đề xuất bảng ngưỡng tại Q30/F52 để KH duyệt.
A8: 7 | B8: Chính sách hoa hồng bằng văn bản (nếu có) | C8: Cấu hình hoa hồng (Q40–Q48) | D8: Chưa gửi | E8: Chưa có văn bản; bên PT đề xuất tại Q40–Q44.
A9: 8 | B9: Danh sách tòa: mã, nhóm T/S/G, chủ nhà, tiền thuê/tháng, ngày bắt đầu, số phòng | C9: Khởi tạo dữ liệu tòa (Q63, Q64) | D9: Chưa gửi | E9: Có thể trích từ sheet BC DT NHÀ T/S/G (mã tòa, loại L1/L2/L3) và sổ tháng 9 (số phòng, quản lý); còn thiếu chủ nhà, tiền thuê, ngày bắt đầu.
A10: 9 | B10: Danh sách đơn giá dịch vụ theo từng tòa (tòa nào khác mặc định) | C10: Cấu hình bảng giá (Q57) | D10: Chưa gửi | E10: Đã nhận «Danh sách mã HĐ điện nước mạng.xlsx» (mã hợp đồng nhà cung cấp) – chưa phải bảng đơn giá bán dịch vụ theo tòa.
A11: 10 | B11: Danh sách cổ đông & tỷ lệ theo từng tòa | C11: Khởi tạo module cổ đông (Q49) | D11: Chưa gửi | E11: Mới có G1 (bảng cổ phần + THU CHI BAN ĐẦU); cần các tòa còn lại.
A12: 11 | B12: Sơ đồ tổ chức + danh sách nhân viên + tòa phụ trách hiện tại | C12: Khởi tạo phân công (Q60) | D12: Chưa gửi | E12: Trích được từ bảng lương tháng 8 (TPVH, TNVH, 12 NVVH + tòa phụ trách); thiếu phòng KD, KT, thị trường, TC-KT.
